INFO:requests.packages.urllib3.connectionpool:Starting new HTTP connection (1): localhost
INFO:requests.packages.urllib3.connectionpool:Starting new HTTP connection (1): localhost
INFO:requests.packages.urllib3.connectionpool:Starting new HTTP connection (1): localhost
INFO:root:Patch products done
INFO:requests.packages.urllib3.connectionpool:Starting new HTTP connection (1): localhost
INFO:requests.packages.urllib3.connectionpool:Starting new HTTP connection (1): localhost
INFO:requests.packages.urllib3.connectionpool:Starting new HTTP connection (1): localhost
INFO:root:Patch products reversed
INFO:requests.packages.urllib3.connectionpool:Starting new HTTP connection (1): localhost
INFO:requests.packages.urllib3.connectionpool:Starting new HTTP connection (1): localhost
INFO:requests.packages.urllib3.connectionpool:Starting new HTTP connection (1): localhost
INFO:root:Patch products done
INFO:requests.packages.urllib3.connectionpool:Starting new HTTP connection (1): localhost
INFO:requests.packages.urllib3.connectionpool:Starting new HTTP connection (1): localhost
INFO:requests.packages.urllib3.connectionpool:Starting new HTTP connection (1): localhost
INFO:root:Patch products reversed
INFO:requests.packages.urllib3.connectionpool:Starting new HTTP connection (1): localhost
INFO:root:Show orders
INFO:requests.packages.urllib3.connectionpool:Starting new HTTP connection (1): localhost
INFO:root:Show orders
INFO:requests.packages.urllib3.connectionpool:Starting new HTTP connection (1): localhost
INFO:root:Show orders
ERROR:django.request:Internal Server Error: /user/3/orders/
Traceback (most recent call last):
  File "/usr/local/lib/python3.5/dist-packages/django/core/handlers/exception.py", line 35, in inner
    response = get_response(request)
  File "/usr/local/lib/python3.5/dist-packages/django/core/handlers/base.py", line 158, in _get_response
    response = self.process_exception_by_middleware(e, request)
  File "/usr/local/lib/python3.5/dist-packages/django/core/handlers/base.py", line 156, in _get_response
    response = response.render()
  File "/usr/local/lib/python3.5/dist-packages/django/template/response.py", line 106, in render
    self.content = self.rendered_content
  File "/usr/local/lib/python3.5/dist-packages/rest_framework/response.py", line 72, in rendered_content
    ret = renderer.render(self.data, accepted_media_type, context)
  File "/usr/local/lib/python3.5/dist-packages/rest_framework/renderers.py", line 168, in render
    template_names = self.get_template_names(response, view)
  File "/usr/local/lib/python3.5/dist-packages/rest_framework/renderers.py", line 197, in get_template_names
    'Returned a template response with no `template_name` attribute set on either the view or response'
django.core.exceptions.ImproperlyConfigured: Returned a template response with no `template_name` attribute set on either the view or response
INFO:requests.packages.urllib3.connectionpool:Starting new HTTP connection (1): localhost
INFO:root:Show orders
INFO:requests.packages.urllib3.connectionpool:Starting new HTTP connection (1): localhost
INFO:root:Show orders
INFO:requests.packages.urllib3.connectionpool:Starting new HTTP connection (1): localhost
INFO:root:Show orders
INFO:requests.packages.urllib3.connectionpool:Starting new HTTP connection (1): localhost
INFO:root:Show orders
INFO:requests.packages.urllib3.connectionpool:Starting new HTTP connection (1): localhost
WARNING:django.request:Not Found: /user/1/orders/
INFO:requests.packages.urllib3.connectionpool:Starting new HTTP connection (1): localhost
INFO:root:Show orders
INFO:requests.packages.urllib3.connectionpool:Starting new HTTP connection (1): localhost
INFO:root:Show orders
INFO:requests.packages.urllib3.connectionpool:Starting new HTTP connection (1): localhost
WARNING:django.request:Not Found: /user/1/orders/
INFO:requests.packages.urllib3.connectionpool:Starting new HTTP connection (1): localhost
INFO:root:Show orders
INFO:requests.packages.urllib3.connectionpool:Starting new HTTP connection (1): localhost
WARNING:django.request:Not Found: /user/1/orders/
INFO:requests.packages.urllib3.connectionpool:Starting new HTTP connection (1): localhost
INFO:root:Show orders
INFO:requests.packages.urllib3.connectionpool:Starting new HTTP connection (1): localhost
INFO:root:Show orders
WARNING:django.request:Not Found: /user/3/
INFO:requests.packages.urllib3.connectionpool:Starting new HTTP connection (1): localhost
INFO:root:Show orders
INFO:requests.packages.urllib3.connectionpool:Starting new HTTP connection (1): localhost
WARNING:django.request:Not Found: /user/1/orders/
INFO:requests.packages.urllib3.connectionpool:Starting new HTTP connection (1): localhost
WARNING:django.request:Not Found: /user/1/orders/
INFO:requests.packages.urllib3.connectionpool:Starting new HTTP connection (1): localhost
ERROR:django.request:Internal Server Error: /user/1/orders/
Traceback (most recent call last):
  File "/home/sanya/Documents/Git/rsoi_2lab/rsoi_2lab/ag_service/aggregator/views.py", line 140, in get
    r.raise_for_status()
  File "/usr/lib/python3/dist-packages/requests/models.py", line 840, in raise_for_status
    raise HTTPError(http_error_msg, response=self)
requests.exceptions.HTTPError: 404 Client Error: Not Found for url: http://localhost:8000/buys/user/1/

During handling of the above exception, another exception occurred:

Traceback (most recent call last):
  File "/usr/local/lib/python3.5/dist-packages/django/core/handlers/exception.py", line 35, in inner
    response = get_response(request)
  File "/usr/local/lib/python3.5/dist-packages/django/core/handlers/base.py", line 128, in _get_response
    response = self.process_exception_by_middleware(e, request)
  File "/usr/local/lib/python3.5/dist-packages/django/core/handlers/base.py", line 126, in _get_response
    response = wrapped_callback(request, *callback_args, **callback_kwargs)
  File "/usr/local/lib/python3.5/dist-packages/django/views/decorators/csrf.py", line 54, in wrapped_view
    return view_func(*args, **kwargs)
  File "/usr/local/lib/python3.5/dist-packages/django/views/generic/base.py", line 69, in view
    return self.dispatch(request, *args, **kwargs)
  File "/usr/local/lib/python3.5/dist-packages/rest_framework/views.py", line 494, in dispatch
    response = self.handle_exception(exc)
  File "/usr/local/lib/python3.5/dist-packages/rest_framework/views.py", line 454, in handle_exception
    self.raise_uncaught_exception(exc)
  File "/usr/local/lib/python3.5/dist-packages/rest_framework/views.py", line 491, in dispatch
    response = handler(request, *args, **kwargs)
  File "/home/sanya/Documents/Git/rsoi_2lab/rsoi_2lab/ag_service/aggregator/views.py", line 145, in get
    return render(request, status_code+".html", {'result':r.json(object_pairs_hook=OrderedDict)})
TypeError: unsupported operand type(s) for +: 'int' and 'str'
INFO:requests.packages.urllib3.connectionpool:Starting new HTTP connection (1): localhost
ERROR:django.request:Internal Server Error: /user/1/orders/
Traceback (most recent call last):
  File "/home/sanya/Documents/Git/rsoi_2lab/rsoi_2lab/ag_service/aggregator/views.py", line 140, in get
    r.raise_for_status()
  File "/usr/lib/python3/dist-packages/requests/models.py", line 840, in raise_for_status
    raise HTTPError(http_error_msg, response=self)
requests.exceptions.HTTPError: 404 Client Error: Not Found for url: http://localhost:8000/buys/user/1/

During handling of the above exception, another exception occurred:

Traceback (most recent call last):
  File "/usr/local/lib/python3.5/dist-packages/django/core/handlers/exception.py", line 35, in inner
    response = get_response(request)
  File "/usr/local/lib/python3.5/dist-packages/django/core/handlers/base.py", line 128, in _get_response
    response = self.process_exception_by_middleware(e, request)
  File "/usr/local/lib/python3.5/dist-packages/django/core/handlers/base.py", line 126, in _get_response
    response = wrapped_callback(request, *callback_args, **callback_kwargs)
  File "/usr/local/lib/python3.5/dist-packages/django/views/decorators/csrf.py", line 54, in wrapped_view
    return view_func(*args, **kwargs)
  File "/usr/local/lib/python3.5/dist-packages/django/views/generic/base.py", line 69, in view
    return self.dispatch(request, *args, **kwargs)
  File "/usr/local/lib/python3.5/dist-packages/rest_framework/views.py", line 494, in dispatch
    response = self.handle_exception(exc)
  File "/usr/local/lib/python3.5/dist-packages/rest_framework/views.py", line 454, in handle_exception
    self.raise_uncaught_exception(exc)
  File "/usr/local/lib/python3.5/dist-packages/rest_framework/views.py", line 491, in dispatch
    response = handler(request, *args, **kwargs)
  File "/home/sanya/Documents/Git/rsoi_2lab/rsoi_2lab/ag_service/aggregator/views.py", line 146, in get
    return render(request, status_code+".html", {'result':r.json(object_pairs_hook=OrderedDict)})
TypeError: unsupported operand type(s) for +: 'int' and 'str'
INFO:requests.packages.urllib3.connectionpool:Starting new HTTP connection (1): localhost
ERROR:django.request:Internal Server Error: /user/1/orders/
Traceback (most recent call last):
  File "/home/sanya/Documents/Git/rsoi_2lab/rsoi_2lab/ag_service/aggregator/views.py", line 140, in get
    r.raise_for_status()
  File "/usr/lib/python3/dist-packages/requests/models.py", line 840, in raise_for_status
    raise HTTPError(http_error_msg, response=self)
requests.exceptions.HTTPError: 404 Client Error: Not Found for url: http://localhost:8000/buys/user/1/

During handling of the above exception, another exception occurred:

Traceback (most recent call last):
  File "/usr/local/lib/python3.5/dist-packages/django/core/handlers/exception.py", line 35, in inner
    response = get_response(request)
  File "/usr/local/lib/python3.5/dist-packages/django/core/handlers/base.py", line 128, in _get_response
    response = self.process_exception_by_middleware(e, request)
  File "/usr/local/lib/python3.5/dist-packages/django/core/handlers/base.py", line 126, in _get_response
    response = wrapped_callback(request, *callback_args, **callback_kwargs)
  File "/usr/local/lib/python3.5/dist-packages/django/views/decorators/csrf.py", line 54, in wrapped_view
    return view_func(*args, **kwargs)
  File "/usr/local/lib/python3.5/dist-packages/django/views/generic/base.py", line 69, in view
    return self.dispatch(request, *args, **kwargs)
  File "/usr/local/lib/python3.5/dist-packages/rest_framework/views.py", line 494, in dispatch
    response = self.handle_exception(exc)
  File "/usr/local/lib/python3.5/dist-packages/rest_framework/views.py", line 454, in handle_exception
    self.raise_uncaught_exception(exc)
  File "/usr/local/lib/python3.5/dist-packages/rest_framework/views.py", line 491, in dispatch
    response = handler(request, *args, **kwargs)
  File "/home/sanya/Documents/Git/rsoi_2lab/rsoi_2lab/ag_service/aggregator/views.py", line 146, in get
    return render(status_code+".html")
TypeError: unsupported operand type(s) for +: 'int' and 'str'
INFO:requests.packages.urllib3.connectionpool:Starting new HTTP connection (1): localhost
ERROR:django.request:Internal Server Error: /user/1/orders/
Traceback (most recent call last):
  File "/home/sanya/Documents/Git/rsoi_2lab/rsoi_2lab/ag_service/aggregator/views.py", line 140, in get
    r.raise_for_status()
  File "/usr/lib/python3/dist-packages/requests/models.py", line 840, in raise_for_status
    raise HTTPError(http_error_msg, response=self)
requests.exceptions.HTTPError: 404 Client Error: Not Found for url: http://localhost:8000/buys/user/1/

During handling of the above exception, another exception occurred:

Traceback (most recent call last):
  File "/usr/local/lib/python3.5/dist-packages/django/core/handlers/exception.py", line 35, in inner
    response = get_response(request)
  File "/usr/local/lib/python3.5/dist-packages/django/core/handlers/base.py", line 128, in _get_response
    response = self.process_exception_by_middleware(e, request)
  File "/usr/local/lib/python3.5/dist-packages/django/core/handlers/base.py", line 126, in _get_response
    response = wrapped_callback(request, *callback_args, **callback_kwargs)
  File "/usr/local/lib/python3.5/dist-packages/django/views/decorators/csrf.py", line 54, in wrapped_view
    return view_func(*args, **kwargs)
  File "/usr/local/lib/python3.5/dist-packages/django/views/generic/base.py", line 69, in view
    return self.dispatch(request, *args, **kwargs)
  File "/usr/local/lib/python3.5/dist-packages/rest_framework/views.py", line 494, in dispatch
    response = self.handle_exception(exc)
  File "/usr/local/lib/python3.5/dist-packages/rest_framework/views.py", line 454, in handle_exception
    self.raise_uncaught_exception(exc)
  File "/usr/local/lib/python3.5/dist-packages/rest_framework/views.py", line 491, in dispatch
    response = handler(request, *args, **kwargs)
  File "/home/sanya/Documents/Git/rsoi_2lab/rsoi_2lab/ag_service/aggregator/views.py", line 146, in get
    return render(str(status_code)+".html")
TypeError: render() missing 1 required positional argument: 'template_name'
INFO:requests.packages.urllib3.connectionpool:Starting new HTTP connection (1): localhost
ERROR:django.request:Internal Server Error: /user/1/orders/
Traceback (most recent call last):
  File "/home/sanya/Documents/Git/rsoi_2lab/rsoi_2lab/ag_service/aggregator/views.py", line 140, in get
    r.raise_for_status()
  File "/usr/lib/python3/dist-packages/requests/models.py", line 840, in raise_for_status
    raise HTTPError(http_error_msg, response=self)
requests.exceptions.HTTPError: 404 Client Error: Not Found for url: http://localhost:8000/buys/user/1/

During handling of the above exception, another exception occurred:

Traceback (most recent call last):
  File "/usr/local/lib/python3.5/dist-packages/django/core/handlers/exception.py", line 35, in inner
    response = get_response(request)
  File "/usr/local/lib/python3.5/dist-packages/django/core/handlers/base.py", line 128, in _get_response
    response = self.process_exception_by_middleware(e, request)
  File "/usr/local/lib/python3.5/dist-packages/django/core/handlers/base.py", line 126, in _get_response
    response = wrapped_callback(request, *callback_args, **callback_kwargs)
  File "/usr/local/lib/python3.5/dist-packages/django/views/decorators/csrf.py", line 54, in wrapped_view
    return view_func(*args, **kwargs)
  File "/usr/local/lib/python3.5/dist-packages/django/views/generic/base.py", line 69, in view
    return self.dispatch(request, *args, **kwargs)
  File "/usr/local/lib/python3.5/dist-packages/rest_framework/views.py", line 494, in dispatch
    response = self.handle_exception(exc)
  File "/usr/local/lib/python3.5/dist-packages/rest_framework/views.py", line 454, in handle_exception
    self.raise_uncaught_exception(exc)
  File "/usr/local/lib/python3.5/dist-packages/rest_framework/views.py", line 491, in dispatch
    response = handler(request, *args, **kwargs)
  File "/home/sanya/Documents/Git/rsoi_2lab/rsoi_2lab/ag_service/aggregator/views.py", line 145, in get
    print (status_code+'.html')
TypeError: unsupported operand type(s) for +: 'int' and 'str'
INFO:requests.packages.urllib3.connectionpool:Starting new HTTP connection (1): localhost
ERROR:django.request:Internal Server Error: /user/1/orders/
Traceback (most recent call last):
  File "/home/sanya/Documents/Git/rsoi_2lab/rsoi_2lab/ag_service/aggregator/views.py", line 140, in get
    r.raise_for_status()
  File "/usr/lib/python3/dist-packages/requests/models.py", line 840, in raise_for_status
    raise HTTPError(http_error_msg, response=self)
requests.exceptions.HTTPError: 404 Client Error: Not Found for url: http://localhost:8000/buys/user/1/

During handling of the above exception, another exception occurred:

Traceback (most recent call last):
  File "/usr/local/lib/python3.5/dist-packages/django/core/handlers/exception.py", line 35, in inner
    response = get_response(request)
  File "/usr/local/lib/python3.5/dist-packages/django/core/handlers/base.py", line 128, in _get_response
    response = self.process_exception_by_middleware(e, request)
  File "/usr/local/lib/python3.5/dist-packages/django/core/handlers/base.py", line 126, in _get_response
    response = wrapped_callback(request, *callback_args, **callback_kwargs)
  File "/usr/local/lib/python3.5/dist-packages/django/views/decorators/csrf.py", line 54, in wrapped_view
    return view_func(*args, **kwargs)
  File "/usr/local/lib/python3.5/dist-packages/django/views/generic/base.py", line 69, in view
    return self.dispatch(request, *args, **kwargs)
  File "/usr/local/lib/python3.5/dist-packages/rest_framework/views.py", line 494, in dispatch
    response = self.handle_exception(exc)
  File "/usr/local/lib/python3.5/dist-packages/rest_framework/views.py", line 454, in handle_exception
    self.raise_uncaught_exception(exc)
  File "/usr/local/lib/python3.5/dist-packages/rest_framework/views.py", line 491, in dispatch
    response = handler(request, *args, **kwargs)
  File "/home/sanya/Documents/Git/rsoi_2lab/rsoi_2lab/ag_service/aggregator/views.py", line 146, in get
    return render(status_code+'.html')
TypeError: unsupported operand type(s) for +: 'int' and 'str'
INFO:requests.packages.urllib3.connectionpool:Starting new HTTP connection (1): localhost
WARNING:django.request:Not Found: /user/1/orders/
INFO:requests.packages.urllib3.connectionpool:Starting new HTTP connection (1): localhost
WARNING:django.request:Not Found: /user/1/orders/
INFO:requests.packages.urllib3.connectionpool:Starting new HTTP connection (1): localhost
INFO:root:Show orders
INFO:requests.packages.urllib3.connectionpool:Starting new HTTP connection (1): localhost
WARNING:django.request:Not Found: /user/1/orders/
INFO:requests.packages.urllib3.connectionpool:Starting new HTTP connection (1): localhost
WARNING:django.request:Not Found: /user/1/orders/
INFO:requests.packages.urllib3.connectionpool:Starting new HTTP connection (1): localhost
INFO:root:Show orders
INFO:requests.packages.urllib3.connectionpool:Starting new HTTP connection (1): localhost
INFO:requests.packages.urllib3.connectionpool:Starting new HTTP connection (1): localhost
WARNING:django.request:Not Found: /user/1/orders/
INFO:requests.packages.urllib3.connectionpool:Starting new HTTP connection (1): localhost
ERROR:django.request:Internal Server Error: /user/1/orders/
Traceback (most recent call last):
  File "/home/sanya/Documents/Git/rsoi_2lab/rsoi_2lab/ag_service/aggregator/views.py", line 141, in get
    r.raise_for_status()
  File "/usr/lib/python3/dist-packages/requests/models.py", line 840, in raise_for_status
    raise HTTPError(http_error_msg, response=self)
requests.exceptions.HTTPError: 404 Client Error: Not Found for url: http://localhost:8000/buys/user/1/

During handling of the above exception, another exception occurred:

Traceback (most recent call last):
  File "/usr/local/lib/python3.5/dist-packages/django/core/handlers/exception.py", line 35, in inner
    response = get_response(request)
  File "/usr/local/lib/python3.5/dist-packages/django/core/handlers/base.py", line 128, in _get_response
    response = self.process_exception_by_middleware(e, request)
  File "/usr/local/lib/python3.5/dist-packages/django/core/handlers/base.py", line 126, in _get_response
    response = wrapped_callback(request, *callback_args, **callback_kwargs)
  File "/usr/local/lib/python3.5/dist-packages/django/views/decorators/csrf.py", line 54, in wrapped_view
    return view_func(*args, **kwargs)
  File "/usr/local/lib/python3.5/dist-packages/django/views/generic/base.py", line 69, in view
    return self.dispatch(request, *args, **kwargs)
  File "/usr/local/lib/python3.5/dist-packages/rest_framework/views.py", line 494, in dispatch
    response = self.handle_exception(exc)
  File "/usr/local/lib/python3.5/dist-packages/rest_framework/views.py", line 454, in handle_exception
    self.raise_uncaught_exception(exc)
  File "/usr/local/lib/python3.5/dist-packages/rest_framework/views.py", line 491, in dispatch
    response = handler(request, *args, **kwargs)
  File "/home/sanya/Documents/Git/rsoi_2lab/rsoi_2lab/ag_service/aggregator/views.py", line 147, in get
    return HttpResponse(loader.render_to_string(str(status_code)+'.html'), status=status_code)
NameError: name 'HttpResponse' is not defined
INFO:requests.packages.urllib3.connectionpool:Starting new HTTP connection (1): localhost
ERROR:django.request:Internal Server Error: /user/1/orders/
Traceback (most recent call last):
  File "/home/sanya/Documents/Git/rsoi_2lab/rsoi_2lab/ag_service/aggregator/views.py", line 141, in get
    r.raise_for_status()
  File "/usr/lib/python3/dist-packages/requests/models.py", line 840, in raise_for_status
    raise HTTPError(http_error_msg, response=self)
requests.exceptions.HTTPError: 404 Client Error: Not Found for url: http://localhost:8000/buys/user/1/

During handling of the above exception, another exception occurred:

Traceback (most recent call last):
  File "/usr/local/lib/python3.5/dist-packages/django/core/handlers/exception.py", line 35, in inner
    response = get_response(request)
  File "/usr/local/lib/python3.5/dist-packages/django/core/handlers/base.py", line 128, in _get_response
    response = self.process_exception_by_middleware(e, request)
  File "/usr/local/lib/python3.5/dist-packages/django/core/handlers/base.py", line 126, in _get_response
    response = wrapped_callback(request, *callback_args, **callback_kwargs)
  File "/usr/local/lib/python3.5/dist-packages/django/views/decorators/csrf.py", line 54, in wrapped_view
    return view_func(*args, **kwargs)
  File "/usr/local/lib/python3.5/dist-packages/django/views/generic/base.py", line 69, in view
    return self.dispatch(request, *args, **kwargs)
  File "/usr/local/lib/python3.5/dist-packages/rest_framework/views.py", line 494, in dispatch
    response = self.handle_exception(exc)
  File "/usr/local/lib/python3.5/dist-packages/rest_framework/views.py", line 454, in handle_exception
    self.raise_uncaught_exception(exc)
  File "/usr/local/lib/python3.5/dist-packages/rest_framework/views.py", line 491, in dispatch
    response = handler(request, *args, **kwargs)
  File "/home/sanya/Documents/Git/rsoi_2lab/rsoi_2lab/ag_service/aggregator/views.py", line 147, in get
    return HttpResponse(loader.render_to_string('404.html'), status=status_code)
NameError: name 'HttpResponse' is not defined
INFO:requests.packages.urllib3.connectionpool:Starting new HTTP connection (1): localhost
ERROR:django.request:Internal Server Error: /user/1/orders/
Traceback (most recent call last):
  File "/usr/lib/python3/dist-packages/urllib3/connection.py", line 137, in _new_conn
    (self.host, self.port), self.timeout, **extra_kw)
  File "/usr/lib/python3/dist-packages/urllib3/util/connection.py", line 91, in create_connection
    raise err
  File "/usr/lib/python3/dist-packages/urllib3/util/connection.py", line 81, in create_connection
    sock.connect(sa)
ConnectionRefusedError: [Errno 111] Connection refused

During handling of the above exception, another exception occurred:

Traceback (most recent call last):
  File "/usr/lib/python3/dist-packages/urllib3/connectionpool.py", line 560, in urlopen
    body=body, headers=headers)
  File "/usr/lib/python3/dist-packages/urllib3/connectionpool.py", line 354, in _make_request
    conn.request(method, url, **httplib_request_kw)
  File "/usr/lib/python3.5/http/client.py", line 1106, in request
    self._send_request(method, url, body, headers)
  File "/usr/lib/python3.5/http/client.py", line 1151, in _send_request
    self.endheaders(body)
  File "/usr/lib/python3.5/http/client.py", line 1102, in endheaders
    self._send_output(message_body)
  File "/usr/lib/python3.5/http/client.py", line 934, in _send_output
    self.send(msg)
  File "/usr/lib/python3.5/http/client.py", line 877, in send
    self.connect()
  File "/usr/lib/python3/dist-packages/urllib3/connection.py", line 162, in connect
    conn = self._new_conn()
  File "/usr/lib/python3/dist-packages/urllib3/connection.py", line 146, in _new_conn
    self, "Failed to establish a new connection: %s" % e)
requests.packages.urllib3.exceptions.NewConnectionError: <requests.packages.urllib3.connection.HTTPConnection object at 0x7fb6c85e87b8>: Failed to establish a new connection: [Errno 111] Connection refused

During handling of the above exception, another exception occurred:

Traceback (most recent call last):
  File "/usr/lib/python3/dist-packages/requests/adapters.py", line 376, in send
    timeout=timeout
  File "/usr/lib/python3/dist-packages/urllib3/connectionpool.py", line 610, in urlopen
    _stacktrace=sys.exc_info()[2])
  File "/usr/lib/python3/dist-packages/urllib3/util/retry.py", line 273, in increment
    raise MaxRetryError(_pool, url, error or ResponseError(cause))
requests.packages.urllib3.exceptions.MaxRetryError: HTTPConnectionPool(host='localhost', port=8000): Max retries exceeded with url: /buys/user/1/ (Caused by NewConnectionError('<requests.packages.urllib3.connection.HTTPConnection object at 0x7fb6c85e87b8>: Failed to establish a new connection: [Errno 111] Connection refused',))

During handling of the above exception, another exception occurred:

Traceback (most recent call last):
  File "/home/sanya/Documents/Git/rsoi_2lab/rsoi_2lab/ag_service/aggregator/views.py", line 140, in get
    r = requests.get(url_buys+"user/"+str(user_id)+"/")
  File "/usr/lib/python3/dist-packages/requests/api.py", line 67, in get
    return request('get', url, params=params, **kwargs)
  File "/usr/lib/python3/dist-packages/requests/api.py", line 53, in request
    return session.request(method=method, url=url, **kwargs)
  File "/usr/lib/python3/dist-packages/requests/sessions.py", line 468, in request
    resp = self.send(prep, **send_kwargs)
  File "/usr/lib/python3/dist-packages/requests/sessions.py", line 576, in send
    r = adapter.send(request, **kwargs)
  File "/usr/lib/python3/dist-packages/requests/adapters.py", line 437, in send
    raise ConnectionError(e, request=request)
requests.exceptions.ConnectionError: HTTPConnectionPool(host='localhost', port=8000): Max retries exceeded with url: /buys/user/1/ (Caused by NewConnectionError('<requests.packages.urllib3.connection.HTTPConnection object at 0x7fb6c85e87b8>: Failed to establish a new connection: [Errno 111] Connection refused',))

During handling of the above exception, another exception occurred:

Traceback (most recent call last):
  File "/usr/local/lib/python3.5/dist-packages/django/core/handlers/exception.py", line 35, in inner
    response = get_response(request)
  File "/usr/local/lib/python3.5/dist-packages/django/core/handlers/base.py", line 128, in _get_response
    response = self.process_exception_by_middleware(e, request)
  File "/usr/local/lib/python3.5/dist-packages/django/core/handlers/base.py", line 126, in _get_response
    response = wrapped_callback(request, *callback_args, **callback_kwargs)
  File "/usr/local/lib/python3.5/dist-packages/django/views/decorators/csrf.py", line 54, in wrapped_view
    return view_func(*args, **kwargs)
  File "/usr/local/lib/python3.5/dist-packages/django/views/generic/base.py", line 69, in view
    return self.dispatch(request, *args, **kwargs)
  File "/usr/local/lib/python3.5/dist-packages/rest_framework/views.py", line 494, in dispatch
    response = self.handle_exception(exc)
  File "/usr/local/lib/python3.5/dist-packages/rest_framework/views.py", line 454, in handle_exception
    self.raise_uncaught_exception(exc)
  File "/usr/local/lib/python3.5/dist-packages/rest_framework/views.py", line 491, in dispatch
    response = handler(request, *args, **kwargs)
  File "/home/sanya/Documents/Git/rsoi_2lab/rsoi_2lab/ag_service/aggregator/views.py", line 150, in get
    return HttpResponse(loader.render_to_string('503.html'), status=503)
NameError: name 'HttpResponse' is not defined
INFO:requests.packages.urllib3.connectionpool:Starting new HTTP connection (1): localhost
ERROR:django.request:Internal Server Error: /user/1/orders/
Traceback (most recent call last):
  File "/usr/lib/python3/dist-packages/urllib3/connection.py", line 137, in _new_conn
    (self.host, self.port), self.timeout, **extra_kw)
  File "/usr/lib/python3/dist-packages/urllib3/util/connection.py", line 91, in create_connection
    raise err
  File "/usr/lib/python3/dist-packages/urllib3/util/connection.py", line 81, in create_connection
    sock.connect(sa)
ConnectionRefusedError: [Errno 111] Connection refused

During handling of the above exception, another exception occurred:

Traceback (most recent call last):
  File "/usr/lib/python3/dist-packages/urllib3/connectionpool.py", line 560, in urlopen
    body=body, headers=headers)
  File "/usr/lib/python3/dist-packages/urllib3/connectionpool.py", line 354, in _make_request
    conn.request(method, url, **httplib_request_kw)
  File "/usr/lib/python3.5/http/client.py", line 1106, in request
    self._send_request(method, url, body, headers)
  File "/usr/lib/python3.5/http/client.py", line 1151, in _send_request
    self.endheaders(body)
  File "/usr/lib/python3.5/http/client.py", line 1102, in endheaders
    self._send_output(message_body)
  File "/usr/lib/python3.5/http/client.py", line 934, in _send_output
    self.send(msg)
  File "/usr/lib/python3.5/http/client.py", line 877, in send
    self.connect()
  File "/usr/lib/python3/dist-packages/urllib3/connection.py", line 162, in connect
    conn = self._new_conn()
  File "/usr/lib/python3/dist-packages/urllib3/connection.py", line 146, in _new_conn
    self, "Failed to establish a new connection: %s" % e)
requests.packages.urllib3.exceptions.NewConnectionError: <requests.packages.urllib3.connection.HTTPConnection object at 0x7fb6c85649e8>: Failed to establish a new connection: [Errno 111] Connection refused

During handling of the above exception, another exception occurred:

Traceback (most recent call last):
  File "/usr/lib/python3/dist-packages/requests/adapters.py", line 376, in send
    timeout=timeout
  File "/usr/lib/python3/dist-packages/urllib3/connectionpool.py", line 610, in urlopen
    _stacktrace=sys.exc_info()[2])
  File "/usr/lib/python3/dist-packages/urllib3/util/retry.py", line 273, in increment
    raise MaxRetryError(_pool, url, error or ResponseError(cause))
requests.packages.urllib3.exceptions.MaxRetryError: HTTPConnectionPool(host='localhost', port=8000): Max retries exceeded with url: /buys/user/1/ (Caused by NewConnectionError('<requests.packages.urllib3.connection.HTTPConnection object at 0x7fb6c85649e8>: Failed to establish a new connection: [Errno 111] Connection refused',))

During handling of the above exception, another exception occurred:

Traceback (most recent call last):
  File "/home/sanya/Documents/Git/rsoi_2lab/rsoi_2lab/ag_service/aggregator/views.py", line 140, in get
    r = requests.get(url_buys+"user/"+str(user_id)+"/")
  File "/usr/lib/python3/dist-packages/requests/api.py", line 67, in get
    return request('get', url, params=params, **kwargs)
  File "/usr/lib/python3/dist-packages/requests/api.py", line 53, in request
    return session.request(method=method, url=url, **kwargs)
  File "/usr/lib/python3/dist-packages/requests/sessions.py", line 468, in request
    resp = self.send(prep, **send_kwargs)
  File "/usr/lib/python3/dist-packages/requests/sessions.py", line 576, in send
    r = adapter.send(request, **kwargs)
  File "/usr/lib/python3/dist-packages/requests/adapters.py", line 437, in send
    raise ConnectionError(e, request=request)
requests.exceptions.ConnectionError: HTTPConnectionPool(host='localhost', port=8000): Max retries exceeded with url: /buys/user/1/ (Caused by NewConnectionError('<requests.packages.urllib3.connection.HTTPConnection object at 0x7fb6c85649e8>: Failed to establish a new connection: [Errno 111] Connection refused',))

During handling of the above exception, another exception occurred:

Traceback (most recent call last):
  File "/usr/local/lib/python3.5/dist-packages/django/core/handlers/exception.py", line 35, in inner
    response = get_response(request)
  File "/usr/local/lib/python3.5/dist-packages/django/core/handlers/base.py", line 128, in _get_response
    response = self.process_exception_by_middleware(e, request)
  File "/usr/local/lib/python3.5/dist-packages/django/core/handlers/base.py", line 126, in _get_response
    response = wrapped_callback(request, *callback_args, **callback_kwargs)
  File "/usr/local/lib/python3.5/dist-packages/django/views/decorators/csrf.py", line 54, in wrapped_view
    return view_func(*args, **kwargs)
  File "/usr/local/lib/python3.5/dist-packages/django/views/generic/base.py", line 69, in view
    return self.dispatch(request, *args, **kwargs)
  File "/usr/local/lib/python3.5/dist-packages/rest_framework/views.py", line 494, in dispatch
    response = self.handle_exception(exc)
  File "/usr/local/lib/python3.5/dist-packages/rest_framework/views.py", line 454, in handle_exception
    self.raise_uncaught_exception(exc)
  File "/usr/local/lib/python3.5/dist-packages/rest_framework/views.py", line 491, in dispatch
    response = handler(request, *args, **kwargs)
  File "/home/sanya/Documents/Git/rsoi_2lab/rsoi_2lab/ag_service/aggregator/views.py", line 150, in get
    return HttpResponse(loader.render_to_string('503.html'), status=503)
NameError: name 'HttpResponse' is not defined
INFO:requests.packages.urllib3.connectionpool:Starting new HTTP connection (1): localhost
ERROR:django.request:Internal Server Error: /user/1/orders/
Traceback (most recent call last):
  File "/usr/lib/python3/dist-packages/urllib3/connection.py", line 137, in _new_conn
    (self.host, self.port), self.timeout, **extra_kw)
  File "/usr/lib/python3/dist-packages/urllib3/util/connection.py", line 91, in create_connection
    raise err
  File "/usr/lib/python3/dist-packages/urllib3/util/connection.py", line 81, in create_connection
    sock.connect(sa)
ConnectionRefusedError: [Errno 111] Connection refused

During handling of the above exception, another exception occurred:

Traceback (most recent call last):
  File "/usr/lib/python3/dist-packages/urllib3/connectionpool.py", line 560, in urlopen
    body=body, headers=headers)
  File "/usr/lib/python3/dist-packages/urllib3/connectionpool.py", line 354, in _make_request
    conn.request(method, url, **httplib_request_kw)
  File "/usr/lib/python3.5/http/client.py", line 1106, in request
    self._send_request(method, url, body, headers)
  File "/usr/lib/python3.5/http/client.py", line 1151, in _send_request
    self.endheaders(body)
  File "/usr/lib/python3.5/http/client.py", line 1102, in endheaders
    self._send_output(message_body)
  File "/usr/lib/python3.5/http/client.py", line 934, in _send_output
    self.send(msg)
  File "/usr/lib/python3.5/http/client.py", line 877, in send
    self.connect()
  File "/usr/lib/python3/dist-packages/urllib3/connection.py", line 162, in connect
    conn = self._new_conn()
  File "/usr/lib/python3/dist-packages/urllib3/connection.py", line 146, in _new_conn
    self, "Failed to establish a new connection: %s" % e)
requests.packages.urllib3.exceptions.NewConnectionError: <requests.packages.urllib3.connection.HTTPConnection object at 0x7f80ed0d96a0>: Failed to establish a new connection: [Errno 111] Connection refused

During handling of the above exception, another exception occurred:

Traceback (most recent call last):
  File "/usr/lib/python3/dist-packages/requests/adapters.py", line 376, in send
    timeout=timeout
  File "/usr/lib/python3/dist-packages/urllib3/connectionpool.py", line 610, in urlopen
    _stacktrace=sys.exc_info()[2])
  File "/usr/lib/python3/dist-packages/urllib3/util/retry.py", line 273, in increment
    raise MaxRetryError(_pool, url, error or ResponseError(cause))
requests.packages.urllib3.exceptions.MaxRetryError: HTTPConnectionPool(host='localhost', port=8000): Max retries exceeded with url: /buys/user/1/ (Caused by NewConnectionError('<requests.packages.urllib3.connection.HTTPConnection object at 0x7f80ed0d96a0>: Failed to establish a new connection: [Errno 111] Connection refused',))

During handling of the above exception, another exception occurred:

Traceback (most recent call last):
  File "/home/sanya/Documents/Git/rsoi_2lab/rsoi_2lab/ag_service/aggregator/views.py", line 140, in get
    r = requests.get(url_buys+"user/"+str(user_id)+"/")
  File "/usr/lib/python3/dist-packages/requests/api.py", line 67, in get
    return request('get', url, params=params, **kwargs)
  File "/usr/lib/python3/dist-packages/requests/api.py", line 53, in request
    return session.request(method=method, url=url, **kwargs)
  File "/usr/lib/python3/dist-packages/requests/sessions.py", line 468, in request
    resp = self.send(prep, **send_kwargs)
  File "/usr/lib/python3/dist-packages/requests/sessions.py", line 576, in send
    r = adapter.send(request, **kwargs)
  File "/usr/lib/python3/dist-packages/requests/adapters.py", line 437, in send
    raise ConnectionError(e, request=request)
requests.exceptions.ConnectionError: HTTPConnectionPool(host='localhost', port=8000): Max retries exceeded with url: /buys/user/1/ (Caused by NewConnectionError('<requests.packages.urllib3.connection.HTTPConnection object at 0x7f80ed0d96a0>: Failed to establish a new connection: [Errno 111] Connection refused',))

During handling of the above exception, another exception occurred:

Traceback (most recent call last):
  File "/usr/local/lib/python3.5/dist-packages/django/core/handlers/exception.py", line 35, in inner
    response = get_response(request)
  File "/usr/local/lib/python3.5/dist-packages/django/core/handlers/base.py", line 128, in _get_response
    response = self.process_exception_by_middleware(e, request)
  File "/usr/local/lib/python3.5/dist-packages/django/core/handlers/base.py", line 126, in _get_response
    response = wrapped_callback(request, *callback_args, **callback_kwargs)
  File "/usr/local/lib/python3.5/dist-packages/django/views/decorators/csrf.py", line 54, in wrapped_view
    return view_func(*args, **kwargs)
  File "/usr/local/lib/python3.5/dist-packages/django/views/generic/base.py", line 69, in view
    return self.dispatch(request, *args, **kwargs)
  File "/usr/local/lib/python3.5/dist-packages/rest_framework/views.py", line 494, in dispatch
    response = self.handle_exception(exc)
  File "/usr/local/lib/python3.5/dist-packages/rest_framework/views.py", line 454, in handle_exception
    self.raise_uncaught_exception(exc)
  File "/usr/local/lib/python3.5/dist-packages/rest_framework/views.py", line 491, in dispatch
    response = handler(request, *args, **kwargs)
  File "/home/sanya/Documents/Git/rsoi_2lab/rsoi_2lab/ag_service/aggregator/views.py", line 150, in get
    print (fsjdfs)
NameError: name 'fsjdfs' is not defined
INFO:requests.packages.urllib3.connectionpool:Starting new HTTP connection (1): localhost
ERROR:django.request:Internal Server Error: /user/1/orders/
Traceback (most recent call last):
  File "/usr/lib/python3/dist-packages/urllib3/connection.py", line 137, in _new_conn
    (self.host, self.port), self.timeout, **extra_kw)
  File "/usr/lib/python3/dist-packages/urllib3/util/connection.py", line 91, in create_connection
    raise err
  File "/usr/lib/python3/dist-packages/urllib3/util/connection.py", line 81, in create_connection
    sock.connect(sa)
ConnectionRefusedError: [Errno 111] Connection refused

During handling of the above exception, another exception occurred:

Traceback (most recent call last):
  File "/usr/lib/python3/dist-packages/urllib3/connectionpool.py", line 560, in urlopen
    body=body, headers=headers)
  File "/usr/lib/python3/dist-packages/urllib3/connectionpool.py", line 354, in _make_request
    conn.request(method, url, **httplib_request_kw)
  File "/usr/lib/python3.5/http/client.py", line 1106, in request
    self._send_request(method, url, body, headers)
  File "/usr/lib/python3.5/http/client.py", line 1151, in _send_request
    self.endheaders(body)
  File "/usr/lib/python3.5/http/client.py", line 1102, in endheaders
    self._send_output(message_body)
  File "/usr/lib/python3.5/http/client.py", line 934, in _send_output
    self.send(msg)
  File "/usr/lib/python3.5/http/client.py", line 877, in send
    self.connect()
  File "/usr/lib/python3/dist-packages/urllib3/connection.py", line 162, in connect
    conn = self._new_conn()
  File "/usr/lib/python3/dist-packages/urllib3/connection.py", line 146, in _new_conn
    self, "Failed to establish a new connection: %s" % e)
requests.packages.urllib3.exceptions.NewConnectionError: <requests.packages.urllib3.connection.HTTPConnection object at 0x7f8c2e28b6a0>: Failed to establish a new connection: [Errno 111] Connection refused

During handling of the above exception, another exception occurred:

Traceback (most recent call last):
  File "/usr/lib/python3/dist-packages/requests/adapters.py", line 376, in send
    timeout=timeout
  File "/usr/lib/python3/dist-packages/urllib3/connectionpool.py", line 610, in urlopen
    _stacktrace=sys.exc_info()[2])
  File "/usr/lib/python3/dist-packages/urllib3/util/retry.py", line 273, in increment
    raise MaxRetryError(_pool, url, error or ResponseError(cause))
requests.packages.urllib3.exceptions.MaxRetryError: HTTPConnectionPool(host='localhost', port=8000): Max retries exceeded with url: /buys/user/1/ (Caused by NewConnectionError('<requests.packages.urllib3.connection.HTTPConnection object at 0x7f8c2e28b6a0>: Failed to establish a new connection: [Errno 111] Connection refused',))

During handling of the above exception, another exception occurred:

Traceback (most recent call last):
  File "/home/sanya/Documents/Git/rsoi_2lab/rsoi_2lab/ag_service/aggregator/views.py", line 140, in get
    r = requests.get(url_buys+"user/"+str(user_id)+"/")
  File "/usr/lib/python3/dist-packages/requests/api.py", line 67, in get
    return request('get', url, params=params, **kwargs)
  File "/usr/lib/python3/dist-packages/requests/api.py", line 53, in request
    return session.request(method=method, url=url, **kwargs)
  File "/usr/lib/python3/dist-packages/requests/sessions.py", line 468, in request
    resp = self.send(prep, **send_kwargs)
  File "/usr/lib/python3/dist-packages/requests/sessions.py", line 576, in send
    r = adapter.send(request, **kwargs)
  File "/usr/lib/python3/dist-packages/requests/adapters.py", line 437, in send
    raise ConnectionError(e, request=request)
requests.exceptions.ConnectionError: HTTPConnectionPool(host='localhost', port=8000): Max retries exceeded with url: /buys/user/1/ (Caused by NewConnectionError('<requests.packages.urllib3.connection.HTTPConnection object at 0x7f8c2e28b6a0>: Failed to establish a new connection: [Errno 111] Connection refused',))

During handling of the above exception, another exception occurred:

Traceback (most recent call last):
  File "/usr/local/lib/python3.5/dist-packages/django/core/handlers/exception.py", line 35, in inner
    response = get_response(request)
  File "/usr/local/lib/python3.5/dist-packages/django/core/handlers/base.py", line 128, in _get_response
    response = self.process_exception_by_middleware(e, request)
  File "/usr/local/lib/python3.5/dist-packages/django/core/handlers/base.py", line 126, in _get_response
    response = wrapped_callback(request, *callback_args, **callback_kwargs)
  File "/usr/local/lib/python3.5/dist-packages/django/views/decorators/csrf.py", line 54, in wrapped_view
    return view_func(*args, **kwargs)
  File "/usr/local/lib/python3.5/dist-packages/django/views/generic/base.py", line 69, in view
    return self.dispatch(request, *args, **kwargs)
  File "/usr/local/lib/python3.5/dist-packages/rest_framework/views.py", line 494, in dispatch
    response = self.handle_exception(exc)
  File "/usr/local/lib/python3.5/dist-packages/rest_framework/views.py", line 454, in handle_exception
    self.raise_uncaught_exception(exc)
  File "/usr/local/lib/python3.5/dist-packages/rest_framework/views.py", line 491, in dispatch
    response = handler(request, *args, **kwargs)
  File "/home/sanya/Documents/Git/rsoi_2lab/rsoi_2lab/ag_service/aggregator/views.py", line 151, in get
    print (fsjdfs)
NameError: name 'fsjdfs' is not defined
INFO:requests.packages.urllib3.connectionpool:Starting new HTTP connection (1): localhost
ERROR:django.request:Internal Server Error: /user/1/orders/
Traceback (most recent call last):
  File "/usr/lib/python3/dist-packages/urllib3/connection.py", line 137, in _new_conn
    (self.host, self.port), self.timeout, **extra_kw)
  File "/usr/lib/python3/dist-packages/urllib3/util/connection.py", line 91, in create_connection
    raise err
  File "/usr/lib/python3/dist-packages/urllib3/util/connection.py", line 81, in create_connection
    sock.connect(sa)
ConnectionRefusedError: [Errno 111] Connection refused

During handling of the above exception, another exception occurred:

Traceback (most recent call last):
  File "/usr/lib/python3/dist-packages/urllib3/connectionpool.py", line 560, in urlopen
    body=body, headers=headers)
  File "/usr/lib/python3/dist-packages/urllib3/connectionpool.py", line 354, in _make_request
    conn.request(method, url, **httplib_request_kw)
  File "/usr/lib/python3.5/http/client.py", line 1106, in request
    self._send_request(method, url, body, headers)
  File "/usr/lib/python3.5/http/client.py", line 1151, in _send_request
    self.endheaders(body)
  File "/usr/lib/python3.5/http/client.py", line 1102, in endheaders
    self._send_output(message_body)
  File "/usr/lib/python3.5/http/client.py", line 934, in _send_output
    self.send(msg)
  File "/usr/lib/python3.5/http/client.py", line 877, in send
    self.connect()
  File "/usr/lib/python3/dist-packages/urllib3/connection.py", line 162, in connect
    conn = self._new_conn()
  File "/usr/lib/python3/dist-packages/urllib3/connection.py", line 146, in _new_conn
    self, "Failed to establish a new connection: %s" % e)
requests.packages.urllib3.exceptions.NewConnectionError: <requests.packages.urllib3.connection.HTTPConnection object at 0x7f2174124470>: Failed to establish a new connection: [Errno 111] Connection refused

During handling of the above exception, another exception occurred:

Traceback (most recent call last):
  File "/usr/lib/python3/dist-packages/requests/adapters.py", line 376, in send
    timeout=timeout
  File "/usr/lib/python3/dist-packages/urllib3/connectionpool.py", line 610, in urlopen
    _stacktrace=sys.exc_info()[2])
  File "/usr/lib/python3/dist-packages/urllib3/util/retry.py", line 273, in increment
    raise MaxRetryError(_pool, url, error or ResponseError(cause))
requests.packages.urllib3.exceptions.MaxRetryError: HTTPConnectionPool(host='localhost', port=8000): Max retries exceeded with url: /buys/user/1/ (Caused by NewConnectionError('<requests.packages.urllib3.connection.HTTPConnection object at 0x7f2174124470>: Failed to establish a new connection: [Errno 111] Connection refused',))

During handling of the above exception, another exception occurred:

Traceback (most recent call last):
  File "/home/sanya/Documents/Git/rsoi_2lab/rsoi_2lab/ag_service/aggregator/views.py", line 140, in get
    r = requests.get(url_buys+"user/"+str(user_id)+"/")
  File "/usr/lib/python3/dist-packages/requests/api.py", line 67, in get
    return request('get', url, params=params, **kwargs)
  File "/usr/lib/python3/dist-packages/requests/api.py", line 53, in request
    return session.request(method=method, url=url, **kwargs)
  File "/usr/lib/python3/dist-packages/requests/sessions.py", line 468, in request
    resp = self.send(prep, **send_kwargs)
  File "/usr/lib/python3/dist-packages/requests/sessions.py", line 576, in send
    r = adapter.send(request, **kwargs)
  File "/usr/lib/python3/dist-packages/requests/adapters.py", line 437, in send
    raise ConnectionError(e, request=request)
requests.exceptions.ConnectionError: HTTPConnectionPool(host='localhost', port=8000): Max retries exceeded with url: /buys/user/1/ (Caused by NewConnectionError('<requests.packages.urllib3.connection.HTTPConnection object at 0x7f2174124470>: Failed to establish a new connection: [Errno 111] Connection refused',))

During handling of the above exception, another exception occurred:

Traceback (most recent call last):
  File "/usr/local/lib/python3.5/dist-packages/django/core/handlers/exception.py", line 35, in inner
    response = get_response(request)
  File "/usr/local/lib/python3.5/dist-packages/django/core/handlers/base.py", line 128, in _get_response
    response = self.process_exception_by_middleware(e, request)
  File "/usr/local/lib/python3.5/dist-packages/django/core/handlers/base.py", line 126, in _get_response
    response = wrapped_callback(request, *callback_args, **callback_kwargs)
  File "/usr/local/lib/python3.5/dist-packages/django/views/decorators/csrf.py", line 54, in wrapped_view
    return view_func(*args, **kwargs)
  File "/usr/local/lib/python3.5/dist-packages/django/views/generic/base.py", line 69, in view
    return self.dispatch(request, *args, **kwargs)
  File "/usr/local/lib/python3.5/dist-packages/rest_framework/views.py", line 494, in dispatch
    response = self.handle_exception(exc)
  File "/usr/local/lib/python3.5/dist-packages/rest_framework/views.py", line 454, in handle_exception
    self.raise_uncaught_exception(exc)
  File "/usr/local/lib/python3.5/dist-packages/rest_framework/views.py", line 491, in dispatch
    response = handler(request, *args, **kwargs)
  File "/home/sanya/Documents/Git/rsoi_2lab/rsoi_2lab/ag_service/aggregator/views.py", line 151, in get
    print (fsjdfs)
NameError: name 'fsjdfs' is not defined
INFO:requests.packages.urllib3.connectionpool:Starting new HTTP connection (1): localhost
ERROR:django.request:Internal Server Error: /user/1/orders/
Traceback (most recent call last):
  File "/home/sanya/Documents/Git/rsoi_2lab/rsoi_2lab/ag_service/aggregator/views.py", line 141, in get
    r.raise_for_status()
  File "/usr/lib/python3/dist-packages/requests/models.py", line 840, in raise_for_status
    raise HTTPError(http_error_msg, response=self)
requests.exceptions.HTTPError: 404 Client Error: Not Found for url: http://localhost:8000/buys/user/1/

During handling of the above exception, another exception occurred:

Traceback (most recent call last):
  File "/usr/local/lib/python3.5/dist-packages/django/core/handlers/exception.py", line 35, in inner
    response = get_response(request)
  File "/usr/local/lib/python3.5/dist-packages/django/core/handlers/base.py", line 128, in _get_response
    response = self.process_exception_by_middleware(e, request)
  File "/usr/local/lib/python3.5/dist-packages/django/core/handlers/base.py", line 126, in _get_response
    response = wrapped_callback(request, *callback_args, **callback_kwargs)
  File "/usr/local/lib/python3.5/dist-packages/django/views/decorators/csrf.py", line 54, in wrapped_view
    return view_func(*args, **kwargs)
  File "/usr/local/lib/python3.5/dist-packages/django/views/generic/base.py", line 69, in view
    return self.dispatch(request, *args, **kwargs)
  File "/usr/local/lib/python3.5/dist-packages/rest_framework/views.py", line 494, in dispatch
    response = self.handle_exception(exc)
  File "/usr/local/lib/python3.5/dist-packages/rest_framework/views.py", line 454, in handle_exception
    self.raise_uncaught_exception(exc)
  File "/usr/local/lib/python3.5/dist-packages/rest_framework/views.py", line 491, in dispatch
    response = handler(request, *args, **kwargs)
  File "/home/sanya/Documents/Git/rsoi_2lab/rsoi_2lab/ag_service/aggregator/views.py", line 147, in get
    print(lal)
NameError: name 'lal' is not defined
INFO:requests.packages.urllib3.connectionpool:Starting new HTTP connection (1): localhost
ERROR:django.request:Internal Server Error: /user/3/orders/
Traceback (most recent call last):
  File "/usr/local/lib/python3.5/dist-packages/django/core/handlers/exception.py", line 35, in inner
    response = get_response(request)
  File "/usr/local/lib/python3.5/dist-packages/django/core/handlers/base.py", line 128, in _get_response
    response = self.process_exception_by_middleware(e, request)
  File "/usr/local/lib/python3.5/dist-packages/django/core/handlers/base.py", line 126, in _get_response
    response = wrapped_callback(request, *callback_args, **callback_kwargs)
  File "/usr/local/lib/python3.5/dist-packages/django/views/decorators/csrf.py", line 54, in wrapped_view
    return view_func(*args, **kwargs)
  File "/usr/local/lib/python3.5/dist-packages/django/views/generic/base.py", line 69, in view
    return self.dispatch(request, *args, **kwargs)
  File "/usr/local/lib/python3.5/dist-packages/rest_framework/views.py", line 494, in dispatch
    response = self.handle_exception(exc)
  File "/usr/local/lib/python3.5/dist-packages/rest_framework/views.py", line 454, in handle_exception
    self.raise_uncaught_exception(exc)
  File "/usr/local/lib/python3.5/dist-packages/rest_framework/views.py", line 491, in dispatch
    response = handler(request, *args, **kwargs)
  File "/home/sanya/Documents/Git/rsoi_2lab/rsoi_2lab/ag_service/aggregator/views.py", line 142, in get
    print(fs)
NameError: name 'fs' is not defined
INFO:requests.packages.urllib3.connectionpool:Starting new HTTP connection (1): localhost
ERROR:django.request:Internal Server Error: /user/3/orders/
Traceback (most recent call last):
  File "/usr/local/lib/python3.5/dist-packages/django/core/handlers/exception.py", line 35, in inner
    response = get_response(request)
  File "/usr/local/lib/python3.5/dist-packages/django/core/handlers/base.py", line 128, in _get_response
    response = self.process_exception_by_middleware(e, request)
  File "/usr/local/lib/python3.5/dist-packages/django/core/handlers/base.py", line 126, in _get_response
    response = wrapped_callback(request, *callback_args, **callback_kwargs)
  File "/usr/local/lib/python3.5/dist-packages/django/views/decorators/csrf.py", line 54, in wrapped_view
    return view_func(*args, **kwargs)
  File "/usr/local/lib/python3.5/dist-packages/django/views/generic/base.py", line 69, in view
    return self.dispatch(request, *args, **kwargs)
  File "/usr/local/lib/python3.5/dist-packages/rest_framework/views.py", line 494, in dispatch
    response = self.handle_exception(exc)
  File "/usr/local/lib/python3.5/dist-packages/rest_framework/views.py", line 454, in handle_exception
    self.raise_uncaught_exception(exc)
  File "/usr/local/lib/python3.5/dist-packages/rest_framework/views.py", line 491, in dispatch
    response = handler(request, *args, **kwargs)
  File "/home/sanya/Documents/Git/rsoi_2lab/rsoi_2lab/ag_service/aggregator/views.py", line 142, in get
    print(fs)
NameError: name 'fs' is not defined
INFO:requests.packages.urllib3.connectionpool:Starting new HTTP connection (1): localhost
INFO:root:Show orders
INFO:requests.packages.urllib3.connectionpool:Starting new HTTP connection (1): localhost
ERROR:django.request:Internal Server Error: /user/3/orders/
Traceback (most recent call last):
  File "/usr/lib/python3/dist-packages/urllib3/connection.py", line 137, in _new_conn
    (self.host, self.port), self.timeout, **extra_kw)
  File "/usr/lib/python3/dist-packages/urllib3/util/connection.py", line 91, in create_connection
    raise err
  File "/usr/lib/python3/dist-packages/urllib3/util/connection.py", line 81, in create_connection
    sock.connect(sa)
ConnectionRefusedError: [Errno 111] Connection refused

During handling of the above exception, another exception occurred:

Traceback (most recent call last):
  File "/usr/lib/python3/dist-packages/urllib3/connectionpool.py", line 560, in urlopen
    body=body, headers=headers)
  File "/usr/lib/python3/dist-packages/urllib3/connectionpool.py", line 354, in _make_request
    conn.request(method, url, **httplib_request_kw)
  File "/usr/lib/python3.5/http/client.py", line 1106, in request
    self._send_request(method, url, body, headers)
  File "/usr/lib/python3.5/http/client.py", line 1151, in _send_request
    self.endheaders(body)
  File "/usr/lib/python3.5/http/client.py", line 1102, in endheaders
    self._send_output(message_body)
  File "/usr/lib/python3.5/http/client.py", line 934, in _send_output
    self.send(msg)
  File "/usr/lib/python3.5/http/client.py", line 877, in send
    self.connect()
  File "/usr/lib/python3/dist-packages/urllib3/connection.py", line 162, in connect
    conn = self._new_conn()
  File "/usr/lib/python3/dist-packages/urllib3/connection.py", line 146, in _new_conn
    self, "Failed to establish a new connection: %s" % e)
requests.packages.urllib3.exceptions.NewConnectionError: <requests.packages.urllib3.connection.HTTPConnection object at 0x7f74e12ee898>: Failed to establish a new connection: [Errno 111] Connection refused

During handling of the above exception, another exception occurred:

Traceback (most recent call last):
  File "/usr/lib/python3/dist-packages/requests/adapters.py", line 376, in send
    timeout=timeout
  File "/usr/lib/python3/dist-packages/urllib3/connectionpool.py", line 610, in urlopen
    _stacktrace=sys.exc_info()[2])
  File "/usr/lib/python3/dist-packages/urllib3/util/retry.py", line 273, in increment
    raise MaxRetryError(_pool, url, error or ResponseError(cause))
requests.packages.urllib3.exceptions.MaxRetryError: HTTPConnectionPool(host='localhost', port=8000): Max retries exceeded with url: /buys/user/3/ (Caused by NewConnectionError('<requests.packages.urllib3.connection.HTTPConnection object at 0x7f74e12ee898>: Failed to establish a new connection: [Errno 111] Connection refused',))

During handling of the above exception, another exception occurred:

Traceback (most recent call last):
  File "/home/sanya/Documents/Git/rsoi_2lab/rsoi_2lab/ag_service/aggregator/views.py", line 140, in get
    r = requests.get(url_buys+"user/"+str(user_id)+"/")
  File "/usr/lib/python3/dist-packages/requests/api.py", line 67, in get
    return request('get', url, params=params, **kwargs)
  File "/usr/lib/python3/dist-packages/requests/api.py", line 53, in request
    return session.request(method=method, url=url, **kwargs)
  File "/usr/lib/python3/dist-packages/requests/sessions.py", line 468, in request
    resp = self.send(prep, **send_kwargs)
  File "/usr/lib/python3/dist-packages/requests/sessions.py", line 576, in send
    r = adapter.send(request, **kwargs)
  File "/usr/lib/python3/dist-packages/requests/adapters.py", line 437, in send
    raise ConnectionError(e, request=request)
requests.exceptions.ConnectionError: HTTPConnectionPool(host='localhost', port=8000): Max retries exceeded with url: /buys/user/3/ (Caused by NewConnectionError('<requests.packages.urllib3.connection.HTTPConnection object at 0x7f74e12ee898>: Failed to establish a new connection: [Errno 111] Connection refused',))

During handling of the above exception, another exception occurred:

Traceback (most recent call last):
  File "/usr/local/lib/python3.5/dist-packages/django/core/handlers/exception.py", line 35, in inner
    response = get_response(request)
  File "/usr/local/lib/python3.5/dist-packages/django/core/handlers/base.py", line 128, in _get_response
    response = self.process_exception_by_middleware(e, request)
  File "/usr/local/lib/python3.5/dist-packages/django/core/handlers/base.py", line 126, in _get_response
    response = wrapped_callback(request, *callback_args, **callback_kwargs)
  File "/usr/local/lib/python3.5/dist-packages/django/views/decorators/csrf.py", line 54, in wrapped_view
    return view_func(*args, **kwargs)
  File "/usr/local/lib/python3.5/dist-packages/django/views/generic/base.py", line 69, in view
    return self.dispatch(request, *args, **kwargs)
  File "/usr/local/lib/python3.5/dist-packages/rest_framework/views.py", line 494, in dispatch
    response = self.handle_exception(exc)
  File "/usr/local/lib/python3.5/dist-packages/rest_framework/views.py", line 454, in handle_exception
    self.raise_uncaught_exception(exc)
  File "/usr/local/lib/python3.5/dist-packages/rest_framework/views.py", line 491, in dispatch
    response = handler(request, *args, **kwargs)
  File "/home/sanya/Documents/Git/rsoi_2lab/rsoi_2lab/ag_service/aggregator/views.py", line 149, in get
    return HttpResponse(loader.render_to_string('503.html'), status=503)
NameError: name 'HttpResponse' is not defined
INFO:requests.packages.urllib3.connectionpool:Starting new HTTP connection (1): localhost
INFO:root:Show orders
INFO:requests.packages.urllib3.connectionpool:Starting new HTTP connection (1): localhost
ERROR:django.request:Internal Server Error: /user/1/orders/
Traceback (most recent call last):
  File "/home/sanya/Documents/Git/rsoi_2lab/rsoi_2lab/ag_service/aggregator/views.py", line 141, in get
    r.raise_for_status()
  File "/usr/lib/python3/dist-packages/requests/models.py", line 840, in raise_for_status
    raise HTTPError(http_error_msg, response=self)
requests.exceptions.HTTPError: 404 Client Error: Not Found for url: http://localhost:8000/buys/user/1/

During handling of the above exception, another exception occurred:

Traceback (most recent call last):
  File "/usr/local/lib/python3.5/dist-packages/django/core/handlers/exception.py", line 35, in inner
    response = get_response(request)
  File "/usr/local/lib/python3.5/dist-packages/django/core/handlers/base.py", line 128, in _get_response
    response = self.process_exception_by_middleware(e, request)
  File "/usr/local/lib/python3.5/dist-packages/django/core/handlers/base.py", line 126, in _get_response
    response = wrapped_callback(request, *callback_args, **callback_kwargs)
  File "/usr/local/lib/python3.5/dist-packages/django/views/decorators/csrf.py", line 54, in wrapped_view
    return view_func(*args, **kwargs)
  File "/usr/local/lib/python3.5/dist-packages/django/views/generic/base.py", line 69, in view
    return self.dispatch(request, *args, **kwargs)
  File "/usr/local/lib/python3.5/dist-packages/rest_framework/views.py", line 494, in dispatch
    response = self.handle_exception(exc)
  File "/usr/local/lib/python3.5/dist-packages/rest_framework/views.py", line 454, in handle_exception
    self.raise_uncaught_exception(exc)
  File "/usr/local/lib/python3.5/dist-packages/rest_framework/views.py", line 491, in dispatch
    response = handler(request, *args, **kwargs)
  File "/home/sanya/Documents/Git/rsoi_2lab/rsoi_2lab/ag_service/aggregator/views.py", line 146, in get
    return render_to_response('404.html')
NameError: name 'render_to_response' is not defined
INFO:requests.packages.urllib3.connectionpool:Starting new HTTP connection (1): localhost
WARNING:django.request:Not Found: /user/1/orders/
INFO:requests.packages.urllib3.connectionpool:Starting new HTTP connection (1): localhost
ERROR:django.request:Internal Server Error: /user/1/orders/
Traceback (most recent call last):
  File "/usr/lib/python3/dist-packages/urllib3/connection.py", line 137, in _new_conn
    (self.host, self.port), self.timeout, **extra_kw)
  File "/usr/lib/python3/dist-packages/urllib3/util/connection.py", line 91, in create_connection
    raise err
  File "/usr/lib/python3/dist-packages/urllib3/util/connection.py", line 81, in create_connection
    sock.connect(sa)
ConnectionRefusedError: [Errno 111] Connection refused

During handling of the above exception, another exception occurred:

Traceback (most recent call last):
  File "/usr/lib/python3/dist-packages/urllib3/connectionpool.py", line 560, in urlopen
    body=body, headers=headers)
  File "/usr/lib/python3/dist-packages/urllib3/connectionpool.py", line 354, in _make_request
    conn.request(method, url, **httplib_request_kw)
  File "/usr/lib/python3.5/http/client.py", line 1106, in request
    self._send_request(method, url, body, headers)
  File "/usr/lib/python3.5/http/client.py", line 1151, in _send_request
    self.endheaders(body)
  File "/usr/lib/python3.5/http/client.py", line 1102, in endheaders
    self._send_output(message_body)
  File "/usr/lib/python3.5/http/client.py", line 934, in _send_output
    self.send(msg)
  File "/usr/lib/python3.5/http/client.py", line 877, in send
    self.connect()
  File "/usr/lib/python3/dist-packages/urllib3/connection.py", line 162, in connect
    conn = self._new_conn()
  File "/usr/lib/python3/dist-packages/urllib3/connection.py", line 146, in _new_conn
    self, "Failed to establish a new connection: %s" % e)
requests.packages.urllib3.exceptions.NewConnectionError: <requests.packages.urllib3.connection.HTTPConnection object at 0x7fd382b716a0>: Failed to establish a new connection: [Errno 111] Connection refused

During handling of the above exception, another exception occurred:

Traceback (most recent call last):
  File "/usr/lib/python3/dist-packages/requests/adapters.py", line 376, in send
    timeout=timeout
  File "/usr/lib/python3/dist-packages/urllib3/connectionpool.py", line 610, in urlopen
    _stacktrace=sys.exc_info()[2])
  File "/usr/lib/python3/dist-packages/urllib3/util/retry.py", line 273, in increment
    raise MaxRetryError(_pool, url, error or ResponseError(cause))
requests.packages.urllib3.exceptions.MaxRetryError: HTTPConnectionPool(host='localhost', port=8000): Max retries exceeded with url: /buys/user/1/ (Caused by NewConnectionError('<requests.packages.urllib3.connection.HTTPConnection object at 0x7fd382b716a0>: Failed to establish a new connection: [Errno 111] Connection refused',))

During handling of the above exception, another exception occurred:

Traceback (most recent call last):
  File "/home/sanya/Documents/Git/rsoi_2lab/rsoi_2lab/ag_service/aggregator/views.py", line 140, in get
    r = requests.get(url_buys+"user/"+str(user_id)+"/")
  File "/usr/lib/python3/dist-packages/requests/api.py", line 67, in get
    return request('get', url, params=params, **kwargs)
  File "/usr/lib/python3/dist-packages/requests/api.py", line 53, in request
    return session.request(method=method, url=url, **kwargs)
  File "/usr/lib/python3/dist-packages/requests/sessions.py", line 468, in request
    resp = self.send(prep, **send_kwargs)
  File "/usr/lib/python3/dist-packages/requests/sessions.py", line 576, in send
    r = adapter.send(request, **kwargs)
  File "/usr/lib/python3/dist-packages/requests/adapters.py", line 437, in send
    raise ConnectionError(e, request=request)
requests.exceptions.ConnectionError: HTTPConnectionPool(host='localhost', port=8000): Max retries exceeded with url: /buys/user/1/ (Caused by NewConnectionError('<requests.packages.urllib3.connection.HTTPConnection object at 0x7fd382b716a0>: Failed to establish a new connection: [Errno 111] Connection refused',))

During handling of the above exception, another exception occurred:

Traceback (most recent call last):
  File "/usr/local/lib/python3.5/dist-packages/django/core/handlers/exception.py", line 35, in inner
    response = get_response(request)
  File "/usr/local/lib/python3.5/dist-packages/django/core/handlers/base.py", line 128, in _get_response
    response = self.process_exception_by_middleware(e, request)
  File "/usr/local/lib/python3.5/dist-packages/django/core/handlers/base.py", line 126, in _get_response
    response = wrapped_callback(request, *callback_args, **callback_kwargs)
  File "/usr/local/lib/python3.5/dist-packages/django/views/decorators/csrf.py", line 54, in wrapped_view
    return view_func(*args, **kwargs)
  File "/usr/local/lib/python3.5/dist-packages/django/views/generic/base.py", line 69, in view
    return self.dispatch(request, *args, **kwargs)
  File "/usr/local/lib/python3.5/dist-packages/rest_framework/views.py", line 494, in dispatch
    response = self.handle_exception(exc)
  File "/usr/local/lib/python3.5/dist-packages/rest_framework/views.py", line 454, in handle_exception
    self.raise_uncaught_exception(exc)
  File "/usr/local/lib/python3.5/dist-packages/rest_framework/views.py", line 491, in dispatch
    response = handler(request, *args, **kwargs)
  File "/home/sanya/Documents/Git/rsoi_2lab/rsoi_2lab/ag_service/aggregator/views.py", line 148, in get
    return HttpResponse(loader.render_to_string('503.html'), status=503)
NameError: name 'HttpResponse' is not defined
INFO:requests.packages.urllib3.connectionpool:Starting new HTTP connection (1): localhost
ERROR:django.request:Internal Server Error: /user/1/orders/
Traceback (most recent call last):
  File "/usr/lib/python3/dist-packages/urllib3/connection.py", line 137, in _new_conn
    (self.host, self.port), self.timeout, **extra_kw)
  File "/usr/lib/python3/dist-packages/urllib3/util/connection.py", line 91, in create_connection
    raise err
  File "/usr/lib/python3/dist-packages/urllib3/util/connection.py", line 81, in create_connection
    sock.connect(sa)
ConnectionRefusedError: [Errno 111] Connection refused

During handling of the above exception, another exception occurred:

Traceback (most recent call last):
  File "/usr/lib/python3/dist-packages/urllib3/connectionpool.py", line 560, in urlopen
    body=body, headers=headers)
  File "/usr/lib/python3/dist-packages/urllib3/connectionpool.py", line 354, in _make_request
    conn.request(method, url, **httplib_request_kw)
  File "/usr/lib/python3.5/http/client.py", line 1106, in request
    self._send_request(method, url, body, headers)
  File "/usr/lib/python3.5/http/client.py", line 1151, in _send_request
    self.endheaders(body)
  File "/usr/lib/python3.5/http/client.py", line 1102, in endheaders
    self._send_output(message_body)
  File "/usr/lib/python3.5/http/client.py", line 934, in _send_output
    self.send(msg)
  File "/usr/lib/python3.5/http/client.py", line 877, in send
    self.connect()
  File "/usr/lib/python3/dist-packages/urllib3/connection.py", line 162, in connect
    conn = self._new_conn()
  File "/usr/lib/python3/dist-packages/urllib3/connection.py", line 146, in _new_conn
    self, "Failed to establish a new connection: %s" % e)
requests.packages.urllib3.exceptions.NewConnectionError: <requests.packages.urllib3.connection.HTTPConnection object at 0x7f97c0191668>: Failed to establish a new connection: [Errno 111] Connection refused

During handling of the above exception, another exception occurred:

Traceback (most recent call last):
  File "/usr/lib/python3/dist-packages/requests/adapters.py", line 376, in send
    timeout=timeout
  File "/usr/lib/python3/dist-packages/urllib3/connectionpool.py", line 610, in urlopen
    _stacktrace=sys.exc_info()[2])
  File "/usr/lib/python3/dist-packages/urllib3/util/retry.py", line 273, in increment
    raise MaxRetryError(_pool, url, error or ResponseError(cause))
requests.packages.urllib3.exceptions.MaxRetryError: HTTPConnectionPool(host='localhost', port=8000): Max retries exceeded with url: /buys/user/1/ (Caused by NewConnectionError('<requests.packages.urllib3.connection.HTTPConnection object at 0x7f97c0191668>: Failed to establish a new connection: [Errno 111] Connection refused',))

During handling of the above exception, another exception occurred:

Traceback (most recent call last):
  File "/home/sanya/Documents/Git/rsoi_2lab/rsoi_2lab/ag_service/aggregator/views.py", line 140, in get
    r = requests.get(url_buys+"user/"+str(user_id)+"/")
  File "/usr/lib/python3/dist-packages/requests/api.py", line 67, in get
    return request('get', url, params=params, **kwargs)
  File "/usr/lib/python3/dist-packages/requests/api.py", line 53, in request
    return session.request(method=method, url=url, **kwargs)
  File "/usr/lib/python3/dist-packages/requests/sessions.py", line 468, in request
    resp = self.send(prep, **send_kwargs)
  File "/usr/lib/python3/dist-packages/requests/sessions.py", line 576, in send
    r = adapter.send(request, **kwargs)
  File "/usr/lib/python3/dist-packages/requests/adapters.py", line 437, in send
    raise ConnectionError(e, request=request)
requests.exceptions.ConnectionError: HTTPConnectionPool(host='localhost', port=8000): Max retries exceeded with url: /buys/user/1/ (Caused by NewConnectionError('<requests.packages.urllib3.connection.HTTPConnection object at 0x7f97c0191668>: Failed to establish a new connection: [Errno 111] Connection refused',))

During handling of the above exception, another exception occurred:

Traceback (most recent call last):
  File "/usr/local/lib/python3.5/dist-packages/django/core/handlers/exception.py", line 35, in inner
    response = get_response(request)
  File "/usr/local/lib/python3.5/dist-packages/django/core/handlers/base.py", line 128, in _get_response
    response = self.process_exception_by_middleware(e, request)
  File "/usr/local/lib/python3.5/dist-packages/django/core/handlers/base.py", line 126, in _get_response
    response = wrapped_callback(request, *callback_args, **callback_kwargs)
  File "/usr/local/lib/python3.5/dist-packages/django/views/decorators/csrf.py", line 54, in wrapped_view
    return view_func(*args, **kwargs)
  File "/usr/local/lib/python3.5/dist-packages/django/views/generic/base.py", line 69, in view
    return self.dispatch(request, *args, **kwargs)
  File "/usr/local/lib/python3.5/dist-packages/rest_framework/views.py", line 494, in dispatch
    response = self.handle_exception(exc)
  File "/usr/local/lib/python3.5/dist-packages/rest_framework/views.py", line 454, in handle_exception
    self.raise_uncaught_exception(exc)
  File "/usr/local/lib/python3.5/dist-packages/rest_framework/views.py", line 491, in dispatch
    response = handler(request, *args, **kwargs)
  File "/home/sanya/Documents/Git/rsoi_2lab/rsoi_2lab/ag_service/aggregator/views.py", line 148, in get
    return HttpResponse(loader.render_to_string('503.html'), status=503)
NameError: name 'HttpResponse' is not defined
INFO:requests.packages.urllib3.connectionpool:Starting new HTTP connection (1): localhost
ERROR:django.request:Internal Server Error: /user/1/orders/
Traceback (most recent call last):
  File "/usr/lib/python3/dist-packages/urllib3/connection.py", line 137, in _new_conn
    (self.host, self.port), self.timeout, **extra_kw)
  File "/usr/lib/python3/dist-packages/urllib3/util/connection.py", line 91, in create_connection
    raise err
  File "/usr/lib/python3/dist-packages/urllib3/util/connection.py", line 81, in create_connection
    sock.connect(sa)
ConnectionRefusedError: [Errno 111] Connection refused

During handling of the above exception, another exception occurred:

Traceback (most recent call last):
  File "/usr/lib/python3/dist-packages/urllib3/connectionpool.py", line 560, in urlopen
    body=body, headers=headers)
  File "/usr/lib/python3/dist-packages/urllib3/connectionpool.py", line 354, in _make_request
    conn.request(method, url, **httplib_request_kw)
  File "/usr/lib/python3.5/http/client.py", line 1106, in request
    self._send_request(method, url, body, headers)
  File "/usr/lib/python3.5/http/client.py", line 1151, in _send_request
    self.endheaders(body)
  File "/usr/lib/python3.5/http/client.py", line 1102, in endheaders
    self._send_output(message_body)
  File "/usr/lib/python3.5/http/client.py", line 934, in _send_output
    self.send(msg)
  File "/usr/lib/python3.5/http/client.py", line 877, in send
    self.connect()
  File "/usr/lib/python3/dist-packages/urllib3/connection.py", line 162, in connect
    conn = self._new_conn()
  File "/usr/lib/python3/dist-packages/urllib3/connection.py", line 146, in _new_conn
    self, "Failed to establish a new connection: %s" % e)
requests.packages.urllib3.exceptions.NewConnectionError: <requests.packages.urllib3.connection.HTTPConnection object at 0x7f97c01468d0>: Failed to establish a new connection: [Errno 111] Connection refused

During handling of the above exception, another exception occurred:

Traceback (most recent call last):
  File "/usr/lib/python3/dist-packages/requests/adapters.py", line 376, in send
    timeout=timeout
  File "/usr/lib/python3/dist-packages/urllib3/connectionpool.py", line 610, in urlopen
    _stacktrace=sys.exc_info()[2])
  File "/usr/lib/python3/dist-packages/urllib3/util/retry.py", line 273, in increment
    raise MaxRetryError(_pool, url, error or ResponseError(cause))
requests.packages.urllib3.exceptions.MaxRetryError: HTTPConnectionPool(host='localhost', port=8000): Max retries exceeded with url: /buys/user/1/ (Caused by NewConnectionError('<requests.packages.urllib3.connection.HTTPConnection object at 0x7f97c01468d0>: Failed to establish a new connection: [Errno 111] Connection refused',))

During handling of the above exception, another exception occurred:

Traceback (most recent call last):
  File "/home/sanya/Documents/Git/rsoi_2lab/rsoi_2lab/ag_service/aggregator/views.py", line 140, in get
    r = requests.get(url_buys+"user/"+str(user_id)+"/")
  File "/usr/lib/python3/dist-packages/requests/api.py", line 67, in get
    return request('get', url, params=params, **kwargs)
  File "/usr/lib/python3/dist-packages/requests/api.py", line 53, in request
    return session.request(method=method, url=url, **kwargs)
  File "/usr/lib/python3/dist-packages/requests/sessions.py", line 468, in request
    resp = self.send(prep, **send_kwargs)
  File "/usr/lib/python3/dist-packages/requests/sessions.py", line 576, in send
    r = adapter.send(request, **kwargs)
  File "/usr/lib/python3/dist-packages/requests/adapters.py", line 437, in send
    raise ConnectionError(e, request=request)
requests.exceptions.ConnectionError: HTTPConnectionPool(host='localhost', port=8000): Max retries exceeded with url: /buys/user/1/ (Caused by NewConnectionError('<requests.packages.urllib3.connection.HTTPConnection object at 0x7f97c01468d0>: Failed to establish a new connection: [Errno 111] Connection refused',))

During handling of the above exception, another exception occurred:

Traceback (most recent call last):
  File "/usr/local/lib/python3.5/dist-packages/django/core/handlers/exception.py", line 35, in inner
    response = get_response(request)
  File "/usr/local/lib/python3.5/dist-packages/django/core/handlers/base.py", line 128, in _get_response
    response = self.process_exception_by_middleware(e, request)
  File "/usr/local/lib/python3.5/dist-packages/django/core/handlers/base.py", line 126, in _get_response
    response = wrapped_callback(request, *callback_args, **callback_kwargs)
  File "/usr/local/lib/python3.5/dist-packages/django/views/decorators/csrf.py", line 54, in wrapped_view
    return view_func(*args, **kwargs)
  File "/usr/local/lib/python3.5/dist-packages/django/views/generic/base.py", line 69, in view
    return self.dispatch(request, *args, **kwargs)
  File "/usr/local/lib/python3.5/dist-packages/rest_framework/views.py", line 494, in dispatch
    response = self.handle_exception(exc)
  File "/usr/local/lib/python3.5/dist-packages/rest_framework/views.py", line 454, in handle_exception
    self.raise_uncaught_exception(exc)
  File "/usr/local/lib/python3.5/dist-packages/rest_framework/views.py", line 491, in dispatch
    response = handler(request, *args, **kwargs)
  File "/home/sanya/Documents/Git/rsoi_2lab/rsoi_2lab/ag_service/aggregator/views.py", line 148, in get
    return HttpResponse(loader.render_to_string('503.html'), status=503)
NameError: name 'HttpResponse' is not defined
INFO:requests.packages.urllib3.connectionpool:Starting new HTTP connection (1): localhost
ERROR:django.request:Internal Server Error: /user/1/orders/
Traceback (most recent call last):
  File "/usr/lib/python3/dist-packages/urllib3/connection.py", line 137, in _new_conn
    (self.host, self.port), self.timeout, **extra_kw)
  File "/usr/lib/python3/dist-packages/urllib3/util/connection.py", line 91, in create_connection
    raise err
  File "/usr/lib/python3/dist-packages/urllib3/util/connection.py", line 81, in create_connection
    sock.connect(sa)
ConnectionRefusedError: [Errno 111] Connection refused

During handling of the above exception, another exception occurred:

Traceback (most recent call last):
  File "/usr/lib/python3/dist-packages/urllib3/connectionpool.py", line 560, in urlopen
    body=body, headers=headers)
  File "/usr/lib/python3/dist-packages/urllib3/connectionpool.py", line 354, in _make_request
    conn.request(method, url, **httplib_request_kw)
  File "/usr/lib/python3.5/http/client.py", line 1106, in request
    self._send_request(method, url, body, headers)
  File "/usr/lib/python3.5/http/client.py", line 1151, in _send_request
    self.endheaders(body)
  File "/usr/lib/python3.5/http/client.py", line 1102, in endheaders
    self._send_output(message_body)
  File "/usr/lib/python3.5/http/client.py", line 934, in _send_output
    self.send(msg)
  File "/usr/lib/python3.5/http/client.py", line 877, in send
    self.connect()
  File "/usr/lib/python3/dist-packages/urllib3/connection.py", line 162, in connect
    conn = self._new_conn()
  File "/usr/lib/python3/dist-packages/urllib3/connection.py", line 146, in _new_conn
    self, "Failed to establish a new connection: %s" % e)
requests.packages.urllib3.exceptions.NewConnectionError: <requests.packages.urllib3.connection.HTTPConnection object at 0x7f97c0149438>: Failed to establish a new connection: [Errno 111] Connection refused

During handling of the above exception, another exception occurred:

Traceback (most recent call last):
  File "/usr/lib/python3/dist-packages/requests/adapters.py", line 376, in send
    timeout=timeout
  File "/usr/lib/python3/dist-packages/urllib3/connectionpool.py", line 610, in urlopen
    _stacktrace=sys.exc_info()[2])
  File "/usr/lib/python3/dist-packages/urllib3/util/retry.py", line 273, in increment
    raise MaxRetryError(_pool, url, error or ResponseError(cause))
requests.packages.urllib3.exceptions.MaxRetryError: HTTPConnectionPool(host='localhost', port=8000): Max retries exceeded with url: /buys/user/1/ (Caused by NewConnectionError('<requests.packages.urllib3.connection.HTTPConnection object at 0x7f97c0149438>: Failed to establish a new connection: [Errno 111] Connection refused',))

During handling of the above exception, another exception occurred:

Traceback (most recent call last):
  File "/home/sanya/Documents/Git/rsoi_2lab/rsoi_2lab/ag_service/aggregator/views.py", line 140, in get
    r = requests.get(url_buys+"user/"+str(user_id)+"/")
  File "/usr/lib/python3/dist-packages/requests/api.py", line 67, in get
    return request('get', url, params=params, **kwargs)
  File "/usr/lib/python3/dist-packages/requests/api.py", line 53, in request
    return session.request(method=method, url=url, **kwargs)
  File "/usr/lib/python3/dist-packages/requests/sessions.py", line 468, in request
    resp = self.send(prep, **send_kwargs)
  File "/usr/lib/python3/dist-packages/requests/sessions.py", line 576, in send
    r = adapter.send(request, **kwargs)
  File "/usr/lib/python3/dist-packages/requests/adapters.py", line 437, in send
    raise ConnectionError(e, request=request)
requests.exceptions.ConnectionError: HTTPConnectionPool(host='localhost', port=8000): Max retries exceeded with url: /buys/user/1/ (Caused by NewConnectionError('<requests.packages.urllib3.connection.HTTPConnection object at 0x7f97c0149438>: Failed to establish a new connection: [Errno 111] Connection refused',))

During handling of the above exception, another exception occurred:

Traceback (most recent call last):
  File "/usr/local/lib/python3.5/dist-packages/django/core/handlers/exception.py", line 35, in inner
    response = get_response(request)
  File "/usr/local/lib/python3.5/dist-packages/django/core/handlers/base.py", line 128, in _get_response
    response = self.process_exception_by_middleware(e, request)
  File "/usr/local/lib/python3.5/dist-packages/django/core/handlers/base.py", line 126, in _get_response
    response = wrapped_callback(request, *callback_args, **callback_kwargs)
  File "/usr/local/lib/python3.5/dist-packages/django/views/decorators/csrf.py", line 54, in wrapped_view
    return view_func(*args, **kwargs)
  File "/usr/local/lib/python3.5/dist-packages/django/views/generic/base.py", line 69, in view
    return self.dispatch(request, *args, **kwargs)
  File "/usr/local/lib/python3.5/dist-packages/rest_framework/views.py", line 494, in dispatch
    response = self.handle_exception(exc)
  File "/usr/local/lib/python3.5/dist-packages/rest_framework/views.py", line 454, in handle_exception
    self.raise_uncaught_exception(exc)
  File "/usr/local/lib/python3.5/dist-packages/rest_framework/views.py", line 491, in dispatch
    response = handler(request, *args, **kwargs)
  File "/home/sanya/Documents/Git/rsoi_2lab/rsoi_2lab/ag_service/aggregator/views.py", line 148, in get
    return HttpResponse(loader.render_to_string('503.html'), status=503)
NameError: name 'HttpResponse' is not defined
INFO:requests.packages.urllib3.connectionpool:Starting new HTTP connection (1): localhost
ERROR:django.request:Internal Server Error: /user/3/orders/
Traceback (most recent call last):
  File "/usr/lib/python3/dist-packages/urllib3/connection.py", line 137, in _new_conn
    (self.host, self.port), self.timeout, **extra_kw)
  File "/usr/lib/python3/dist-packages/urllib3/util/connection.py", line 91, in create_connection
    raise err
  File "/usr/lib/python3/dist-packages/urllib3/util/connection.py", line 81, in create_connection
    sock.connect(sa)
ConnectionRefusedError: [Errno 111] Connection refused

During handling of the above exception, another exception occurred:

Traceback (most recent call last):
  File "/usr/lib/python3/dist-packages/urllib3/connectionpool.py", line 560, in urlopen
    body=body, headers=headers)
  File "/usr/lib/python3/dist-packages/urllib3/connectionpool.py", line 354, in _make_request
    conn.request(method, url, **httplib_request_kw)
  File "/usr/lib/python3.5/http/client.py", line 1106, in request
    self._send_request(method, url, body, headers)
  File "/usr/lib/python3.5/http/client.py", line 1151, in _send_request
    self.endheaders(body)
  File "/usr/lib/python3.5/http/client.py", line 1102, in endheaders
    self._send_output(message_body)
  File "/usr/lib/python3.5/http/client.py", line 934, in _send_output
    self.send(msg)
  File "/usr/lib/python3.5/http/client.py", line 877, in send
    self.connect()
  File "/usr/lib/python3/dist-packages/urllib3/connection.py", line 162, in connect
    conn = self._new_conn()
  File "/usr/lib/python3/dist-packages/urllib3/connection.py", line 146, in _new_conn
    self, "Failed to establish a new connection: %s" % e)
requests.packages.urllib3.exceptions.NewConnectionError: <requests.packages.urllib3.connection.HTTPConnection object at 0x7f97c00ee2e8>: Failed to establish a new connection: [Errno 111] Connection refused

During handling of the above exception, another exception occurred:

Traceback (most recent call last):
  File "/usr/lib/python3/dist-packages/requests/adapters.py", line 376, in send
    timeout=timeout
  File "/usr/lib/python3/dist-packages/urllib3/connectionpool.py", line 610, in urlopen
    _stacktrace=sys.exc_info()[2])
  File "/usr/lib/python3/dist-packages/urllib3/util/retry.py", line 273, in increment
    raise MaxRetryError(_pool, url, error or ResponseError(cause))
requests.packages.urllib3.exceptions.MaxRetryError: HTTPConnectionPool(host='localhost', port=8000): Max retries exceeded with url: /buys/user/3/ (Caused by NewConnectionError('<requests.packages.urllib3.connection.HTTPConnection object at 0x7f97c00ee2e8>: Failed to establish a new connection: [Errno 111] Connection refused',))

During handling of the above exception, another exception occurred:

Traceback (most recent call last):
  File "/home/sanya/Documents/Git/rsoi_2lab/rsoi_2lab/ag_service/aggregator/views.py", line 140, in get
    r = requests.get(url_buys+"user/"+str(user_id)+"/")
  File "/usr/lib/python3/dist-packages/requests/api.py", line 67, in get
    return request('get', url, params=params, **kwargs)
  File "/usr/lib/python3/dist-packages/requests/api.py", line 53, in request
    return session.request(method=method, url=url, **kwargs)
  File "/usr/lib/python3/dist-packages/requests/sessions.py", line 468, in request
    resp = self.send(prep, **send_kwargs)
  File "/usr/lib/python3/dist-packages/requests/sessions.py", line 576, in send
    r = adapter.send(request, **kwargs)
  File "/usr/lib/python3/dist-packages/requests/adapters.py", line 437, in send
    raise ConnectionError(e, request=request)
requests.exceptions.ConnectionError: HTTPConnectionPool(host='localhost', port=8000): Max retries exceeded with url: /buys/user/3/ (Caused by NewConnectionError('<requests.packages.urllib3.connection.HTTPConnection object at 0x7f97c00ee2e8>: Failed to establish a new connection: [Errno 111] Connection refused',))

During handling of the above exception, another exception occurred:

Traceback (most recent call last):
  File "/usr/local/lib/python3.5/dist-packages/django/core/handlers/exception.py", line 35, in inner
    response = get_response(request)
  File "/usr/local/lib/python3.5/dist-packages/django/core/handlers/base.py", line 128, in _get_response
    response = self.process_exception_by_middleware(e, request)
  File "/usr/local/lib/python3.5/dist-packages/django/core/handlers/base.py", line 126, in _get_response
    response = wrapped_callback(request, *callback_args, **callback_kwargs)
  File "/usr/local/lib/python3.5/dist-packages/django/views/decorators/csrf.py", line 54, in wrapped_view
    return view_func(*args, **kwargs)
  File "/usr/local/lib/python3.5/dist-packages/django/views/generic/base.py", line 69, in view
    return self.dispatch(request, *args, **kwargs)
  File "/usr/local/lib/python3.5/dist-packages/rest_framework/views.py", line 494, in dispatch
    response = self.handle_exception(exc)
  File "/usr/local/lib/python3.5/dist-packages/rest_framework/views.py", line 454, in handle_exception
    self.raise_uncaught_exception(exc)
  File "/usr/local/lib/python3.5/dist-packages/rest_framework/views.py", line 491, in dispatch
    response = handler(request, *args, **kwargs)
  File "/home/sanya/Documents/Git/rsoi_2lab/rsoi_2lab/ag_service/aggregator/views.py", line 148, in get
    return HttpResponse(loader.render_to_string('503.html'), status=503)
NameError: name 'HttpResponse' is not defined
INFO:requests.packages.urllib3.connectionpool:Starting new HTTP connection (1): localhost
INFO:root:Show orders
INFO:requests.packages.urllib3.connectionpool:Starting new HTTP connection (1): localhost
INFO:root:Show orders
INFO:requests.packages.urllib3.connectionpool:Starting new HTTP connection (1): localhost
WARNING:django.request:Not Found: /user/1/orders/
WARNING:django.request:Not Found: /static/rest_framework/css/bootstrap.min.css
WARNING:django.request:Not Found: /static/rest_framework/css/bootstrap-tweaks.css
WARNING:django.request:Not Found: /static/rest_framework/css/prettify.css
WARNING:django.request:Not Found: /static/rest_framework/css/default.css
WARNING:django.request:Not Found: /static/rest_framework/js/ajax-form.js
WARNING:django.request:Not Found: /static/rest_framework/js/jquery-1.12.4.min.js
WARNING:django.request:Not Found: /static/rest_framework/js/csrf.js
WARNING:django.request:Not Found: /static/rest_framework/js/bootstrap.min.js
WARNING:django.request:Not Found: /static/rest_framework/js/prettify-min.js
WARNING:django.request:Not Found: /static/rest_framework/js/default.js
WARNING:django.request:Not Found: /static/rest_framework/js/jquery-1.12.4.min.js
WARNING:django.request:Not Found: /static/rest_framework/js/ajax-form.js
WARNING:django.request:Not Found: /static/rest_framework/js/csrf.js
WARNING:django.request:Not Found: /static/rest_framework/js/bootstrap.min.js
WARNING:django.request:Not Found: /static/rest_framework/js/prettify-min.js
WARNING:django.request:Not Found: /static/rest_framework/js/default.js
INFO:requests.packages.urllib3.connectionpool:Starting new HTTP connection (1): localhost
WARNING:django.request:Not Found: /user/1/orders/
INFO:requests.packages.urllib3.connectionpool:Starting new HTTP connection (1): localhost
ERROR:django.request:Internal Server Error: /user/1/orders/
Traceback (most recent call last):
  File "/usr/lib/python3/dist-packages/urllib3/connection.py", line 137, in _new_conn
    (self.host, self.port), self.timeout, **extra_kw)
  File "/usr/lib/python3/dist-packages/urllib3/util/connection.py", line 91, in create_connection
    raise err
  File "/usr/lib/python3/dist-packages/urllib3/util/connection.py", line 81, in create_connection
    sock.connect(sa)
ConnectionRefusedError: [Errno 111] Connection refused

During handling of the above exception, another exception occurred:

Traceback (most recent call last):
  File "/usr/lib/python3/dist-packages/urllib3/connectionpool.py", line 560, in urlopen
    body=body, headers=headers)
  File "/usr/lib/python3/dist-packages/urllib3/connectionpool.py", line 354, in _make_request
    conn.request(method, url, **httplib_request_kw)
  File "/usr/lib/python3.5/http/client.py", line 1106, in request
    self._send_request(method, url, body, headers)
  File "/usr/lib/python3.5/http/client.py", line 1151, in _send_request
    self.endheaders(body)
  File "/usr/lib/python3.5/http/client.py", line 1102, in endheaders
    self._send_output(message_body)
  File "/usr/lib/python3.5/http/client.py", line 934, in _send_output
    self.send(msg)
  File "/usr/lib/python3.5/http/client.py", line 877, in send
    self.connect()
  File "/usr/lib/python3/dist-packages/urllib3/connection.py", line 162, in connect
    conn = self._new_conn()
  File "/usr/lib/python3/dist-packages/urllib3/connection.py", line 146, in _new_conn
    self, "Failed to establish a new connection: %s" % e)
requests.packages.urllib3.exceptions.NewConnectionError: <requests.packages.urllib3.connection.HTTPConnection object at 0x7f35505ea0b8>: Failed to establish a new connection: [Errno 111] Connection refused

During handling of the above exception, another exception occurred:

Traceback (most recent call last):
  File "/usr/lib/python3/dist-packages/requests/adapters.py", line 376, in send
    timeout=timeout
  File "/usr/lib/python3/dist-packages/urllib3/connectionpool.py", line 610, in urlopen
    _stacktrace=sys.exc_info()[2])
  File "/usr/lib/python3/dist-packages/urllib3/util/retry.py", line 273, in increment
    raise MaxRetryError(_pool, url, error or ResponseError(cause))
requests.packages.urllib3.exceptions.MaxRetryError: HTTPConnectionPool(host='localhost', port=8000): Max retries exceeded with url: /buys/user/1/ (Caused by NewConnectionError('<requests.packages.urllib3.connection.HTTPConnection object at 0x7f35505ea0b8>: Failed to establish a new connection: [Errno 111] Connection refused',))

During handling of the above exception, another exception occurred:

Traceback (most recent call last):
  File "/home/sanya/Documents/Git/rsoi_2lab/rsoi_2lab/ag_service/aggregator/views.py", line 140, in get
    r = requests.get(url_buys+"user/"+str(user_id)+"/")
  File "/usr/lib/python3/dist-packages/requests/api.py", line 67, in get
    return request('get', url, params=params, **kwargs)
  File "/usr/lib/python3/dist-packages/requests/api.py", line 53, in request
    return session.request(method=method, url=url, **kwargs)
  File "/usr/lib/python3/dist-packages/requests/sessions.py", line 468, in request
    resp = self.send(prep, **send_kwargs)
  File "/usr/lib/python3/dist-packages/requests/sessions.py", line 576, in send
    r = adapter.send(request, **kwargs)
  File "/usr/lib/python3/dist-packages/requests/adapters.py", line 437, in send
    raise ConnectionError(e, request=request)
requests.exceptions.ConnectionError: HTTPConnectionPool(host='localhost', port=8000): Max retries exceeded with url: /buys/user/1/ (Caused by NewConnectionError('<requests.packages.urllib3.connection.HTTPConnection object at 0x7f35505ea0b8>: Failed to establish a new connection: [Errno 111] Connection refused',))

During handling of the above exception, another exception occurred:

Traceback (most recent call last):
  File "/usr/local/lib/python3.5/dist-packages/django/core/handlers/exception.py", line 35, in inner
    response = get_response(request)
  File "/usr/local/lib/python3.5/dist-packages/django/core/handlers/base.py", line 128, in _get_response
    response = self.process_exception_by_middleware(e, request)
  File "/usr/local/lib/python3.5/dist-packages/django/core/handlers/base.py", line 126, in _get_response
    response = wrapped_callback(request, *callback_args, **callback_kwargs)
  File "/usr/local/lib/python3.5/dist-packages/django/views/decorators/csrf.py", line 54, in wrapped_view
    return view_func(*args, **kwargs)
  File "/usr/local/lib/python3.5/dist-packages/django/views/generic/base.py", line 69, in view
    return self.dispatch(request, *args, **kwargs)
  File "/usr/local/lib/python3.5/dist-packages/rest_framework/views.py", line 494, in dispatch
    response = self.handle_exception(exc)
  File "/usr/local/lib/python3.5/dist-packages/rest_framework/views.py", line 454, in handle_exception
    self.raise_uncaught_exception(exc)
  File "/usr/local/lib/python3.5/dist-packages/rest_framework/views.py", line 491, in dispatch
    response = handler(request, *args, **kwargs)
  File "/home/sanya/Documents/Git/rsoi_2lab/rsoi_2lab/ag_service/aggregator/views.py", line 148, in get
    return HttpResponse(loader.render_to_string('503.html'), status=503)
NameError: name 'HttpResponse' is not defined
INFO:requests.packages.urllib3.connectionpool:Starting new HTTP connection (1): localhost
INFO:requests.packages.urllib3.connectionpool:Starting new HTTP connection (1): localhost
WARNING:django.request:Not Found: /user/1/orders/
INFO:requests.packages.urllib3.connectionpool:Starting new HTTP connection (1): localhost
INFO:root:Show orders
INFO:requests.packages.urllib3.connectionpool:Starting new HTTP connection (1): localhost
INFO:root:Show orders
INFO:requests.packages.urllib3.connectionpool:Starting new HTTP connection (1): localhost
WARNING:django.request:Not Found: /user/6/orders/
INFO:requests.packages.urllib3.connectionpool:Starting new HTTP connection (1): localhost
INFO:root:Show orders
ERROR:django.request:Internal Server Error: /user/3/orders/
Traceback (most recent call last):
  File "/usr/local/lib/python3.5/dist-packages/django/core/handlers/exception.py", line 35, in inner
    response = get_response(request)
  File "/usr/local/lib/python3.5/dist-packages/django/core/handlers/base.py", line 128, in _get_response
    response = self.process_exception_by_middleware(e, request)
  File "/usr/local/lib/python3.5/dist-packages/django/core/handlers/base.py", line 126, in _get_response
    response = wrapped_callback(request, *callback_args, **callback_kwargs)
  File "/usr/local/lib/python3.5/dist-packages/django/views/decorators/csrf.py", line 54, in wrapped_view
    return view_func(*args, **kwargs)
  File "/usr/local/lib/python3.5/dist-packages/django/views/generic/base.py", line 69, in view
    return self.dispatch(request, *args, **kwargs)
  File "/usr/local/lib/python3.5/dist-packages/rest_framework/views.py", line 494, in dispatch
    response = self.handle_exception(exc)
  File "/usr/local/lib/python3.5/dist-packages/rest_framework/views.py", line 454, in handle_exception
    self.raise_uncaught_exception(exc)
  File "/usr/local/lib/python3.5/dist-packages/rest_framework/views.py", line 491, in dispatch
    response = handler(request, *args, **kwargs)
  File "/home/sanya/Documents/Git/rsoi_2lab/rsoi_2lab/ag_service/aggregator/views.py", line 154, in get
    return render(request, 'index.html', {'result':r.json(object_pairs_hook=OrderedDict)})
  File "/usr/local/lib/python3.5/dist-packages/django/shortcuts.py", line 36, in render
    content = loader.render_to_string(template_name, context, request, using=using)
  File "/usr/local/lib/python3.5/dist-packages/django/template/loader.py", line 62, in render_to_string
    return template.render(context, request)
  File "/usr/local/lib/python3.5/dist-packages/django/template/backends/django.py", line 61, in render
    return self.template.render(context)
  File "/usr/local/lib/python3.5/dist-packages/django/template/base.py", line 175, in render
    return self._render(context)
  File "/usr/local/lib/python3.5/dist-packages/django/template/base.py", line 167, in _render
    return self.nodelist.render(context)
  File "/usr/local/lib/python3.5/dist-packages/django/template/base.py", line 943, in render
    bit = node.render_annotated(context)
  File "/usr/local/lib/python3.5/dist-packages/django/template/base.py", line 910, in render_annotated
    return self.render(context)
  File "/usr/local/lib/python3.5/dist-packages/django/template/defaulttags.py", line 211, in render
    nodelist.append(node.render_annotated(context))
  File "/usr/local/lib/python3.5/dist-packages/django/template/base.py", line 910, in render_annotated
    return self.render(context)
  File "/usr/local/lib/python3.5/dist-packages/django/template/defaulttags.py", line 447, in render
    url = reverse(view_name, args=args, kwargs=kwargs, current_app=current_app)
  File "/usr/local/lib/python3.5/dist-packages/django/urls/base.py", line 88, in reverse
    return iri_to_uri(resolver._reverse_with_prefix(view, prefix, *args, **kwargs))
  File "/usr/local/lib/python3.5/dist-packages/django/urls/resolvers.py", line 632, in _reverse_with_prefix
    raise NoReverseMatch(msg)
django.urls.exceptions.NoReverseMatch: Reverse for 'agg1' with arguments '(6,)' not found. 1 pattern(s) tried: ['user\\/(?P<user_id>[^/]+)\\/order\\/(?P<order_id>[^/]+)\\/$']
INFO:requests.packages.urllib3.connectionpool:Starting new HTTP connection (1): localhost
INFO:root:Show orders
INFO:requests.packages.urllib3.connectionpool:Starting new HTTP connection (1): localhost
ERROR:django.request:Internal Server Error: /user/agg2/order/6/
Traceback (most recent call last):
  File "/usr/local/lib/python3.5/dist-packages/django/core/handlers/exception.py", line 35, in inner
    response = get_response(request)
  File "/usr/local/lib/python3.5/dist-packages/django/core/handlers/base.py", line 128, in _get_response
    response = self.process_exception_by_middleware(e, request)
  File "/usr/local/lib/python3.5/dist-packages/django/core/handlers/base.py", line 126, in _get_response
    response = wrapped_callback(request, *callback_args, **callback_kwargs)
  File "/usr/local/lib/python3.5/dist-packages/django/views/decorators/csrf.py", line 54, in wrapped_view
    return view_func(*args, **kwargs)
  File "/usr/local/lib/python3.5/dist-packages/django/views/generic/base.py", line 69, in view
    return self.dispatch(request, *args, **kwargs)
  File "/usr/local/lib/python3.5/dist-packages/rest_framework/views.py", line 494, in dispatch
    response = self.handle_exception(exc)
  File "/usr/local/lib/python3.5/dist-packages/rest_framework/views.py", line 454, in handle_exception
    self.raise_uncaught_exception(exc)
  File "/usr/local/lib/python3.5/dist-packages/rest_framework/views.py", line 491, in dispatch
    response = handler(request, *args, **kwargs)
  File "/home/sanya/Documents/Git/rsoi_2lab/rsoi_2lab/ag_service/aggregator/views.py", line 47, in get
    return Response(r.json(), status=status_code)
  File "/usr/lib/python3/dist-packages/requests/models.py", line 808, in json
    return complexjson.loads(self.text, **kwargs)
  File "/usr/lib/python3.5/json/__init__.py", line 319, in loads
    return _default_decoder.decode(s)
  File "/usr/lib/python3.5/json/decoder.py", line 339, in decode
    obj, end = self.raw_decode(s, idx=_w(s, 0).end())
  File "/usr/lib/python3.5/json/decoder.py", line 357, in raw_decode
    raise JSONDecodeError("Expecting value", s, err.value) from None
json.decoder.JSONDecodeError: Expecting value: line 1 column 1 (char 0)
INFO:requests.packages.urllib3.connectionpool:Starting new HTTP connection (1): localhost
INFO:root:Show orders
ERROR:django.request:Internal Server Error: /user/3/orders/
Traceback (most recent call last):
  File "/usr/local/lib/python3.5/dist-packages/django/core/handlers/exception.py", line 35, in inner
    response = get_response(request)
  File "/usr/local/lib/python3.5/dist-packages/django/core/handlers/base.py", line 128, in _get_response
    response = self.process_exception_by_middleware(e, request)
  File "/usr/local/lib/python3.5/dist-packages/django/core/handlers/base.py", line 126, in _get_response
    response = wrapped_callback(request, *callback_args, **callback_kwargs)
  File "/usr/local/lib/python3.5/dist-packages/django/views/decorators/csrf.py", line 54, in wrapped_view
    return view_func(*args, **kwargs)
  File "/usr/local/lib/python3.5/dist-packages/django/views/generic/base.py", line 69, in view
    return self.dispatch(request, *args, **kwargs)
  File "/usr/local/lib/python3.5/dist-packages/rest_framework/views.py", line 494, in dispatch
    response = self.handle_exception(exc)
  File "/usr/local/lib/python3.5/dist-packages/rest_framework/views.py", line 454, in handle_exception
    self.raise_uncaught_exception(exc)
  File "/usr/local/lib/python3.5/dist-packages/rest_framework/views.py", line 491, in dispatch
    response = handler(request, *args, **kwargs)
  File "/home/sanya/Documents/Git/rsoi_2lab/rsoi_2lab/ag_service/aggregator/views.py", line 155, in get
    return render(request, 'index.html', {'result':r.json(object_pairs_hook=OrderedDict)})
  File "/usr/local/lib/python3.5/dist-packages/django/shortcuts.py", line 36, in render
    content = loader.render_to_string(template_name, context, request, using=using)
  File "/usr/local/lib/python3.5/dist-packages/django/template/loader.py", line 62, in render_to_string
    return template.render(context, request)
  File "/usr/local/lib/python3.5/dist-packages/django/template/backends/django.py", line 61, in render
    return self.template.render(context)
  File "/usr/local/lib/python3.5/dist-packages/django/template/base.py", line 175, in render
    return self._render(context)
  File "/usr/local/lib/python3.5/dist-packages/django/template/base.py", line 167, in _render
    return self.nodelist.render(context)
  File "/usr/local/lib/python3.5/dist-packages/django/template/base.py", line 943, in render
    bit = node.render_annotated(context)
  File "/usr/local/lib/python3.5/dist-packages/django/template/base.py", line 910, in render_annotated
    return self.render(context)
  File "/usr/local/lib/python3.5/dist-packages/django/template/defaulttags.py", line 211, in render
    nodelist.append(node.render_annotated(context))
  File "/usr/local/lib/python3.5/dist-packages/django/template/base.py", line 910, in render_annotated
    return self.render(context)
  File "/usr/local/lib/python3.5/dist-packages/django/template/defaulttags.py", line 447, in render
    url = reverse(view_name, args=args, kwargs=kwargs, current_app=current_app)
  File "/usr/local/lib/python3.5/dist-packages/django/urls/base.py", line 88, in reverse
    return iri_to_uri(resolver._reverse_with_prefix(view, prefix, *args, **kwargs))
  File "/usr/local/lib/python3.5/dist-packages/django/urls/resolvers.py", line 632, in _reverse_with_prefix
    raise NoReverseMatch(msg)
django.urls.exceptions.NoReverseMatch: Reverse for 'agg1' with arguments '('', 6)' not found. 1 pattern(s) tried: ['user\\/(?P<user_id>[^/]+)\\/order\\/(?P<order_id>[^/]+)\\/$']
INFO:requests.packages.urllib3.connectionpool:Starting new HTTP connection (1): localhost
INFO:root:Show orders
ERROR:django.request:Internal Server Error: /user/3/orders/
Traceback (most recent call last):
  File "/usr/local/lib/python3.5/dist-packages/django/core/handlers/exception.py", line 35, in inner
    response = get_response(request)
  File "/usr/local/lib/python3.5/dist-packages/django/core/handlers/base.py", line 128, in _get_response
    response = self.process_exception_by_middleware(e, request)
  File "/usr/local/lib/python3.5/dist-packages/django/core/handlers/base.py", line 126, in _get_response
    response = wrapped_callback(request, *callback_args, **callback_kwargs)
  File "/usr/local/lib/python3.5/dist-packages/django/views/decorators/csrf.py", line 54, in wrapped_view
    return view_func(*args, **kwargs)
  File "/usr/local/lib/python3.5/dist-packages/django/views/generic/base.py", line 69, in view
    return self.dispatch(request, *args, **kwargs)
  File "/usr/local/lib/python3.5/dist-packages/rest_framework/views.py", line 494, in dispatch
    response = self.handle_exception(exc)
  File "/usr/local/lib/python3.5/dist-packages/rest_framework/views.py", line 454, in handle_exception
    self.raise_uncaught_exception(exc)
  File "/usr/local/lib/python3.5/dist-packages/rest_framework/views.py", line 491, in dispatch
    response = handler(request, *args, **kwargs)
  File "/home/sanya/Documents/Git/rsoi_2lab/rsoi_2lab/ag_service/aggregator/views.py", line 155, in get
    return render(request, 'index.html', {'result':r.json(object_pairs_hook=OrderedDict)})
  File "/usr/local/lib/python3.5/dist-packages/django/shortcuts.py", line 36, in render
    content = loader.render_to_string(template_name, context, request, using=using)
  File "/usr/local/lib/python3.5/dist-packages/django/template/loader.py", line 62, in render_to_string
    return template.render(context, request)
  File "/usr/local/lib/python3.5/dist-packages/django/template/backends/django.py", line 61, in render
    return self.template.render(context)
  File "/usr/local/lib/python3.5/dist-packages/django/template/base.py", line 175, in render
    return self._render(context)
  File "/usr/local/lib/python3.5/dist-packages/django/template/base.py", line 167, in _render
    return self.nodelist.render(context)
  File "/usr/local/lib/python3.5/dist-packages/django/template/base.py", line 943, in render
    bit = node.render_annotated(context)
  File "/usr/local/lib/python3.5/dist-packages/django/template/base.py", line 910, in render_annotated
    return self.render(context)
  File "/usr/local/lib/python3.5/dist-packages/django/template/defaulttags.py", line 211, in render
    nodelist.append(node.render_annotated(context))
  File "/usr/local/lib/python3.5/dist-packages/django/template/base.py", line 910, in render_annotated
    return self.render(context)
  File "/usr/local/lib/python3.5/dist-packages/django/template/defaulttags.py", line 447, in render
    url = reverse(view_name, args=args, kwargs=kwargs, current_app=current_app)
  File "/usr/local/lib/python3.5/dist-packages/django/urls/base.py", line 88, in reverse
    return iri_to_uri(resolver._reverse_with_prefix(view, prefix, *args, **kwargs))
  File "/usr/local/lib/python3.5/dist-packages/django/urls/resolvers.py", line 632, in _reverse_with_prefix
    raise NoReverseMatch(msg)
django.urls.exceptions.NoReverseMatch: Reverse for 'agg1' with arguments '('', 6)' not found. 1 pattern(s) tried: ['user\\/(?P<user_id>[^/]+)\\/order\\/(?P<order_id>[^/]+)\\/$']
INFO:requests.packages.urllib3.connectionpool:Starting new HTTP connection (1): localhost
INFO:root:Show orders
ERROR:django.request:Internal Server Error: /user/3/orders/
Traceback (most recent call last):
  File "/usr/local/lib/python3.5/dist-packages/django/core/handlers/exception.py", line 35, in inner
    response = get_response(request)
  File "/usr/local/lib/python3.5/dist-packages/django/core/handlers/base.py", line 128, in _get_response
    response = self.process_exception_by_middleware(e, request)
  File "/usr/local/lib/python3.5/dist-packages/django/core/handlers/base.py", line 126, in _get_response
    response = wrapped_callback(request, *callback_args, **callback_kwargs)
  File "/usr/local/lib/python3.5/dist-packages/django/views/decorators/csrf.py", line 54, in wrapped_view
    return view_func(*args, **kwargs)
  File "/usr/local/lib/python3.5/dist-packages/django/views/generic/base.py", line 69, in view
    return self.dispatch(request, *args, **kwargs)
  File "/usr/local/lib/python3.5/dist-packages/rest_framework/views.py", line 494, in dispatch
    response = self.handle_exception(exc)
  File "/usr/local/lib/python3.5/dist-packages/rest_framework/views.py", line 454, in handle_exception
    self.raise_uncaught_exception(exc)
  File "/usr/local/lib/python3.5/dist-packages/rest_framework/views.py", line 491, in dispatch
    response = handler(request, *args, **kwargs)
  File "/home/sanya/Documents/Git/rsoi_2lab/rsoi_2lab/ag_service/aggregator/views.py", line 155, in get
    return render(request, 'index.html', {'result':r.json(object_pairs_hook=OrderedDict)})
  File "/usr/local/lib/python3.5/dist-packages/django/shortcuts.py", line 36, in render
    content = loader.render_to_string(template_name, context, request, using=using)
  File "/usr/local/lib/python3.5/dist-packages/django/template/loader.py", line 61, in render_to_string
    template = get_template(template_name, using=using)
  File "/usr/local/lib/python3.5/dist-packages/django/template/loader.py", line 15, in get_template
    return engine.get_template(template_name)
  File "/usr/local/lib/python3.5/dist-packages/django/template/backends/django.py", line 34, in get_template
    return Template(self.engine.get_template(template_name), self)
  File "/usr/local/lib/python3.5/dist-packages/django/template/engine.py", line 144, in get_template
    template, origin = self.find_template(template_name)
  File "/usr/local/lib/python3.5/dist-packages/django/template/engine.py", line 126, in find_template
    template = loader.get_template(name, skip=skip)
  File "/usr/local/lib/python3.5/dist-packages/django/template/loaders/base.py", line 30, in get_template
    contents, origin, origin.template_name, self.engine,
  File "/usr/local/lib/python3.5/dist-packages/django/template/base.py", line 160, in __init__
    self.nodelist = self.compile_nodelist()
  File "/usr/local/lib/python3.5/dist-packages/django/template/base.py", line 198, in compile_nodelist
    return parser.parse()
  File "/usr/local/lib/python3.5/dist-packages/django/template/base.py", line 483, in parse
    raise self.error(token, e)
  File "/usr/local/lib/python3.5/dist-packages/django/template/base.py", line 481, in parse
    compiled_result = compile_func(self, token)
  File "/usr/local/lib/python3.5/dist-packages/django/template/defaulttags.py", line 815, in do_for
    nodelist_loop = parser.parse(('empty', 'endfor',))
  File "/usr/local/lib/python3.5/dist-packages/django/template/base.py", line 483, in parse
    raise self.error(token, e)
  File "/usr/local/lib/python3.5/dist-packages/django/template/base.py", line 481, in parse
    compiled_result = compile_func(self, token)
  File "/usr/local/lib/python3.5/dist-packages/django/template/defaulttags.py", line 1381, in url
    args.append(parser.compile_filter(value))
  File "/usr/local/lib/python3.5/dist-packages/django/template/base.py", line 568, in compile_filter
    return FilterExpression(token, self)
  File "/usr/local/lib/python3.5/dist-packages/django/template/base.py", line 668, in __init__
    "from '%s'" % (token[upto:], token))
django.template.exceptions.TemplateSyntaxError: Could not parse the remainder: '{{request.GET.user_id}}' from '{{request.GET.user_id}}'
INFO:requests.packages.urllib3.connectionpool:Starting new HTTP connection (1): localhost
INFO:root:Show orders
ERROR:django.request:Internal Server Error: /user/3/orders/
Traceback (most recent call last):
  File "/usr/local/lib/python3.5/dist-packages/django/core/handlers/exception.py", line 35, in inner
    response = get_response(request)
  File "/usr/local/lib/python3.5/dist-packages/django/core/handlers/base.py", line 128, in _get_response
    response = self.process_exception_by_middleware(e, request)
  File "/usr/local/lib/python3.5/dist-packages/django/core/handlers/base.py", line 126, in _get_response
    response = wrapped_callback(request, *callback_args, **callback_kwargs)
  File "/usr/local/lib/python3.5/dist-packages/django/views/decorators/csrf.py", line 54, in wrapped_view
    return view_func(*args, **kwargs)
  File "/usr/local/lib/python3.5/dist-packages/django/views/generic/base.py", line 69, in view
    return self.dispatch(request, *args, **kwargs)
  File "/usr/local/lib/python3.5/dist-packages/rest_framework/views.py", line 494, in dispatch
    response = self.handle_exception(exc)
  File "/usr/local/lib/python3.5/dist-packages/rest_framework/views.py", line 454, in handle_exception
    self.raise_uncaught_exception(exc)
  File "/usr/local/lib/python3.5/dist-packages/rest_framework/views.py", line 491, in dispatch
    response = handler(request, *args, **kwargs)
  File "/home/sanya/Documents/Git/rsoi_2lab/rsoi_2lab/ag_service/aggregator/views.py", line 155, in get
    return render(request, 'index.html', {'result':r.json(object_pairs_hook=OrderedDict)})
  File "/usr/local/lib/python3.5/dist-packages/django/shortcuts.py", line 36, in render
    content = loader.render_to_string(template_name, context, request, using=using)
  File "/usr/local/lib/python3.5/dist-packages/django/template/loader.py", line 62, in render_to_string
    return template.render(context, request)
  File "/usr/local/lib/python3.5/dist-packages/django/template/backends/django.py", line 61, in render
    return self.template.render(context)
  File "/usr/local/lib/python3.5/dist-packages/django/template/base.py", line 175, in render
    return self._render(context)
  File "/usr/local/lib/python3.5/dist-packages/django/template/base.py", line 167, in _render
    return self.nodelist.render(context)
  File "/usr/local/lib/python3.5/dist-packages/django/template/base.py", line 943, in render
    bit = node.render_annotated(context)
  File "/usr/local/lib/python3.5/dist-packages/django/template/base.py", line 910, in render_annotated
    return self.render(context)
  File "/usr/local/lib/python3.5/dist-packages/django/template/defaulttags.py", line 211, in render
    nodelist.append(node.render_annotated(context))
  File "/usr/local/lib/python3.5/dist-packages/django/template/base.py", line 910, in render_annotated
    return self.render(context)
  File "/usr/local/lib/python3.5/dist-packages/django/template/defaulttags.py", line 447, in render
    url = reverse(view_name, args=args, kwargs=kwargs, current_app=current_app)
  File "/usr/local/lib/python3.5/dist-packages/django/urls/base.py", line 88, in reverse
    return iri_to_uri(resolver._reverse_with_prefix(view, prefix, *args, **kwargs))
  File "/usr/local/lib/python3.5/dist-packages/django/urls/resolvers.py", line 632, in _reverse_with_prefix
    raise NoReverseMatch(msg)
django.urls.exceptions.NoReverseMatch: Reverse for 'agg1' with arguments '('', 6)' not found. 1 pattern(s) tried: ['user\\/(?P<user_id>[^/]+)\\/order\\/(?P<order_id>[^/]+)\\/$']
INFO:requests.packages.urllib3.connectionpool:Starting new HTTP connection (1): localhost
INFO:root:Show orders
ERROR:django.request:Internal Server Error: /user/3/orders/
Traceback (most recent call last):
  File "/usr/local/lib/python3.5/dist-packages/django/core/handlers/exception.py", line 35, in inner
    response = get_response(request)
  File "/usr/local/lib/python3.5/dist-packages/django/core/handlers/base.py", line 128, in _get_response
    response = self.process_exception_by_middleware(e, request)
  File "/usr/local/lib/python3.5/dist-packages/django/core/handlers/base.py", line 126, in _get_response
    response = wrapped_callback(request, *callback_args, **callback_kwargs)
  File "/usr/local/lib/python3.5/dist-packages/django/views/decorators/csrf.py", line 54, in wrapped_view
    return view_func(*args, **kwargs)
  File "/usr/local/lib/python3.5/dist-packages/django/views/generic/base.py", line 69, in view
    return self.dispatch(request, *args, **kwargs)
  File "/usr/local/lib/python3.5/dist-packages/rest_framework/views.py", line 494, in dispatch
    response = self.handle_exception(exc)
  File "/usr/local/lib/python3.5/dist-packages/rest_framework/views.py", line 454, in handle_exception
    self.raise_uncaught_exception(exc)
  File "/usr/local/lib/python3.5/dist-packages/rest_framework/views.py", line 491, in dispatch
    response = handler(request, *args, **kwargs)
  File "/home/sanya/Documents/Git/rsoi_2lab/rsoi_2lab/ag_service/aggregator/views.py", line 155, in get
    return render(request, 'index.html', {'result':r.json(object_pairs_hook=OrderedDict)})
  File "/usr/local/lib/python3.5/dist-packages/django/shortcuts.py", line 36, in render
    content = loader.render_to_string(template_name, context, request, using=using)
  File "/usr/local/lib/python3.5/dist-packages/django/template/loader.py", line 61, in render_to_string
    template = get_template(template_name, using=using)
  File "/usr/local/lib/python3.5/dist-packages/django/template/loader.py", line 15, in get_template
    return engine.get_template(template_name)
  File "/usr/local/lib/python3.5/dist-packages/django/template/backends/django.py", line 34, in get_template
    return Template(self.engine.get_template(template_name), self)
  File "/usr/local/lib/python3.5/dist-packages/django/template/engine.py", line 144, in get_template
    template, origin = self.find_template(template_name)
  File "/usr/local/lib/python3.5/dist-packages/django/template/engine.py", line 126, in find_template
    template = loader.get_template(name, skip=skip)
  File "/usr/local/lib/python3.5/dist-packages/django/template/loaders/base.py", line 30, in get_template
    contents, origin, origin.template_name, self.engine,
  File "/usr/local/lib/python3.5/dist-packages/django/template/base.py", line 160, in __init__
    self.nodelist = self.compile_nodelist()
  File "/usr/local/lib/python3.5/dist-packages/django/template/base.py", line 198, in compile_nodelist
    return parser.parse()
  File "/usr/local/lib/python3.5/dist-packages/django/template/base.py", line 483, in parse
    raise self.error(token, e)
  File "/usr/local/lib/python3.5/dist-packages/django/template/base.py", line 481, in parse
    compiled_result = compile_func(self, token)
  File "/usr/local/lib/python3.5/dist-packages/django/template/defaulttags.py", line 815, in do_for
    nodelist_loop = parser.parse(('empty', 'endfor',))
  File "/usr/local/lib/python3.5/dist-packages/django/template/base.py", line 483, in parse
    raise self.error(token, e)
  File "/usr/local/lib/python3.5/dist-packages/django/template/base.py", line 481, in parse
    compiled_result = compile_func(self, token)
  File "/usr/local/lib/python3.5/dist-packages/django/template/defaulttags.py", line 1381, in url
    args.append(parser.compile_filter(value))
  File "/usr/local/lib/python3.5/dist-packages/django/template/base.py", line 568, in compile_filter
    return FilterExpression(token, self)
  File "/usr/local/lib/python3.5/dist-packages/django/template/base.py", line 668, in __init__
    "from '%s'" % (token[upto:], token))
django.template.exceptions.TemplateSyntaxError: Could not parse the remainder: '{{' from '{{'
INFO:requests.packages.urllib3.connectionpool:Starting new HTTP connection (1): localhost
INFO:root:Show orders
ERROR:django.request:Internal Server Error: /user/3/orders/
Traceback (most recent call last):
  File "/usr/local/lib/python3.5/dist-packages/django/core/handlers/exception.py", line 35, in inner
    response = get_response(request)
  File "/usr/local/lib/python3.5/dist-packages/django/core/handlers/base.py", line 128, in _get_response
    response = self.process_exception_by_middleware(e, request)
  File "/usr/local/lib/python3.5/dist-packages/django/core/handlers/base.py", line 126, in _get_response
    response = wrapped_callback(request, *callback_args, **callback_kwargs)
  File "/usr/local/lib/python3.5/dist-packages/django/views/decorators/csrf.py", line 54, in wrapped_view
    return view_func(*args, **kwargs)
  File "/usr/local/lib/python3.5/dist-packages/django/views/generic/base.py", line 69, in view
    return self.dispatch(request, *args, **kwargs)
  File "/usr/local/lib/python3.5/dist-packages/rest_framework/views.py", line 494, in dispatch
    response = self.handle_exception(exc)
  File "/usr/local/lib/python3.5/dist-packages/rest_framework/views.py", line 454, in handle_exception
    self.raise_uncaught_exception(exc)
  File "/usr/local/lib/python3.5/dist-packages/rest_framework/views.py", line 491, in dispatch
    response = handler(request, *args, **kwargs)
  File "/home/sanya/Documents/Git/rsoi_2lab/rsoi_2lab/ag_service/aggregator/views.py", line 155, in get
    return render(request, 'index.html', {'result':r.json(object_pairs_hook=OrderedDict)})
  File "/usr/local/lib/python3.5/dist-packages/django/shortcuts.py", line 36, in render
    content = loader.render_to_string(template_name, context, request, using=using)
  File "/usr/local/lib/python3.5/dist-packages/django/template/loader.py", line 62, in render_to_string
    return template.render(context, request)
  File "/usr/local/lib/python3.5/dist-packages/django/template/backends/django.py", line 61, in render
    return self.template.render(context)
  File "/usr/local/lib/python3.5/dist-packages/django/template/base.py", line 173, in render
    with context.bind_template(self):
  File "/usr/lib/python3.5/contextlib.py", line 59, in __enter__
    return next(self.gen)
  File "/usr/local/lib/python3.5/dist-packages/django/template/context.py", line 246, in bind_template
    processors = (template.engine.template_context_processors +
  File "/usr/local/lib/python3.5/dist-packages/django/utils/functional.py", line 36, in __get__
    res = instance.__dict__[self.name] = self.func(instance)
  File "/usr/local/lib/python3.5/dist-packages/django/template/engine.py", line 85, in template_context_processors
    return tuple(import_string(path) for path in context_processors)
  File "/usr/local/lib/python3.5/dist-packages/django/template/engine.py", line 85, in <genexpr>
    return tuple(import_string(path) for path in context_processors)
  File "/usr/local/lib/python3.5/dist-packages/django/utils/module_loading.py", line 17, in import_string
    module = import_module(module_path)
  File "/usr/lib/python3.5/importlib/__init__.py", line 126, in import_module
    return _bootstrap._gcd_import(name[level:], package, level)
  File "<frozen importlib._bootstrap>", line 986, in _gcd_import
  File "<frozen importlib._bootstrap>", line 969, in _find_and_load
  File "<frozen importlib._bootstrap>", line 956, in _find_and_load_unlocked
ImportError: No module named 'django.core.context_processors'
INFO:requests.packages.urllib3.connectionpool:Starting new HTTP connection (1): localhost
INFO:root:Show orders
ERROR:django.request:Internal Server Error: /user/3/orders/
Traceback (most recent call last):
  File "/usr/local/lib/python3.5/dist-packages/django/core/handlers/exception.py", line 35, in inner
    response = get_response(request)
  File "/usr/local/lib/python3.5/dist-packages/django/core/handlers/base.py", line 128, in _get_response
    response = self.process_exception_by_middleware(e, request)
  File "/usr/local/lib/python3.5/dist-packages/django/core/handlers/base.py", line 126, in _get_response
    response = wrapped_callback(request, *callback_args, **callback_kwargs)
  File "/usr/local/lib/python3.5/dist-packages/django/views/decorators/csrf.py", line 54, in wrapped_view
    return view_func(*args, **kwargs)
  File "/usr/local/lib/python3.5/dist-packages/django/views/generic/base.py", line 69, in view
    return self.dispatch(request, *args, **kwargs)
  File "/usr/local/lib/python3.5/dist-packages/rest_framework/views.py", line 494, in dispatch
    response = self.handle_exception(exc)
  File "/usr/local/lib/python3.5/dist-packages/rest_framework/views.py", line 454, in handle_exception
    self.raise_uncaught_exception(exc)
  File "/usr/local/lib/python3.5/dist-packages/rest_framework/views.py", line 491, in dispatch
    response = handler(request, *args, **kwargs)
  File "/home/sanya/Documents/Git/rsoi_2lab/rsoi_2lab/ag_service/aggregator/views.py", line 155, in get
    return render(request, 'index.html', {'result':r.json(object_pairs_hook=OrderedDict)})
  File "/usr/local/lib/python3.5/dist-packages/django/shortcuts.py", line 36, in render
    content = loader.render_to_string(template_name, context, request, using=using)
  File "/usr/local/lib/python3.5/dist-packages/django/template/loader.py", line 62, in render_to_string
    return template.render(context, request)
  File "/usr/local/lib/python3.5/dist-packages/django/template/backends/django.py", line 61, in render
    return self.template.render(context)
  File "/usr/local/lib/python3.5/dist-packages/django/template/base.py", line 175, in render
    return self._render(context)
  File "/usr/local/lib/python3.5/dist-packages/django/template/base.py", line 167, in _render
    return self.nodelist.render(context)
  File "/usr/local/lib/python3.5/dist-packages/django/template/base.py", line 943, in render
    bit = node.render_annotated(context)
  File "/usr/local/lib/python3.5/dist-packages/django/template/base.py", line 910, in render_annotated
    return self.render(context)
  File "/usr/local/lib/python3.5/dist-packages/django/template/defaulttags.py", line 211, in render
    nodelist.append(node.render_annotated(context))
  File "/usr/local/lib/python3.5/dist-packages/django/template/base.py", line 910, in render_annotated
    return self.render(context)
  File "/usr/local/lib/python3.5/dist-packages/django/template/defaulttags.py", line 447, in render
    url = reverse(view_name, args=args, kwargs=kwargs, current_app=current_app)
  File "/usr/local/lib/python3.5/dist-packages/django/urls/base.py", line 88, in reverse
    return iri_to_uri(resolver._reverse_with_prefix(view, prefix, *args, **kwargs))
  File "/usr/local/lib/python3.5/dist-packages/django/urls/resolvers.py", line 632, in _reverse_with_prefix
    raise NoReverseMatch(msg)
django.urls.exceptions.NoReverseMatch: Reverse for 'agg1' with arguments '('', 6)' not found. 1 pattern(s) tried: ['user\\/(?P<user_id>[^/]+)\\/order\\/(?P<order_id>[^/]+)\\/$']
INFO:requests.packages.urllib3.connectionpool:Starting new HTTP connection (1): localhost
INFO:root:Show orders
INFO:requests.packages.urllib3.connectionpool:Starting new HTTP connection (1): localhost
INFO:root:Show orders
INFO:requests.packages.urllib3.connectionpool:Starting new HTTP connection (1): localhost
INFO:root:Show orders
INFO:requests.packages.urllib3.connectionpool:Starting new HTTP connection (1): localhost
INFO:root:Show orders
INFO:requests.packages.urllib3.connectionpool:Starting new HTTP connection (1): localhost
INFO:root:Show orders
INFO:requests.packages.urllib3.connectionpool:Starting new HTTP connection (1): localhost
INFO:root:Show orders
INFO:requests.packages.urllib3.connectionpool:Starting new HTTP connection (1): localhost
INFO:requests.packages.urllib3.connectionpool:Starting new HTTP connection (1): localhost
INFO:requests.packages.urllib3.connectionpool:Starting new HTTP connection (1): localhost
INFO:requests.packages.urllib3.connectionpool:Starting new HTTP connection (1): localhost
INFO:requests.packages.urllib3.connectionpool:Starting new HTTP connection (1): localhost
INFO:root:Show order details
INFO:requests.packages.urllib3.connectionpool:Starting new HTTP connection (1): localhost
INFO:requests.packages.urllib3.connectionpool:Starting new HTTP connection (1): localhost
INFO:requests.packages.urllib3.connectionpool:Starting new HTTP connection (1): localhost
INFO:root:Show order details
ERROR:django.request:Internal Server Error: /user/3/order/6/
Traceback (most recent call last):
  File "/usr/local/lib/python3.5/dist-packages/django/core/handlers/exception.py", line 35, in inner
    response = get_response(request)
  File "/usr/local/lib/python3.5/dist-packages/django/core/handlers/base.py", line 128, in _get_response
    response = self.process_exception_by_middleware(e, request)
  File "/usr/local/lib/python3.5/dist-packages/django/core/handlers/base.py", line 126, in _get_response
    response = wrapped_callback(request, *callback_args, **callback_kwargs)
  File "/usr/local/lib/python3.5/dist-packages/django/views/decorators/csrf.py", line 54, in wrapped_view
    return view_func(*args, **kwargs)
  File "/usr/local/lib/python3.5/dist-packages/django/views/generic/base.py", line 69, in view
    return self.dispatch(request, *args, **kwargs)
  File "/usr/local/lib/python3.5/dist-packages/rest_framework/views.py", line 494, in dispatch
    response = self.handle_exception(exc)
  File "/usr/local/lib/python3.5/dist-packages/rest_framework/views.py", line 454, in handle_exception
    self.raise_uncaught_exception(exc)
  File "/usr/local/lib/python3.5/dist-packages/rest_framework/views.py", line 491, in dispatch
    response = handler(request, *args, **kwargs)
  File "/home/sanya/Documents/Git/rsoi_2lab/rsoi_2lab/ag_service/aggregator/views.py", line 56, in get
    return render(request, 'order_detail.html', {'result':r.json(object_pairs_hook=OrderedDict)})
  File "/usr/local/lib/python3.5/dist-packages/django/shortcuts.py", line 36, in render
    content = loader.render_to_string(template_name, context, request, using=using)
  File "/usr/local/lib/python3.5/dist-packages/django/template/loader.py", line 61, in render_to_string
    template = get_template(template_name, using=using)
  File "/usr/local/lib/python3.5/dist-packages/django/template/loader.py", line 15, in get_template
    return engine.get_template(template_name)
  File "/usr/local/lib/python3.5/dist-packages/django/template/backends/django.py", line 34, in get_template
    return Template(self.engine.get_template(template_name), self)
  File "/usr/local/lib/python3.5/dist-packages/django/template/engine.py", line 144, in get_template
    template, origin = self.find_template(template_name)
  File "/usr/local/lib/python3.5/dist-packages/django/template/engine.py", line 126, in find_template
    template = loader.get_template(name, skip=skip)
  File "/usr/local/lib/python3.5/dist-packages/django/template/loaders/base.py", line 30, in get_template
    contents, origin, origin.template_name, self.engine,
  File "/usr/local/lib/python3.5/dist-packages/django/template/base.py", line 160, in __init__
    self.nodelist = self.compile_nodelist()
  File "/usr/local/lib/python3.5/dist-packages/django/template/base.py", line 198, in compile_nodelist
    return parser.parse()
  File "/usr/local/lib/python3.5/dist-packages/django/template/base.py", line 454, in parse
    raise self.error(token, e)
  File "/usr/local/lib/python3.5/dist-packages/django/template/base.py", line 452, in parse
    filter_expression = self.compile_filter(token.contents)
  File "/usr/local/lib/python3.5/dist-packages/django/template/base.py", line 568, in compile_filter
    return FilterExpression(token, self)
  File "/usr/local/lib/python3.5/dist-packages/django/template/base.py", line 668, in __init__
    "from '%s'" % (token[upto:], token))
django.template.exceptions.TemplateSyntaxError: Could not parse the remainder: '[0].number' from 'result[0].number'
INFO:requests.packages.urllib3.connectionpool:Starting new HTTP connection (1): localhost
INFO:requests.packages.urllib3.connectionpool:Starting new HTTP connection (1): localhost
INFO:requests.packages.urllib3.connectionpool:Starting new HTTP connection (1): localhost
INFO:root:Show order details
INFO:requests.packages.urllib3.connectionpool:Starting new HTTP connection (1): localhost
INFO:requests.packages.urllib3.connectionpool:Starting new HTTP connection (1): localhost
INFO:requests.packages.urllib3.connectionpool:Starting new HTTP connection (1): localhost
INFO:root:Show order details
INFO:requests.packages.urllib3.connectionpool:Starting new HTTP connection (1): localhost
INFO:requests.packages.urllib3.connectionpool:Starting new HTTP connection (1): localhost
INFO:requests.packages.urllib3.connectionpool:Starting new HTTP connection (1): localhost
INFO:root:Show order details
INFO:requests.packages.urllib3.connectionpool:Starting new HTTP connection (1): localhost
INFO:requests.packages.urllib3.connectionpool:Starting new HTTP connection (1): localhost
INFO:requests.packages.urllib3.connectionpool:Starting new HTTP connection (1): localhost
INFO:root:Show order details
INFO:requests.packages.urllib3.connectionpool:Starting new HTTP connection (1): localhost
INFO:requests.packages.urllib3.connectionpool:Starting new HTTP connection (1): localhost
INFO:requests.packages.urllib3.connectionpool:Starting new HTTP connection (1): localhost
INFO:root:Show order details
INFO:requests.packages.urllib3.connectionpool:Starting new HTTP connection (1): localhost
INFO:requests.packages.urllib3.connectionpool:Starting new HTTP connection (1): localhost
INFO:requests.packages.urllib3.connectionpool:Starting new HTTP connection (1): localhost
INFO:root:Show order details
INFO:requests.packages.urllib3.connectionpool:Starting new HTTP connection (1): localhost
INFO:requests.packages.urllib3.connectionpool:Starting new HTTP connection (1): localhost
INFO:requests.packages.urllib3.connectionpool:Starting new HTTP connection (1): localhost
INFO:root:Show order details
INFO:requests.packages.urllib3.connectionpool:Starting new HTTP connection (1): localhost
INFO:requests.packages.urllib3.connectionpool:Starting new HTTP connection (1): localhost
INFO:requests.packages.urllib3.connectionpool:Starting new HTTP connection (1): localhost
INFO:root:Show order details
INFO:requests.packages.urllib3.connectionpool:Starting new HTTP connection (1): localhost
INFO:requests.packages.urllib3.connectionpool:Starting new HTTP connection (1): localhost
INFO:requests.packages.urllib3.connectionpool:Starting new HTTP connection (1): localhost
INFO:root:Show order details
INFO:requests.packages.urllib3.connectionpool:Starting new HTTP connection (1): localhost
INFO:requests.packages.urllib3.connectionpool:Starting new HTTP connection (1): localhost
INFO:requests.packages.urllib3.connectionpool:Starting new HTTP connection (1): localhost
INFO:root:Show order details
INFO:requests.packages.urllib3.connectionpool:Starting new HTTP connection (1): localhost
INFO:root:Show orders
INFO:requests.packages.urllib3.connectionpool:Starting new HTTP connection (1): localhost
INFO:requests.packages.urllib3.connectionpool:Starting new HTTP connection (1): localhost
INFO:root:Show order details
INFO:requests.packages.urllib3.connectionpool:Starting new HTTP connection (1): localhost
INFO:requests.packages.urllib3.connectionpool:Starting new HTTP connection (1): localhost
INFO:requests.packages.urllib3.connectionpool:Starting new HTTP connection (1): localhost
INFO:root:Show order details
INFO:requests.packages.urllib3.connectionpool:Starting new HTTP connection (1): localhost
INFO:requests.packages.urllib3.connectionpool:Starting new HTTP connection (1): localhost
INFO:requests.packages.urllib3.connectionpool:Starting new HTTP connection (1): localhost
INFO:requests.packages.urllib3.connectionpool:Starting new HTTP connection (1): localhost
INFO:root:Show order details
INFO:requests.packages.urllib3.connectionpool:Starting new HTTP connection (1): localhost
INFO:requests.packages.urllib3.connectionpool:Starting new HTTP connection (1): localhost
INFO:root:Show order details
INFO:requests.packages.urllib3.connectionpool:Starting new HTTP connection (1): localhost
INFO:requests.packages.urllib3.connectionpool:Starting new HTTP connection (1): localhost
INFO:requests.packages.urllib3.connectionpool:Starting new HTTP connection (1): localhost
INFO:root:Show order details
INFO:requests.packages.urllib3.connectionpool:Starting new HTTP connection (1): localhost
INFO:root:Show orders
INFO:requests.packages.urllib3.connectionpool:Starting new HTTP connection (1): localhost
INFO:requests.packages.urllib3.connectionpool:Starting new HTTP connection (1): localhost
INFO:requests.packages.urllib3.connectionpool:Starting new HTTP connection (1): localhost
INFO:root:Show order details
ERROR:django.request:Internal Server Error: /user/3/order/6/
Traceback (most recent call last):
  File "/usr/local/lib/python3.5/dist-packages/django/template/base.py", line 475, in parse
    compile_func = self.tags[command]
KeyError: 'else'

During handling of the above exception, another exception occurred:

Traceback (most recent call last):
  File "/usr/local/lib/python3.5/dist-packages/django/core/handlers/exception.py", line 35, in inner
    response = get_response(request)
  File "/usr/local/lib/python3.5/dist-packages/django/core/handlers/base.py", line 128, in _get_response
    response = self.process_exception_by_middleware(e, request)
  File "/usr/local/lib/python3.5/dist-packages/django/core/handlers/base.py", line 126, in _get_response
    response = wrapped_callback(request, *callback_args, **callback_kwargs)
  File "/usr/local/lib/python3.5/dist-packages/django/views/decorators/csrf.py", line 54, in wrapped_view
    return view_func(*args, **kwargs)
  File "/usr/local/lib/python3.5/dist-packages/django/views/generic/base.py", line 69, in view
    return self.dispatch(request, *args, **kwargs)
  File "/usr/local/lib/python3.5/dist-packages/rest_framework/views.py", line 494, in dispatch
    response = self.handle_exception(exc)
  File "/usr/local/lib/python3.5/dist-packages/rest_framework/views.py", line 454, in handle_exception
    self.raise_uncaught_exception(exc)
  File "/usr/local/lib/python3.5/dist-packages/rest_framework/views.py", line 491, in dispatch
    response = handler(request, *args, **kwargs)
  File "/home/sanya/Documents/Git/rsoi_2lab/rsoi_2lab/ag_service/aggregator/views.py", line 57, in get
    return render(request, 'order_detail.html', {'result':dict})
  File "/usr/local/lib/python3.5/dist-packages/django/shortcuts.py", line 36, in render
    content = loader.render_to_string(template_name, context, request, using=using)
  File "/usr/local/lib/python3.5/dist-packages/django/template/loader.py", line 61, in render_to_string
    template = get_template(template_name, using=using)
  File "/usr/local/lib/python3.5/dist-packages/django/template/loader.py", line 15, in get_template
    return engine.get_template(template_name)
  File "/usr/local/lib/python3.5/dist-packages/django/template/backends/django.py", line 34, in get_template
    return Template(self.engine.get_template(template_name), self)
  File "/usr/local/lib/python3.5/dist-packages/django/template/engine.py", line 144, in get_template
    template, origin = self.find_template(template_name)
  File "/usr/local/lib/python3.5/dist-packages/django/template/engine.py", line 126, in find_template
    template = loader.get_template(name, skip=skip)
  File "/usr/local/lib/python3.5/dist-packages/django/template/loaders/base.py", line 30, in get_template
    contents, origin, origin.template_name, self.engine,
  File "/usr/local/lib/python3.5/dist-packages/django/template/base.py", line 160, in __init__
    self.nodelist = self.compile_nodelist()
  File "/usr/local/lib/python3.5/dist-packages/django/template/base.py", line 198, in compile_nodelist
    return parser.parse()
  File "/usr/local/lib/python3.5/dist-packages/django/template/base.py", line 477, in parse
    self.invalid_block_tag(token, command, parse_until)
  File "/usr/local/lib/python3.5/dist-packages/django/template/base.py", line 539, in invalid_block_tag
    "or load this tag?" % (token.lineno, command)
django.template.exceptions.TemplateSyntaxError: Invalid block tag on line 21: 'else'. Did you forget to register or load this tag?
INFO:requests.packages.urllib3.connectionpool:Starting new HTTP connection (1): localhost
INFO:requests.packages.urllib3.connectionpool:Starting new HTTP connection (1): localhost
INFO:requests.packages.urllib3.connectionpool:Starting new HTTP connection (1): localhost
INFO:root:Show order details
INFO:requests.packages.urllib3.connectionpool:Starting new HTTP connection (1): localhost
INFO:requests.packages.urllib3.connectionpool:Starting new HTTP connection (1): localhost
INFO:root:Show order details
INFO:requests.packages.urllib3.connectionpool:Starting new HTTP connection (1): localhost
INFO:requests.packages.urllib3.connectionpool:Starting new HTTP connection (1): localhost
INFO:root:Show order details
INFO:requests.packages.urllib3.connectionpool:Starting new HTTP connection (1): localhost
INFO:requests.packages.urllib3.connectionpool:Starting new HTTP connection (1): localhost
INFO:root:Show order details
INFO:requests.packages.urllib3.connectionpool:Starting new HTTP connection (1): localhost
INFO:requests.packages.urllib3.connectionpool:Starting new HTTP connection (1): localhost
INFO:root:Show order details
INFO:requests.packages.urllib3.connectionpool:Starting new HTTP connection (1): localhost
INFO:requests.packages.urllib3.connectionpool:Starting new HTTP connection (1): localhost
INFO:root:Show order details
INFO:requests.packages.urllib3.connectionpool:Starting new HTTP connection (1): localhost
INFO:requests.packages.urllib3.connectionpool:Starting new HTTP connection (1): localhost
INFO:root:Show order details
INFO:requests.packages.urllib3.connectionpool:Starting new HTTP connection (1): localhost
INFO:requests.packages.urllib3.connectionpool:Starting new HTTP connection (1): localhost
INFO:root:Show order details
INFO:requests.packages.urllib3.connectionpool:Starting new HTTP connection (1): localhost
INFO:requests.packages.urllib3.connectionpool:Starting new HTTP connection (1): localhost
INFO:requests.packages.urllib3.connectionpool:Starting new HTTP connection (1): localhost
INFO:requests.packages.urllib3.connectionpool:Starting new HTTP connection (1): localhost
INFO:root:Show orders
INFO:requests.packages.urllib3.connectionpool:Starting new HTTP connection (1): localhost
INFO:requests.packages.urllib3.connectionpool:Starting new HTTP connection (1): localhost
INFO:requests.packages.urllib3.connectionpool:Starting new HTTP connection (1): localhost
INFO:root:Show order details
ERROR:django.request:Internal Server Error: /user/3/order/6/
Traceback (most recent call last):
  File "/usr/local/lib/python3.5/dist-packages/django/core/handlers/exception.py", line 35, in inner
    response = get_response(request)
  File "/usr/local/lib/python3.5/dist-packages/django/core/handlers/base.py", line 128, in _get_response
    response = self.process_exception_by_middleware(e, request)
  File "/usr/local/lib/python3.5/dist-packages/django/core/handlers/base.py", line 126, in _get_response
    response = wrapped_callback(request, *callback_args, **callback_kwargs)
  File "/usr/local/lib/python3.5/dist-packages/django/views/decorators/csrf.py", line 54, in wrapped_view
    return view_func(*args, **kwargs)
  File "/usr/local/lib/python3.5/dist-packages/django/views/generic/base.py", line 69, in view
    return self.dispatch(request, *args, **kwargs)
  File "/usr/local/lib/python3.5/dist-packages/rest_framework/views.py", line 494, in dispatch
    response = self.handle_exception(exc)
  File "/usr/local/lib/python3.5/dist-packages/rest_framework/views.py", line 454, in handle_exception
    self.raise_uncaught_exception(exc)
  File "/usr/local/lib/python3.5/dist-packages/rest_framework/views.py", line 491, in dispatch
    response = handler(request, *args, **kwargs)
  File "/home/sanya/Documents/Git/rsoi_2lab/rsoi_2lab/ag_service/aggregator/views.py", line 58, in get
    return render(request, 'order_detail.html', {'result':dict})
  File "/usr/local/lib/python3.5/dist-packages/django/shortcuts.py", line 36, in render
    content = loader.render_to_string(template_name, context, request, using=using)
  File "/usr/local/lib/python3.5/dist-packages/django/template/loader.py", line 62, in render_to_string
    return template.render(context, request)
  File "/usr/local/lib/python3.5/dist-packages/django/template/backends/django.py", line 61, in render
    return self.template.render(context)
  File "/usr/local/lib/python3.5/dist-packages/django/template/base.py", line 175, in render
    return self._render(context)
  File "/usr/local/lib/python3.5/dist-packages/django/template/base.py", line 167, in _render
    return self.nodelist.render(context)
  File "/usr/local/lib/python3.5/dist-packages/django/template/base.py", line 943, in render
    bit = node.render_annotated(context)
  File "/usr/local/lib/python3.5/dist-packages/django/template/base.py", line 910, in render_annotated
    return self.render(context)
  File "/usr/local/lib/python3.5/dist-packages/django/template/defaulttags.py", line 447, in render
    url = reverse(view_name, args=args, kwargs=kwargs, current_app=current_app)
  File "/usr/local/lib/python3.5/dist-packages/django/urls/base.py", line 88, in reverse
    return iri_to_uri(resolver._reverse_with_prefix(view, prefix, *args, **kwargs))
  File "/usr/local/lib/python3.5/dist-packages/django/urls/resolvers.py", line 632, in _reverse_with_prefix
    raise NoReverseMatch(msg)
django.urls.exceptions.NoReverseMatch: Reverse for 'agg1' with arguments '(3, '')' not found. 1 pattern(s) tried: ['user\\/(?P<user_id>[^/]+)\\/order\\/(?P<order_id>[^/]+)\\/$']
INFO:requests.packages.urllib3.connectionpool:Starting new HTTP connection (1): localhost
INFO:requests.packages.urllib3.connectionpool:Starting new HTTP connection (1): localhost
INFO:requests.packages.urllib3.connectionpool:Starting new HTTP connection (1): localhost
INFO:root:Show order details
INFO:requests.packages.urllib3.connectionpool:Starting new HTTP connection (1): localhost
INFO:requests.packages.urllib3.connectionpool:Starting new HTTP connection (1): localhost
INFO:requests.packages.urllib3.connectionpool:Starting new HTTP connection (1): localhost
INFO:root:Show order details
INFO:requests.packages.urllib3.connectionpool:Starting new HTTP connection (1): localhost
INFO:requests.packages.urllib3.connectionpool:Starting new HTTP connection (1): localhost
INFO:requests.packages.urllib3.connectionpool:Starting new HTTP connection (1): localhost
INFO:root:Show order details
INFO:requests.packages.urllib3.connectionpool:Starting new HTTP connection (1): localhost
INFO:requests.packages.urllib3.connectionpool:Starting new HTTP connection (1): localhost
INFO:requests.packages.urllib3.connectionpool:Starting new HTTP connection (1): localhost
INFO:requests.packages.urllib3.connectionpool:Starting new HTTP connection (1): localhost
INFO:requests.packages.urllib3.connectionpool:Starting new HTTP connection (1): localhost
INFO:requests.packages.urllib3.connectionpool:Starting new HTTP connection (1): localhost
ERROR:django.request:Internal Server Error: /user/3/order/6/
Traceback (most recent call last):
  File "/usr/local/lib/python3.5/dist-packages/django/core/handlers/exception.py", line 35, in inner
    response = get_response(request)
  File "/usr/local/lib/python3.5/dist-packages/django/core/handlers/base.py", line 128, in _get_response
    response = self.process_exception_by_middleware(e, request)
  File "/usr/local/lib/python3.5/dist-packages/django/core/handlers/base.py", line 126, in _get_response
    response = wrapped_callback(request, *callback_args, **callback_kwargs)
  File "/usr/local/lib/python3.5/dist-packages/django/views/decorators/csrf.py", line 54, in wrapped_view
    return view_func(*args, **kwargs)
  File "/usr/local/lib/python3.5/dist-packages/django/views/generic/base.py", line 69, in view
    return self.dispatch(request, *args, **kwargs)
  File "/usr/local/lib/python3.5/dist-packages/rest_framework/views.py", line 494, in dispatch
    response = self.handle_exception(exc)
  File "/usr/local/lib/python3.5/dist-packages/rest_framework/views.py", line 454, in handle_exception
    self.raise_uncaught_exception(exc)
  File "/usr/local/lib/python3.5/dist-packages/rest_framework/views.py", line 491, in dispatch
    response = handler(request, *args, **kwargs)
  File "/home/sanya/Documents/Git/rsoi_2lab/rsoi_2lab/ag_service/aggregator/views.py", line 66, in post
    print(json.loads(request.body.decode("utf-8")))
  File "/usr/lib/python3.5/json/__init__.py", line 319, in loads
    return _default_decoder.decode(s)
  File "/usr/lib/python3.5/json/decoder.py", line 339, in decode
    obj, end = self.raw_decode(s, idx=_w(s, 0).end())
  File "/usr/lib/python3.5/json/decoder.py", line 357, in raw_decode
    raise JSONDecodeError("Expecting value", s, err.value) from None
json.decoder.JSONDecodeError: Expecting value: line 1 column 1 (char 0)
INFO:requests.packages.urllib3.connectionpool:Starting new HTTP connection (1): localhost
INFO:requests.packages.urllib3.connectionpool:Starting new HTTP connection (1): localhost
INFO:requests.packages.urllib3.connectionpool:Starting new HTTP connection (1): localhost
ERROR:django.request:Internal Server Error: /user/3/order/6/
Traceback (most recent call last):
  File "/usr/local/lib/python3.5/dist-packages/rest_framework/request.py", line 410, in __getattr__
    return getattr(self._request, attr)
AttributeError: 'WSGIRequest' object has no attribute 'text'

During handling of the above exception, another exception occurred:

Traceback (most recent call last):
  File "/usr/local/lib/python3.5/dist-packages/django/core/handlers/exception.py", line 35, in inner
    response = get_response(request)
  File "/usr/local/lib/python3.5/dist-packages/django/core/handlers/base.py", line 128, in _get_response
    response = self.process_exception_by_middleware(e, request)
  File "/usr/local/lib/python3.5/dist-packages/django/core/handlers/base.py", line 126, in _get_response
    response = wrapped_callback(request, *callback_args, **callback_kwargs)
  File "/usr/local/lib/python3.5/dist-packages/django/views/decorators/csrf.py", line 54, in wrapped_view
    return view_func(*args, **kwargs)
  File "/usr/local/lib/python3.5/dist-packages/django/views/generic/base.py", line 69, in view
    return self.dispatch(request, *args, **kwargs)
  File "/usr/local/lib/python3.5/dist-packages/rest_framework/views.py", line 494, in dispatch
    response = self.handle_exception(exc)
  File "/usr/local/lib/python3.5/dist-packages/rest_framework/views.py", line 454, in handle_exception
    self.raise_uncaught_exception(exc)
  File "/usr/local/lib/python3.5/dist-packages/rest_framework/views.py", line 491, in dispatch
    response = handler(request, *args, **kwargs)
  File "/home/sanya/Documents/Git/rsoi_2lab/rsoi_2lab/ag_service/aggregator/views.py", line 67, in post
    print(request.text())
  File "/usr/local/lib/python3.5/dist-packages/rest_framework/request.py", line 412, in __getattr__
    return self.__getattribute__(attr)
AttributeError: 'Request' object has no attribute 'text'
INFO:requests.packages.urllib3.connectionpool:Starting new HTTP connection (1): localhost
INFO:requests.packages.urllib3.connectionpool:Starting new HTTP connection (1): localhost
INFO:requests.packages.urllib3.connectionpool:Starting new HTTP connection (1): localhost
INFO:requests.packages.urllib3.connectionpool:Starting new HTTP connection (1): localhost
INFO:requests.packages.urllib3.connectionpool:Starting new HTTP connection (1): localhost
INFO:requests.packages.urllib3.connectionpool:Starting new HTTP connection (1): localhost
INFO:requests.packages.urllib3.connectionpool:Starting new HTTP connection (1): localhost
INFO:requests.packages.urllib3.connectionpool:Starting new HTTP connection (1): localhost
INFO:root:Show order details
INFO:requests.packages.urllib3.connectionpool:Starting new HTTP connection (1): localhost
INFO:requests.packages.urllib3.connectionpool:Starting new HTTP connection (1): localhost
INFO:requests.packages.urllib3.connectionpool:Starting new HTTP connection (1): localhost
INFO:requests.packages.urllib3.connectionpool:Starting new HTTP connection (1): localhost
INFO:requests.packages.urllib3.connectionpool:Starting new HTTP connection (1): localhost
INFO:requests.packages.urllib3.connectionpool:Starting new HTTP connection (1): localhost
ERROR:django.request:Internal Server Error: /user/3/order/6/
Traceback (most recent call last):
  File "/usr/local/lib/python3.5/dist-packages/django/core/handlers/exception.py", line 35, in inner
    response = get_response(request)
  File "/usr/local/lib/python3.5/dist-packages/django/core/handlers/base.py", line 128, in _get_response
    response = self.process_exception_by_middleware(e, request)
  File "/usr/local/lib/python3.5/dist-packages/django/core/handlers/base.py", line 126, in _get_response
    response = wrapped_callback(request, *callback_args, **callback_kwargs)
  File "/usr/local/lib/python3.5/dist-packages/django/views/decorators/csrf.py", line 54, in wrapped_view
    return view_func(*args, **kwargs)
  File "/usr/local/lib/python3.5/dist-packages/django/views/generic/base.py", line 69, in view
    return self.dispatch(request, *args, **kwargs)
  File "/usr/local/lib/python3.5/dist-packages/rest_framework/views.py", line 494, in dispatch
    response = self.handle_exception(exc)
  File "/usr/local/lib/python3.5/dist-packages/rest_framework/views.py", line 454, in handle_exception
    self.raise_uncaught_exception(exc)
  File "/usr/local/lib/python3.5/dist-packages/rest_framework/views.py", line 491, in dispatch
    response = handler(request, *args, **kwargs)
  File "/home/sanya/Documents/Git/rsoi_2lab/rsoi_2lab/ag_service/aggregator/views.py", line 79, in post
    for id in ids:
TypeError: 'int' object is not iterable
INFO:requests.packages.urllib3.connectionpool:Starting new HTTP connection (1): localhost
INFO:requests.packages.urllib3.connectionpool:Starting new HTTP connection (1): localhost
INFO:requests.packages.urllib3.connectionpool:Starting new HTTP connection (1): localhost
INFO:root:Patch products done
INFO:requests.packages.urllib3.connectionpool:Starting new HTTP connection (1): localhost
INFO:requests.packages.urllib3.connectionpool:Starting new HTTP connection (1): localhost
INFO:root:Edit order details
INFO:requests.packages.urllib3.connectionpool:Starting new HTTP connection (1): localhost
INFO:requests.packages.urllib3.connectionpool:Starting new HTTP connection (1): localhost
INFO:requests.packages.urllib3.connectionpool:Starting new HTTP connection (1): localhost
INFO:requests.packages.urllib3.connectionpool:Starting new HTTP connection (1): localhost
INFO:root:Show order details
INFO:requests.packages.urllib3.connectionpool:Starting new HTTP connection (1): localhost
INFO:requests.packages.urllib3.connectionpool:Starting new HTTP connection (1): localhost
INFO:requests.packages.urllib3.connectionpool:Starting new HTTP connection (1): localhost
INFO:root:Patch products done
INFO:requests.packages.urllib3.connectionpool:Starting new HTTP connection (1): localhost
INFO:requests.packages.urllib3.connectionpool:Starting new HTTP connection (1): localhost
INFO:root:Edit order details
INFO:requests.packages.urllib3.connectionpool:Starting new HTTP connection (1): localhost
INFO:requests.packages.urllib3.connectionpool:Starting new HTTP connection (1): localhost
INFO:requests.packages.urllib3.connectionpool:Starting new HTTP connection (1): localhost
INFO:requests.packages.urllib3.connectionpool:Starting new HTTP connection (1): localhost
INFO:root:Show order details
INFO:requests.packages.urllib3.connectionpool:Starting new HTTP connection (1): localhost
INFO:requests.packages.urllib3.connectionpool:Starting new HTTP connection (1): localhost
INFO:requests.packages.urllib3.connectionpool:Starting new HTTP connection (1): localhost
INFO:root:Patch products done
INFO:requests.packages.urllib3.connectionpool:Starting new HTTP connection (1): localhost
INFO:requests.packages.urllib3.connectionpool:Starting new HTTP connection (1): localhost
INFO:root:Edit order details
INFO:requests.packages.urllib3.connectionpool:Starting new HTTP connection (1): localhost
INFO:requests.packages.urllib3.connectionpool:Starting new HTTP connection (1): localhost
INFO:requests.packages.urllib3.connectionpool:Starting new HTTP connection (1): localhost
INFO:requests.packages.urllib3.connectionpool:Starting new HTTP connection (1): localhost
INFO:root:Show order details
INFO:requests.packages.urllib3.connectionpool:Starting new HTTP connection (1): localhost
INFO:requests.packages.urllib3.connectionpool:Starting new HTTP connection (1): localhost
INFO:requests.packages.urllib3.connectionpool:Starting new HTTP connection (1): localhost
INFO:requests.packages.urllib3.connectionpool:Starting new HTTP connection (1): localhost
INFO:root:Show order details
INFO:requests.packages.urllib3.connectionpool:Starting new HTTP connection (1): localhost
INFO:requests.packages.urllib3.connectionpool:Starting new HTTP connection (1): localhost
INFO:requests.packages.urllib3.connectionpool:Starting new HTTP connection (1): localhost
INFO:requests.packages.urllib3.connectionpool:Starting new HTTP connection (1): localhost
INFO:root:Show order details
WARNING:django.request:Not Found: /user/3/order/
INFO:requests.packages.urllib3.connectionpool:Starting new HTTP connection (1): localhost
INFO:root:Show orders
INFO:requests.packages.urllib3.connectionpool:Starting new HTTP connection (1): localhost
INFO:requests.packages.urllib3.connectionpool:Starting new HTTP connection (1): localhost
INFO:requests.packages.urllib3.connectionpool:Starting new HTTP connection (1): localhost
INFO:requests.packages.urllib3.connectionpool:Starting new HTTP connection (1): localhost
INFO:root:Show order details
INFO:requests.packages.urllib3.connectionpool:Starting new HTTP connection (1): localhost
INFO:requests.packages.urllib3.connectionpool:Starting new HTTP connection (1): localhost
INFO:requests.packages.urllib3.connectionpool:Starting new HTTP connection (1): localhost
INFO:root:Patch products done
INFO:requests.packages.urllib3.connectionpool:Starting new HTTP connection (1): localhost
INFO:requests.packages.urllib3.connectionpool:Starting new HTTP connection (1): localhost
INFO:root:Edit order details
ERROR:django.request:Internal Server Error: /user/3/order/6/
Traceback (most recent call last):
  File "/usr/local/lib/python3.5/dist-packages/django/core/handlers/exception.py", line 35, in inner
    response = get_response(request)
  File "/usr/local/lib/python3.5/dist-packages/django/core/handlers/base.py", line 128, in _get_response
    response = self.process_exception_by_middleware(e, request)
  File "/usr/local/lib/python3.5/dist-packages/django/core/handlers/base.py", line 126, in _get_response
    response = wrapped_callback(request, *callback_args, **callback_kwargs)
  File "/usr/local/lib/python3.5/dist-packages/django/views/decorators/csrf.py", line 54, in wrapped_view
    return view_func(*args, **kwargs)
  File "/usr/local/lib/python3.5/dist-packages/django/views/generic/base.py", line 69, in view
    return self.dispatch(request, *args, **kwargs)
  File "/usr/local/lib/python3.5/dist-packages/rest_framework/views.py", line 494, in dispatch
    response = self.handle_exception(exc)
  File "/usr/local/lib/python3.5/dist-packages/rest_framework/views.py", line 454, in handle_exception
    self.raise_uncaught_exception(exc)
  File "/usr/local/lib/python3.5/dist-packages/rest_framework/views.py", line 491, in dispatch
    response = handler(request, *args, **kwargs)
  File "/home/sanya/Documents/Git/rsoi_2lab/rsoi_2lab/ag_service/aggregator/views.py", line 119, in post
    return render(request, 'orders.html', {'result':r.json()})
  File "/usr/local/lib/python3.5/dist-packages/django/shortcuts.py", line 36, in render
    content = loader.render_to_string(template_name, context, request, using=using)
  File "/usr/local/lib/python3.5/dist-packages/django/template/loader.py", line 62, in render_to_string
    return template.render(context, request)
  File "/usr/local/lib/python3.5/dist-packages/django/template/backends/django.py", line 61, in render
    return self.template.render(context)
  File "/usr/local/lib/python3.5/dist-packages/django/template/base.py", line 175, in render
    return self._render(context)
  File "/usr/local/lib/python3.5/dist-packages/django/template/base.py", line 167, in _render
    return self.nodelist.render(context)
  File "/usr/local/lib/python3.5/dist-packages/django/template/base.py", line 943, in render
    bit = node.render_annotated(context)
  File "/usr/local/lib/python3.5/dist-packages/django/template/base.py", line 910, in render_annotated
    return self.render(context)
  File "/usr/local/lib/python3.5/dist-packages/django/template/defaulttags.py", line 211, in render
    nodelist.append(node.render_annotated(context))
  File "/usr/local/lib/python3.5/dist-packages/django/template/base.py", line 910, in render_annotated
    return self.render(context)
  File "/usr/local/lib/python3.5/dist-packages/django/template/defaulttags.py", line 447, in render
    url = reverse(view_name, args=args, kwargs=kwargs, current_app=current_app)
  File "/usr/local/lib/python3.5/dist-packages/django/urls/base.py", line 88, in reverse
    return iri_to_uri(resolver._reverse_with_prefix(view, prefix, *args, **kwargs))
  File "/usr/local/lib/python3.5/dist-packages/django/urls/resolvers.py", line 632, in _reverse_with_prefix
    raise NoReverseMatch(msg)
django.urls.exceptions.NoReverseMatch: Reverse for 'agg1' with arguments '('', '')' not found. 1 pattern(s) tried: ['user\\/(?P<user_id>[^/]+)\\/order\\/(?P<order_id>[^/]+)\\/$']
INFO:requests.packages.urllib3.connectionpool:Starting new HTTP connection (1): localhost
INFO:root:Show orders
INFO:requests.packages.urllib3.connectionpool:Starting new HTTP connection (1): localhost
INFO:requests.packages.urllib3.connectionpool:Starting new HTTP connection (1): localhost
INFO:root:Show order details
INFO:requests.packages.urllib3.connectionpool:Starting new HTTP connection (1): localhost
INFO:requests.packages.urllib3.connectionpool:Starting new HTTP connection (1): localhost
INFO:requests.packages.urllib3.connectionpool:Starting new HTTP connection (1): localhost
INFO:root:Patch products done
INFO:requests.packages.urllib3.connectionpool:Starting new HTTP connection (1): localhost
INFO:requests.packages.urllib3.connectionpool:Starting new HTTP connection (1): localhost
INFO:root:Edit order details
ERROR:django.request:Internal Server Error: /user/3/order/5/
Traceback (most recent call last):
  File "/usr/local/lib/python3.5/dist-packages/django/core/handlers/exception.py", line 35, in inner
    response = get_response(request)
  File "/usr/local/lib/python3.5/dist-packages/django/core/handlers/base.py", line 128, in _get_response
    response = self.process_exception_by_middleware(e, request)
  File "/usr/local/lib/python3.5/dist-packages/django/core/handlers/base.py", line 126, in _get_response
    response = wrapped_callback(request, *callback_args, **callback_kwargs)
  File "/usr/local/lib/python3.5/dist-packages/django/views/decorators/csrf.py", line 54, in wrapped_view
    return view_func(*args, **kwargs)
  File "/usr/local/lib/python3.5/dist-packages/django/views/generic/base.py", line 69, in view
    return self.dispatch(request, *args, **kwargs)
  File "/usr/local/lib/python3.5/dist-packages/rest_framework/views.py", line 494, in dispatch
    response = self.handle_exception(exc)
  File "/usr/local/lib/python3.5/dist-packages/rest_framework/views.py", line 454, in handle_exception
    self.raise_uncaught_exception(exc)
  File "/usr/local/lib/python3.5/dist-packages/rest_framework/views.py", line 491, in dispatch
    response = handler(request, *args, **kwargs)
  File "/home/sanya/Documents/Git/rsoi_2lab/rsoi_2lab/ag_service/aggregator/views.py", line 119, in post
    return render(request, 'succes.html', {'result':r.json()})
  File "/usr/local/lib/python3.5/dist-packages/django/shortcuts.py", line 36, in render
    content = loader.render_to_string(template_name, context, request, using=using)
  File "/usr/local/lib/python3.5/dist-packages/django/template/loader.py", line 61, in render_to_string
    template = get_template(template_name, using=using)
  File "/usr/local/lib/python3.5/dist-packages/django/template/loader.py", line 19, in get_template
    raise TemplateDoesNotExist(template_name, chain=chain)
django.template.exceptions.TemplateDoesNotExist: succes.html
INFO:requests.packages.urllib3.connectionpool:Starting new HTTP connection (1): localhost
INFO:requests.packages.urllib3.connectionpool:Starting new HTTP connection (1): localhost
INFO:requests.packages.urllib3.connectionpool:Starting new HTTP connection (1): localhost
INFO:root:Patch products done
INFO:requests.packages.urllib3.connectionpool:Starting new HTTP connection (1): localhost
INFO:requests.packages.urllib3.connectionpool:Starting new HTTP connection (1): localhost
INFO:root:Edit order details
ERROR:django.request:Internal Server Error: /user/3/order/5/
Traceback (most recent call last):
  File "/usr/local/lib/python3.5/dist-packages/django/core/handlers/exception.py", line 35, in inner
    response = get_response(request)
  File "/usr/local/lib/python3.5/dist-packages/django/core/handlers/base.py", line 128, in _get_response
    response = self.process_exception_by_middleware(e, request)
  File "/usr/local/lib/python3.5/dist-packages/django/core/handlers/base.py", line 126, in _get_response
    response = wrapped_callback(request, *callback_args, **callback_kwargs)
  File "/usr/local/lib/python3.5/dist-packages/django/views/decorators/csrf.py", line 54, in wrapped_view
    return view_func(*args, **kwargs)
  File "/usr/local/lib/python3.5/dist-packages/django/views/generic/base.py", line 69, in view
    return self.dispatch(request, *args, **kwargs)
  File "/usr/local/lib/python3.5/dist-packages/rest_framework/views.py", line 494, in dispatch
    response = self.handle_exception(exc)
  File "/usr/local/lib/python3.5/dist-packages/rest_framework/views.py", line 454, in handle_exception
    self.raise_uncaught_exception(exc)
  File "/usr/local/lib/python3.5/dist-packages/rest_framework/views.py", line 491, in dispatch
    response = handler(request, *args, **kwargs)
  File "/home/sanya/Documents/Git/rsoi_2lab/rsoi_2lab/ag_service/aggregator/views.py", line 119, in post
    return render(request, 'succes.html', {'result':r.json()})
  File "/usr/local/lib/python3.5/dist-packages/django/shortcuts.py", line 36, in render
    content = loader.render_to_string(template_name, context, request, using=using)
  File "/usr/local/lib/python3.5/dist-packages/django/template/loader.py", line 61, in render_to_string
    template = get_template(template_name, using=using)
  File "/usr/local/lib/python3.5/dist-packages/django/template/loader.py", line 19, in get_template
    raise TemplateDoesNotExist(template_name, chain=chain)
django.template.exceptions.TemplateDoesNotExist: succes.html
INFO:requests.packages.urllib3.connectionpool:Starting new HTTP connection (1): localhost
INFO:requests.packages.urllib3.connectionpool:Starting new HTTP connection (1): localhost
INFO:requests.packages.urllib3.connectionpool:Starting new HTTP connection (1): localhost
INFO:root:Patch products done
INFO:requests.packages.urllib3.connectionpool:Starting new HTTP connection (1): localhost
INFO:requests.packages.urllib3.connectionpool:Starting new HTTP connection (1): localhost
INFO:root:Edit order details
ERROR:django.request:Internal Server Error: /user/3/order/5/
Traceback (most recent call last):
  File "/usr/local/lib/python3.5/dist-packages/django/core/handlers/exception.py", line 35, in inner
    response = get_response(request)
  File "/usr/local/lib/python3.5/dist-packages/django/core/handlers/base.py", line 128, in _get_response
    response = self.process_exception_by_middleware(e, request)
  File "/usr/local/lib/python3.5/dist-packages/django/core/handlers/base.py", line 126, in _get_response
    response = wrapped_callback(request, *callback_args, **callback_kwargs)
  File "/usr/local/lib/python3.5/dist-packages/django/views/decorators/csrf.py", line 54, in wrapped_view
    return view_func(*args, **kwargs)
  File "/usr/local/lib/python3.5/dist-packages/django/views/generic/base.py", line 69, in view
    return self.dispatch(request, *args, **kwargs)
  File "/usr/local/lib/python3.5/dist-packages/rest_framework/views.py", line 494, in dispatch
    response = self.handle_exception(exc)
  File "/usr/local/lib/python3.5/dist-packages/rest_framework/views.py", line 454, in handle_exception
    self.raise_uncaught_exception(exc)
  File "/usr/local/lib/python3.5/dist-packages/rest_framework/views.py", line 491, in dispatch
    response = handler(request, *args, **kwargs)
  File "/home/sanya/Documents/Git/rsoi_2lab/rsoi_2lab/ag_service/aggregator/views.py", line 119, in post
    return render(request, 'succes.html', {'result':r.json()})
  File "/usr/local/lib/python3.5/dist-packages/django/shortcuts.py", line 36, in render
    content = loader.render_to_string(template_name, context, request, using=using)
  File "/usr/local/lib/python3.5/dist-packages/django/template/loader.py", line 61, in render_to_string
    template = get_template(template_name, using=using)
  File "/usr/local/lib/python3.5/dist-packages/django/template/loader.py", line 19, in get_template
    raise TemplateDoesNotExist(template_name, chain=chain)
django.template.exceptions.TemplateDoesNotExist: succes.html
INFO:requests.packages.urllib3.connectionpool:Starting new HTTP connection (1): localhost
INFO:requests.packages.urllib3.connectionpool:Starting new HTTP connection (1): localhost
INFO:requests.packages.urllib3.connectionpool:Starting new HTTP connection (1): localhost
INFO:root:Patch products done
INFO:requests.packages.urllib3.connectionpool:Starting new HTTP connection (1): localhost
INFO:requests.packages.urllib3.connectionpool:Starting new HTTP connection (1): localhost
INFO:root:Edit order details
INFO:requests.packages.urllib3.connectionpool:Starting new HTTP connection (1): localhost
INFO:root:Show orders
INFO:requests.packages.urllib3.connectionpool:Starting new HTTP connection (1): localhost
INFO:requests.packages.urllib3.connectionpool:Starting new HTTP connection (1): localhost
INFO:requests.packages.urllib3.connectionpool:Starting new HTTP connection (1): localhost
INFO:requests.packages.urllib3.connectionpool:Starting new HTTP connection (1): localhost
INFO:root:Show order details
INFO:requests.packages.urllib3.connectionpool:Starting new HTTP connection (1): localhost
INFO:requests.packages.urllib3.connectionpool:Starting new HTTP connection (1): localhost
INFO:requests.packages.urllib3.connectionpool:Starting new HTTP connection (1): localhost
INFO:requests.packages.urllib3.connectionpool:Starting new HTTP connection (1): localhost
INFO:root:Show order details
ERROR:django.request:Internal Server Error: /user/3/order/6/
Traceback (most recent call last):
  File "/usr/local/lib/python3.5/dist-packages/django/core/handlers/exception.py", line 35, in inner
    response = get_response(request)
  File "/usr/local/lib/python3.5/dist-packages/django/core/handlers/base.py", line 128, in _get_response
    response = self.process_exception_by_middleware(e, request)
  File "/usr/local/lib/python3.5/dist-packages/django/core/handlers/base.py", line 126, in _get_response
    response = wrapped_callback(request, *callback_args, **callback_kwargs)
  File "/usr/local/lib/python3.5/dist-packages/django/views/decorators/csrf.py", line 54, in wrapped_view
    return view_func(*args, **kwargs)
  File "/usr/local/lib/python3.5/dist-packages/django/views/generic/base.py", line 69, in view
    return self.dispatch(request, *args, **kwargs)
  File "/usr/local/lib/python3.5/dist-packages/rest_framework/views.py", line 494, in dispatch
    response = self.handle_exception(exc)
  File "/usr/local/lib/python3.5/dist-packages/rest_framework/views.py", line 454, in handle_exception
    self.raise_uncaught_exception(exc)
  File "/usr/local/lib/python3.5/dist-packages/rest_framework/views.py", line 491, in dispatch
    response = handler(request, *args, **kwargs)
  File "/home/sanya/Documents/Git/rsoi_2lab/rsoi_2lab/ag_service/aggregator/views.py", line 58, in get
    return render(request, 'order_detail.html', {'result':dict})
  File "/usr/local/lib/python3.5/dist-packages/django/shortcuts.py", line 36, in render
    content = loader.render_to_string(template_name, context, request, using=using)
  File "/usr/local/lib/python3.5/dist-packages/django/template/loader.py", line 61, in render_to_string
    template = get_template(template_name, using=using)
  File "/usr/local/lib/python3.5/dist-packages/django/template/loader.py", line 15, in get_template
    return engine.get_template(template_name)
  File "/usr/local/lib/python3.5/dist-packages/django/template/backends/django.py", line 34, in get_template
    return Template(self.engine.get_template(template_name), self)
  File "/usr/local/lib/python3.5/dist-packages/django/template/engine.py", line 144, in get_template
    template, origin = self.find_template(template_name)
  File "/usr/local/lib/python3.5/dist-packages/django/template/engine.py", line 126, in find_template
    template = loader.get_template(name, skip=skip)
  File "/usr/local/lib/python3.5/dist-packages/django/template/loaders/base.py", line 30, in get_template
    contents, origin, origin.template_name, self.engine,
  File "/usr/local/lib/python3.5/dist-packages/django/template/base.py", line 160, in __init__
    self.nodelist = self.compile_nodelist()
  File "/usr/local/lib/python3.5/dist-packages/django/template/base.py", line 198, in compile_nodelist
    return parser.parse()
  File "/usr/local/lib/python3.5/dist-packages/django/template/base.py", line 483, in parse
    raise self.error(token, e)
  File "/usr/local/lib/python3.5/dist-packages/django/template/base.py", line 481, in parse
    compiled_result = compile_func(self, token)
  File "/usr/local/lib/python3.5/dist-packages/django/template/defaulttags.py", line 956, in do_if
    nodelist = parser.parse(('elif', 'else', 'endif'))
  File "/usr/local/lib/python3.5/dist-packages/django/template/base.py", line 488, in parse
    self.unclosed_block_tag(parse_until)
  File "/usr/local/lib/python3.5/dist-packages/django/template/base.py", line 549, in unclosed_block_tag
    raise self.error(token, msg)
django.template.exceptions.TemplateSyntaxError: Unclosed tag on line 42: 'if'. Looking for one of: elif, else, endif.
INFO:requests.packages.urllib3.connectionpool:Starting new HTTP connection (1): localhost
INFO:requests.packages.urllib3.connectionpool:Starting new HTTP connection (1): localhost
INFO:requests.packages.urllib3.connectionpool:Starting new HTTP connection (1): localhost
INFO:requests.packages.urllib3.connectionpool:Starting new HTTP connection (1): localhost
INFO:root:Show order details
INFO:requests.packages.urllib3.connectionpool:Starting new HTTP connection (1): localhost
ERROR:django.request:Internal Server Error: /user/3/order/6/
Traceback (most recent call last):
  File "/usr/local/lib/python3.5/dist-packages/django/core/handlers/exception.py", line 35, in inner
    response = get_response(request)
  File "/usr/local/lib/python3.5/dist-packages/django/core/handlers/base.py", line 128, in _get_response
    response = self.process_exception_by_middleware(e, request)
  File "/usr/local/lib/python3.5/dist-packages/django/core/handlers/base.py", line 126, in _get_response
    response = wrapped_callback(request, *callback_args, **callback_kwargs)
  File "/usr/local/lib/python3.5/dist-packages/django/views/decorators/csrf.py", line 54, in wrapped_view
    return view_func(*args, **kwargs)
  File "/usr/local/lib/python3.5/dist-packages/django/views/generic/base.py", line 69, in view
    return self.dispatch(request, *args, **kwargs)
  File "/usr/local/lib/python3.5/dist-packages/rest_framework/views.py", line 494, in dispatch
    response = self.handle_exception(exc)
  File "/usr/local/lib/python3.5/dist-packages/rest_framework/views.py", line 454, in handle_exception
    self.raise_uncaught_exception(exc)
  File "/usr/local/lib/python3.5/dist-packages/rest_framework/views.py", line 491, in dispatch
    response = handler(request, *args, **kwargs)
  File "/home/sanya/Documents/Git/rsoi_2lab/rsoi_2lab/ag_service/aggregator/views.py", line 73, in post
    ids = [int(pre_data)]
ValueError: invalid literal for int() with base 10: 'efef'
INFO:requests.packages.urllib3.connectionpool:Starting new HTTP connection (1): localhost
INFO:requests.packages.urllib3.connectionpool:Starting new HTTP connection (1): localhost
ERROR:django.request:Internal Server Error: /user/3/order/6/
Traceback (most recent call last):
  File "/home/sanya/Documents/Git/rsoi_2lab/rsoi_2lab/ag_service/aggregator/views.py", line 77, in post
    r.raise_for_status()
  File "/usr/lib/python3/dist-packages/requests/models.py", line 840, in raise_for_status
    raise HTTPError(http_error_msg, response=self)
requests.exceptions.HTTPError: 500 Server Error: Internal Server Error for url: http://localhost:8001/products/efef/

During handling of the above exception, another exception occurred:

Traceback (most recent call last):
  File "/usr/local/lib/python3.5/dist-packages/django/core/handlers/exception.py", line 35, in inner
    response = get_response(request)
  File "/usr/local/lib/python3.5/dist-packages/django/core/handlers/base.py", line 128, in _get_response
    response = self.process_exception_by_middleware(e, request)
  File "/usr/local/lib/python3.5/dist-packages/django/core/handlers/base.py", line 126, in _get_response
    response = wrapped_callback(request, *callback_args, **callback_kwargs)
  File "/usr/local/lib/python3.5/dist-packages/django/views/decorators/csrf.py", line 54, in wrapped_view
    return view_func(*args, **kwargs)
  File "/usr/local/lib/python3.5/dist-packages/django/views/generic/base.py", line 69, in view
    return self.dispatch(request, *args, **kwargs)
  File "/usr/local/lib/python3.5/dist-packages/rest_framework/views.py", line 494, in dispatch
    response = self.handle_exception(exc)
  File "/usr/local/lib/python3.5/dist-packages/rest_framework/views.py", line 454, in handle_exception
    self.raise_uncaught_exception(exc)
  File "/usr/local/lib/python3.5/dist-packages/rest_framework/views.py", line 491, in dispatch
    response = handler(request, *args, **kwargs)
  File "/home/sanya/Documents/Git/rsoi_2lab/rsoi_2lab/ag_service/aggregator/views.py", line 112, in post
    return HttpResponse(loader.render_to_string( str(status_code)+'.html'), status=status_code)
  File "/usr/local/lib/python3.5/dist-packages/django/template/loader.py", line 61, in render_to_string
    template = get_template(template_name, using=using)
  File "/usr/local/lib/python3.5/dist-packages/django/template/loader.py", line 19, in get_template
    raise TemplateDoesNotExist(template_name, chain=chain)
django.template.exceptions.TemplateDoesNotExist: 500.html
INFO:requests.packages.urllib3.connectionpool:Starting new HTTP connection (1): localhost
INFO:root:Show orders
INFO:requests.packages.urllib3.connectionpool:Starting new HTTP connection (1): localhost
INFO:requests.packages.urllib3.connectionpool:Starting new HTTP connection (1): localhost
INFO:requests.packages.urllib3.connectionpool:Starting new HTTP connection (1): localhost
INFO:requests.packages.urllib3.connectionpool:Starting new HTTP connection (1): localhost
INFO:root:Show order details
INFO:requests.packages.urllib3.connectionpool:Starting new HTTP connection (1): localhost
INFO:requests.packages.urllib3.connectionpool:Starting new HTTP connection (1): localhost
INFO:requests.packages.urllib3.connectionpool:Starting new HTTP connection (1): localhost
INFO:requests.packages.urllib3.connectionpool:Starting new HTTP connection (1): localhost
INFO:root:Show order details
INFO:requests.packages.urllib3.connectionpool:Starting new HTTP connection (1): localhost
INFO:requests.packages.urllib3.connectionpool:Starting new HTTP connection (1): localhost
WARNING:django.request:Not Found: /user/3/order/6/
INFO:requests.packages.urllib3.connectionpool:Starting new HTTP connection (1): localhost
INFO:root:Show orders
INFO:requests.packages.urllib3.connectionpool:Starting new HTTP connection (1): localhost
INFO:requests.packages.urllib3.connectionpool:Starting new HTTP connection (1): localhost
INFO:requests.packages.urllib3.connectionpool:Starting new HTTP connection (1): localhost
INFO:requests.packages.urllib3.connectionpool:Starting new HTTP connection (1): localhost
INFO:root:Show order details
INFO:requests.packages.urllib3.connectionpool:Starting new HTTP connection (1): localhost
INFO:requests.packages.urllib3.connectionpool:Starting new HTTP connection (1): localhost
WARNING:django.request:Not Found: /user/3/order/6/
INFO:requests.packages.urllib3.connectionpool:Starting new HTTP connection (1): localhost
INFO:requests.packages.urllib3.connectionpool:Starting new HTTP connection (1): localhost
INFO:requests.packages.urllib3.connectionpool:Starting new HTTP connection (1): localhost
INFO:root:Patch products done
INFO:requests.packages.urllib3.connectionpool:Starting new HTTP connection (1): localhost
INFO:requests.packages.urllib3.connectionpool:Starting new HTTP connection (1): localhost
INFO:root:Edit order details
INFO:requests.packages.urllib3.connectionpool:Starting new HTTP connection (1): localhost
INFO:root:Show orders
INFO:requests.packages.urllib3.connectionpool:Starting new HTTP connection (1): localhost
INFO:requests.packages.urllib3.connectionpool:Starting new HTTP connection (1): localhost
INFO:requests.packages.urllib3.connectionpool:Starting new HTTP connection (1): localhost
INFO:root:Show order details
INFO:requests.packages.urllib3.connectionpool:Starting new HTTP connection (1): localhost
INFO:requests.packages.urllib3.connectionpool:Starting new HTTP connection (1): localhost
INFO:requests.packages.urllib3.connectionpool:Starting new HTTP connection (1): localhost
INFO:requests.packages.urllib3.connectionpool:Starting new HTTP connection (1): localhost
INFO:root:Show order details
INFO:requests.packages.urllib3.connectionpool:Starting new HTTP connection (1): localhost
INFO:root:Show orders
INFO:requests.packages.urllib3.connectionpool:Starting new HTTP connection (1): localhost
INFO:requests.packages.urllib3.connectionpool:Starting new HTTP connection (1): localhost
INFO:root:Show order details
INFO:requests.packages.urllib3.connectionpool:Starting new HTTP connection (1): localhost
INFO:requests.packages.urllib3.connectionpool:Starting new HTTP connection (1): localhost
INFO:root:Show order details
INFO:requests.packages.urllib3.connectionpool:Starting new HTTP connection (1): localhost
INFO:requests.packages.urllib3.connectionpool:Starting new HTTP connection (1): localhost
INFO:requests.packages.urllib3.connectionpool:Starting new HTTP connection (1): localhost
INFO:root:Show orders
INFO:requests.packages.urllib3.connectionpool:Starting new HTTP connection (1): localhost
INFO:requests.packages.urllib3.connectionpool:Starting new HTTP connection (1): localhost
INFO:root:Show order details
INFO:requests.packages.urllib3.connectionpool:Starting new HTTP connection (1): localhost
INFO:requests.packages.urllib3.connectionpool:Starting new HTTP connection (1): localhost
INFO:root:Show order details
INFO:requests.packages.urllib3.connectionpool:Starting new HTTP connection (1): localhost
INFO:requests.packages.urllib3.connectionpool:Starting new HTTP connection (1): localhost
INFO:root:Show order details
INFO:requests.packages.urllib3.connectionpool:Starting new HTTP connection (1): localhost
INFO:requests.packages.urllib3.connectionpool:Starting new HTTP connection (1): localhost
INFO:root:Show order details
INFO:requests.packages.urllib3.connectionpool:Starting new HTTP connection (1): localhost
INFO:requests.packages.urllib3.connectionpool:Starting new HTTP connection (1): localhost
INFO:requests.packages.urllib3.connectionpool:Starting new HTTP connection (1): localhost
INFO:requests.packages.urllib3.connectionpool:Starting new HTTP connection (1): localhost
INFO:root:Show orders
INFO:requests.packages.urllib3.connectionpool:Starting new HTTP connection (1): localhost
INFO:requests.packages.urllib3.connectionpool:Starting new HTTP connection (1): localhost
INFO:root:Show order details
INFO:requests.packages.urllib3.connectionpool:Starting new HTTP connection (1): localhost
INFO:requests.packages.urllib3.connectionpool:Starting new HTTP connection (1): localhost
INFO:root:Show order details
INFO:requests.packages.urllib3.connectionpool:Starting new HTTP connection (1): localhost
INFO:requests.packages.urllib3.connectionpool:Starting new HTTP connection (1): localhost
INFO:root:Show order details
INFO:requests.packages.urllib3.connectionpool:Starting new HTTP connection (1): localhost
INFO:requests.packages.urllib3.connectionpool:Starting new HTTP connection (1): localhost
INFO:root:Show order details
INFO:requests.packages.urllib3.connectionpool:Starting new HTTP connection (1): localhost
INFO:requests.packages.urllib3.connectionpool:Starting new HTTP connection (1): localhost
INFO:root:Show order details
INFO:requests.packages.urllib3.connectionpool:Starting new HTTP connection (1): localhost
INFO:requests.packages.urllib3.connectionpool:Starting new HTTP connection (1): localhost
INFO:root:Show order details
INFO:requests.packages.urllib3.connectionpool:Starting new HTTP connection (1): localhost
INFO:requests.packages.urllib3.connectionpool:Starting new HTTP connection (1): localhost
INFO:root:Show order details
INFO:requests.packages.urllib3.connectionpool:Starting new HTTP connection (1): localhost
INFO:requests.packages.urllib3.connectionpool:Starting new HTTP connection (1): localhost
INFO:root:Show order details
INFO:requests.packages.urllib3.connectionpool:Starting new HTTP connection (1): localhost
INFO:root:Show orders
INFO:requests.packages.urllib3.connectionpool:Starting new HTTP connection (1): localhost
INFO:requests.packages.urllib3.connectionpool:Starting new HTTP connection (1): localhost
INFO:requests.packages.urllib3.connectionpool:Starting new HTTP connection (1): localhost
INFO:requests.packages.urllib3.connectionpool:Starting new HTTP connection (1): localhost
INFO:requests.packages.urllib3.connectionpool:Starting new HTTP connection (1): localhost
INFO:requests.packages.urllib3.connectionpool:Starting new HTTP connection (1): localhost
INFO:root:Show order details
INFO:requests.packages.urllib3.connectionpool:Starting new HTTP connection (1): localhost
INFO:requests.packages.urllib3.connectionpool:Starting new HTTP connection (1): localhost
INFO:requests.packages.urllib3.connectionpool:Starting new HTTP connection (1): localhost
INFO:requests.packages.urllib3.connectionpool:Starting new HTTP connection (1): localhost
INFO:requests.packages.urllib3.connectionpool:Starting new HTTP connection (1): localhost
INFO:requests.packages.urllib3.connectionpool:Starting new HTTP connection (1): localhost
INFO:requests.packages.urllib3.connectionpool:Starting new HTTP connection (1): localhost
INFO:requests.packages.urllib3.connectionpool:Starting new HTTP connection (1): localhost
INFO:requests.packages.urllib3.connectionpool:Starting new HTTP connection (1): localhost
INFO:requests.packages.urllib3.connectionpool:Starting new HTTP connection (1): localhost
INFO:root:Show order details
