INFO:requests.packages.urllib3.connectionpool:Starting new HTTP connection (1): localhost
INFO:requests.packages.urllib3.connectionpool:Starting new HTTP connection (1): localhost
INFO:requests.packages.urllib3.connectionpool:Starting new HTTP connection (1): localhost
INFO:requests.packages.urllib3.connectionpool:Starting new HTTP connection (1): localhost
INFO:requests.packages.urllib3.connectionpool:Starting new HTTP connection (1): localhost
INFO:requests.packages.urllib3.connectionpool:Starting new HTTP connection (1): localhost
INFO:requests.packages.urllib3.connectionpool:Starting new HTTP connection (1): localhost
INFO:root:Show order details
INFO:requests.packages.urllib3.connectionpool:Starting new HTTP connection (1): localhost
INFO:requests.packages.urllib3.connectionpool:Starting new HTTP connection (1): localhost
INFO:requests.packages.urllib3.connectionpool:Starting new HTTP connection (1): localhost
INFO:root:Patch products done
INFO:requests.packages.urllib3.connectionpool:Starting new HTTP connection (1): localhost
INFO:requests.packages.urllib3.connectionpool:Starting new HTTP connection (1): localhost
INFO:root:Edit order details
ERROR:django.request:Internal Server Error: /user/3/order/6/
Traceback (most recent call last):
  File "/usr/local/lib/python3.5/dist-packages/django/core/handlers/exception.py", line 35, in inner
    response = get_response(request)
  File "/usr/local/lib/python3.5/dist-packages/django/core/handlers/base.py", line 128, in _get_response
    response = self.process_exception_by_middleware(e, request)
  File "/usr/local/lib/python3.5/dist-packages/django/core/handlers/base.py", line 126, in _get_response
    response = wrapped_callback(request, *callback_args, **callback_kwargs)
  File "/usr/local/lib/python3.5/dist-packages/django/views/decorators/csrf.py", line 54, in wrapped_view
    return view_func(*args, **kwargs)
  File "/usr/local/lib/python3.5/dist-packages/django/views/generic/base.py", line 69, in view
    return self.dispatch(request, *args, **kwargs)
  File "/usr/local/lib/python3.5/dist-packages/rest_framework/views.py", line 494, in dispatch
    response = self.handle_exception(exc)
  File "/usr/local/lib/python3.5/dist-packages/rest_framework/views.py", line 454, in handle_exception
    self.raise_uncaught_exception(exc)
  File "/usr/local/lib/python3.5/dist-packages/rest_framework/views.py", line 491, in dispatch
    response = handler(request, *args, **kwargs)
  File "/home/sanya/Documents/Git/rsoi_2lab/rsoi_2lab/ag_service/aggregator/views.py", line 124, in post
    return redirect('agg1', args=[user_id,order_id])
NameError: name 'redirect' is not defined
INFO:requests.packages.urllib3.connectionpool:Starting new HTTP connection (1): localhost
INFO:requests.packages.urllib3.connectionpool:Starting new HTTP connection (1): localhost
INFO:requests.packages.urllib3.connectionpool:Starting new HTTP connection (1): localhost
INFO:requests.packages.urllib3.connectionpool:Starting new HTTP connection (1): localhost
INFO:requests.packages.urllib3.connectionpool:Starting new HTTP connection (1): localhost
INFO:requests.packages.urllib3.connectionpool:Starting new HTTP connection (1): localhost
INFO:requests.packages.urllib3.connectionpool:Starting new HTTP connection (1): localhost
INFO:requests.packages.urllib3.connectionpool:Starting new HTTP connection (1): localhost
INFO:root:Show order details
INFO:requests.packages.urllib3.connectionpool:Starting new HTTP connection (1): localhost
INFO:requests.packages.urllib3.connectionpool:Starting new HTTP connection (1): localhost
INFO:requests.packages.urllib3.connectionpool:Starting new HTTP connection (1): localhost
INFO:root:Patch products done
INFO:requests.packages.urllib3.connectionpool:Starting new HTTP connection (1): localhost
INFO:requests.packages.urllib3.connectionpool:Starting new HTTP connection (1): localhost
INFO:root:Edit order details
ERROR:django.request:Internal Server Error: /user/3/order/6/
Traceback (most recent call last):
  File "/usr/local/lib/python3.5/dist-packages/django/core/handlers/exception.py", line 35, in inner
    response = get_response(request)
  File "/usr/local/lib/python3.5/dist-packages/django/core/handlers/base.py", line 128, in _get_response
    response = self.process_exception_by_middleware(e, request)
  File "/usr/local/lib/python3.5/dist-packages/django/core/handlers/base.py", line 126, in _get_response
    response = wrapped_callback(request, *callback_args, **callback_kwargs)
  File "/usr/local/lib/python3.5/dist-packages/django/views/decorators/csrf.py", line 54, in wrapped_view
    return view_func(*args, **kwargs)
  File "/usr/local/lib/python3.5/dist-packages/django/views/generic/base.py", line 69, in view
    return self.dispatch(request, *args, **kwargs)
  File "/usr/local/lib/python3.5/dist-packages/rest_framework/views.py", line 494, in dispatch
    response = self.handle_exception(exc)
  File "/usr/local/lib/python3.5/dist-packages/rest_framework/views.py", line 454, in handle_exception
    self.raise_uncaught_exception(exc)
  File "/usr/local/lib/python3.5/dist-packages/rest_framework/views.py", line 491, in dispatch
    response = handler(request, *args, **kwargs)
  File "/home/sanya/Documents/Git/rsoi_2lab/rsoi_2lab/ag_service/aggregator/views.py", line 125, in post
    return redirect('agg1', args=[user_id,order_id])
  File "/usr/local/lib/python3.5/dist-packages/django/shortcuts.py", line 58, in redirect
    return redirect_class(resolve_url(to, *args, **kwargs))
  File "/usr/local/lib/python3.5/dist-packages/django/shortcuts.py", line 149, in resolve_url
    return reverse(to, args=args, kwargs=kwargs)
  File "/usr/local/lib/python3.5/dist-packages/django/urls/base.py", line 88, in reverse
    return iri_to_uri(resolver._reverse_with_prefix(view, prefix, *args, **kwargs))
  File "/usr/local/lib/python3.5/dist-packages/django/urls/resolvers.py", line 632, in _reverse_with_prefix
    raise NoReverseMatch(msg)
django.urls.exceptions.NoReverseMatch: Reverse for 'agg1' with keyword arguments '{'args': ['3', '6']}' not found. 1 pattern(s) tried: ['user\\/(?P<user_id>[^/]+)\\/order\\/(?P<order_id>[^/]+)\\/$']
INFO:requests.packages.urllib3.connectionpool:Starting new HTTP connection (1): localhost
INFO:requests.packages.urllib3.connectionpool:Starting new HTTP connection (1): localhost
INFO:root:Delete product from order
INFO:requests.packages.urllib3.connectionpool:Starting new HTTP connection (1): localhost
INFO:root:Show orders
INFO:requests.packages.urllib3.connectionpool:Starting new HTTP connection (1): localhost
INFO:requests.packages.urllib3.connectionpool:Starting new HTTP connection (1): localhost
INFO:requests.packages.urllib3.connectionpool:Starting new HTTP connection (1): localhost
INFO:requests.packages.urllib3.connectionpool:Starting new HTTP connection (1): localhost
INFO:requests.packages.urllib3.connectionpool:Starting new HTTP connection (1): localhost
INFO:requests.packages.urllib3.connectionpool:Starting new HTTP connection (1): localhost
INFO:requests.packages.urllib3.connectionpool:Starting new HTTP connection (1): localhost
INFO:requests.packages.urllib3.connectionpool:Starting new HTTP connection (1): localhost
INFO:root:Show order details
INFO:requests.packages.urllib3.connectionpool:Starting new HTTP connection (1): localhost
INFO:requests.packages.urllib3.connectionpool:Starting new HTTP connection (1): localhost
INFO:requests.packages.urllib3.connectionpool:Starting new HTTP connection (1): localhost
INFO:root:Patch products done
INFO:requests.packages.urllib3.connectionpool:Starting new HTTP connection (1): localhost
INFO:requests.packages.urllib3.connectionpool:Starting new HTTP connection (1): localhost
INFO:root:Edit order details
INFO:requests.packages.urllib3.connectionpool:Starting new HTTP connection (1): localhost
INFO:requests.packages.urllib3.connectionpool:Starting new HTTP connection (1): localhost
INFO:requests.packages.urllib3.connectionpool:Starting new HTTP connection (1): localhost
INFO:requests.packages.urllib3.connectionpool:Starting new HTTP connection (1): localhost
INFO:requests.packages.urllib3.connectionpool:Starting new HTTP connection (1): localhost
INFO:requests.packages.urllib3.connectionpool:Starting new HTTP connection (1): localhost
INFO:requests.packages.urllib3.connectionpool:Starting new HTTP connection (1): localhost
INFO:requests.packages.urllib3.connectionpool:Starting new HTTP connection (1): localhost
INFO:requests.packages.urllib3.connectionpool:Starting new HTTP connection (1): localhost
INFO:root:Show order details
INFO:requests.packages.urllib3.connectionpool:Starting new HTTP connection (1): localhost
INFO:requests.packages.urllib3.connectionpool:Starting new HTTP connection (1): localhost
INFO:root:Delete product from order
INFO:requests.packages.urllib3.connectionpool:Starting new HTTP connection (1): localhost
INFO:requests.packages.urllib3.connectionpool:Starting new HTTP connection (1): localhost
INFO:requests.packages.urllib3.connectionpool:Starting new HTTP connection (1): localhost
INFO:requests.packages.urllib3.connectionpool:Starting new HTTP connection (1): localhost
INFO:requests.packages.urllib3.connectionpool:Starting new HTTP connection (1): localhost
INFO:requests.packages.urllib3.connectionpool:Starting new HTTP connection (1): localhost
INFO:requests.packages.urllib3.connectionpool:Starting new HTTP connection (1): localhost
INFO:requests.packages.urllib3.connectionpool:Starting new HTTP connection (1): localhost
INFO:root:Show order details
INFO:requests.packages.urllib3.connectionpool:Starting new HTTP connection (1): localhost
INFO:requests.packages.urllib3.connectionpool:Starting new HTTP connection (1): localhost
INFO:root:Delete product from order
INFO:requests.packages.urllib3.connectionpool:Starting new HTTP connection (1): localhost
INFO:requests.packages.urllib3.connectionpool:Starting new HTTP connection (1): localhost
INFO:requests.packages.urllib3.connectionpool:Starting new HTTP connection (1): localhost
INFO:requests.packages.urllib3.connectionpool:Starting new HTTP connection (1): localhost
INFO:requests.packages.urllib3.connectionpool:Starting new HTTP connection (1): localhost
INFO:requests.packages.urllib3.connectionpool:Starting new HTTP connection (1): localhost
INFO:requests.packages.urllib3.connectionpool:Starting new HTTP connection (1): localhost
INFO:root:Show order details
INFO:requests.packages.urllib3.connectionpool:Starting new HTTP connection (1): localhost
INFO:requests.packages.urllib3.connectionpool:Starting new HTTP connection (1): localhost
INFO:requests.packages.urllib3.connectionpool:Starting new HTTP connection (1): localhost
INFO:root:Patch products done
INFO:requests.packages.urllib3.connectionpool:Starting new HTTP connection (1): localhost
INFO:requests.packages.urllib3.connectionpool:Starting new HTTP connection (1): localhost
INFO:root:Edit order details
INFO:requests.packages.urllib3.connectionpool:Starting new HTTP connection (1): localhost
INFO:requests.packages.urllib3.connectionpool:Starting new HTTP connection (1): localhost
INFO:requests.packages.urllib3.connectionpool:Starting new HTTP connection (1): localhost
INFO:requests.packages.urllib3.connectionpool:Starting new HTTP connection (1): localhost
INFO:requests.packages.urllib3.connectionpool:Starting new HTTP connection (1): localhost
INFO:requests.packages.urllib3.connectionpool:Starting new HTTP connection (1): localhost
INFO:requests.packages.urllib3.connectionpool:Starting new HTTP connection (1): localhost
INFO:requests.packages.urllib3.connectionpool:Starting new HTTP connection (1): localhost
INFO:root:Show order details
INFO:requests.packages.urllib3.connectionpool:Starting new HTTP connection (1): localhost
INFO:requests.packages.urllib3.connectionpool:Starting new HTTP connection (1): localhost
INFO:root:Delete product from order
INFO:requests.packages.urllib3.connectionpool:Starting new HTTP connection (1): localhost
INFO:requests.packages.urllib3.connectionpool:Starting new HTTP connection (1): localhost
INFO:requests.packages.urllib3.connectionpool:Starting new HTTP connection (1): localhost
INFO:requests.packages.urllib3.connectionpool:Starting new HTTP connection (1): localhost
INFO:requests.packages.urllib3.connectionpool:Starting new HTTP connection (1): localhost
INFO:requests.packages.urllib3.connectionpool:Starting new HTTP connection (1): localhost
INFO:requests.packages.urllib3.connectionpool:Starting new HTTP connection (1): localhost
INFO:root:Show order details
INFO:requests.packages.urllib3.connectionpool:Starting new HTTP connection (1): localhost
INFO:requests.packages.urllib3.connectionpool:Starting new HTTP connection (1): localhost
INFO:requests.packages.urllib3.connectionpool:Starting new HTTP connection (1): localhost
INFO:root:Patch products done
INFO:requests.packages.urllib3.connectionpool:Starting new HTTP connection (1): localhost
INFO:requests.packages.urllib3.connectionpool:Starting new HTTP connection (1): localhost
INFO:root:Edit order details
INFO:requests.packages.urllib3.connectionpool:Starting new HTTP connection (1): localhost
INFO:requests.packages.urllib3.connectionpool:Starting new HTTP connection (1): localhost
INFO:requests.packages.urllib3.connectionpool:Starting new HTTP connection (1): localhost
INFO:requests.packages.urllib3.connectionpool:Starting new HTTP connection (1): localhost
INFO:requests.packages.urllib3.connectionpool:Starting new HTTP connection (1): localhost
INFO:requests.packages.urllib3.connectionpool:Starting new HTTP connection (1): localhost
INFO:requests.packages.urllib3.connectionpool:Starting new HTTP connection (1): localhost
INFO:requests.packages.urllib3.connectionpool:Starting new HTTP connection (1): localhost
INFO:root:Show order details
INFO:requests.packages.urllib3.connectionpool:Starting new HTTP connection (1): localhost
INFO:requests.packages.urllib3.connectionpool:Starting new HTTP connection (1): localhost
INFO:root:Delete product from order
INFO:requests.packages.urllib3.connectionpool:Starting new HTTP connection (1): localhost
INFO:requests.packages.urllib3.connectionpool:Starting new HTTP connection (1): localhost
INFO:requests.packages.urllib3.connectionpool:Starting new HTTP connection (1): localhost
INFO:requests.packages.urllib3.connectionpool:Starting new HTTP connection (1): localhost
INFO:requests.packages.urllib3.connectionpool:Starting new HTTP connection (1): localhost
INFO:requests.packages.urllib3.connectionpool:Starting new HTTP connection (1): localhost
INFO:requests.packages.urllib3.connectionpool:Starting new HTTP connection (1): localhost
INFO:root:Show order details
INFO:requests.packages.urllib3.connectionpool:Starting new HTTP connection (1): localhost
INFO:root:Show orders
INFO:requests.packages.urllib3.connectionpool:Starting new HTTP connection (1): localhost
INFO:requests.packages.urllib3.connectionpool:Starting new HTTP connection (1): localhost
INFO:requests.packages.urllib3.connectionpool:Starting new HTTP connection (1): localhost
INFO:requests.packages.urllib3.connectionpool:Starting new HTTP connection (1): localhost
INFO:requests.packages.urllib3.connectionpool:Starting new HTTP connection (1): localhost
INFO:requests.packages.urllib3.connectionpool:Starting new HTTP connection (1): localhost
INFO:root:Show order details
INFO:requests.packages.urllib3.connectionpool:Starting new HTTP connection (1): localhost
INFO:requests.packages.urllib3.connectionpool:Starting new HTTP connection (1): localhost
INFO:requests.packages.urllib3.connectionpool:Starting new HTTP connection (1): localhost
INFO:requests.packages.urllib3.connectionpool:Starting new HTTP connection (1): localhost
INFO:requests.packages.urllib3.connectionpool:Starting new HTTP connection (1): localhost
INFO:requests.packages.urllib3.connectionpool:Starting new HTTP connection (1): localhost
INFO:root:Show order details
INFO:requests.packages.urllib3.connectionpool:Starting new HTTP connection (1): localhost
INFO:requests.packages.urllib3.connectionpool:Starting new HTTP connection (1): localhost
INFO:root:Delete product from order
INFO:requests.packages.urllib3.connectionpool:Starting new HTTP connection (1): localhost
INFO:requests.packages.urllib3.connectionpool:Starting new HTTP connection (1): localhost
INFO:requests.packages.urllib3.connectionpool:Starting new HTTP connection (1): localhost
INFO:requests.packages.urllib3.connectionpool:Starting new HTTP connection (1): localhost
INFO:requests.packages.urllib3.connectionpool:Starting new HTTP connection (1): localhost
INFO:root:Show order details
INFO:requests.packages.urllib3.connectionpool:Starting new HTTP connection (1): localhost
INFO:requests.packages.urllib3.connectionpool:Starting new HTTP connection (1): localhost
INFO:requests.packages.urllib3.connectionpool:Starting new HTTP connection (1): localhost
INFO:requests.packages.urllib3.connectionpool:Starting new HTTP connection (1): localhost
INFO:requests.packages.urllib3.connectionpool:Starting new HTTP connection (1): localhost
INFO:requests.packages.urllib3.connectionpool:Starting new HTTP connection (1): localhost
INFO:requests.packages.urllib3.connectionpool:Starting new HTTP connection (1): localhost
INFO:root:Show order details
INFO:requests.packages.urllib3.connectionpool:Starting new HTTP connection (1): localhost
INFO:requests.packages.urllib3.connectionpool:Starting new HTTP connection (1): localhost
INFO:requests.packages.urllib3.connectionpool:Starting new HTTP connection (1): localhost
INFO:requests.packages.urllib3.connectionpool:Starting new HTTP connection (1): localhost
INFO:requests.packages.urllib3.connectionpool:Starting new HTTP connection (1): localhost
INFO:root:Show order details
INFO:requests.packages.urllib3.connectionpool:Starting new HTTP connection (1): localhost
INFO:root:Show orders
INFO:requests.packages.urllib3.connectionpool:Starting new HTTP connection (1): localhost
INFO:requests.packages.urllib3.connectionpool:Starting new HTTP connection (1): localhost
INFO:requests.packages.urllib3.connectionpool:Starting new HTTP connection (1): localhost
INFO:requests.packages.urllib3.connectionpool:Starting new HTTP connection (1): localhost
INFO:requests.packages.urllib3.connectionpool:Starting new HTTP connection (1): localhost
INFO:root:Show order details
INFO:requests.packages.urllib3.connectionpool:Starting new HTTP connection (1): localhost
INFO:root:Show orders
INFO:requests.packages.urllib3.connectionpool:Starting new HTTP connection (1): localhost
INFO:requests.packages.urllib3.connectionpool:Starting new HTTP connection (1): localhost
INFO:requests.packages.urllib3.connectionpool:Starting new HTTP connection (1): localhost
INFO:requests.packages.urllib3.connectionpool:Starting new HTTP connection (1): localhost
INFO:requests.packages.urllib3.connectionpool:Starting new HTTP connection (1): localhost
INFO:requests.packages.urllib3.connectionpool:Starting new HTTP connection (1): localhost
INFO:requests.packages.urllib3.connectionpool:Starting new HTTP connection (1): localhost
INFO:root:Show order details
INFO:requests.packages.urllib3.connectionpool:Starting new HTTP connection (1): localhost
INFO:root:Show orders
INFO:requests.packages.urllib3.connectionpool:Starting new HTTP connection (1): localhost
INFO:requests.packages.urllib3.connectionpool:Starting new HTTP connection (1): localhost
INFO:requests.packages.urllib3.connectionpool:Starting new HTTP connection (1): localhost
INFO:requests.packages.urllib3.connectionpool:Starting new HTTP connection (1): localhost
INFO:requests.packages.urllib3.connectionpool:Starting new HTTP connection (1): localhost
INFO:requests.packages.urllib3.connectionpool:Starting new HTTP connection (1): localhost
INFO:requests.packages.urllib3.connectionpool:Starting new HTTP connection (1): localhost
INFO:root:Show order details
INFO:requests.packages.urllib3.connectionpool:Starting new HTTP connection (1): localhost
INFO:root:Show orders
INFO:requests.packages.urllib3.connectionpool:Starting new HTTP connection (1): localhost
INFO:root:Show orders
WARNING:django.request:Not Found: /favicon.ico
INFO:requests.packages.urllib3.connectionpool:Starting new HTTP connection (1): localhost
INFO:root:Show orders
INFO:requests.packages.urllib3.connectionpool:Starting new HTTP connection (1): localhost
INFO:requests.packages.urllib3.connectionpool:Starting new HTTP connection (1): localhost
INFO:requests.packages.urllib3.connectionpool:Starting new HTTP connection (1): localhost
INFO:requests.packages.urllib3.connectionpool:Starting new HTTP connection (1): localhost
INFO:requests.packages.urllib3.connectionpool:Starting new HTTP connection (1): localhost
INFO:requests.packages.urllib3.connectionpool:Starting new HTTP connection (1): localhost
INFO:requests.packages.urllib3.connectionpool:Starting new HTTP connection (1): localhost
INFO:root:Show order details
INFO:requests.packages.urllib3.connectionpool:Starting new HTTP connection (1): localhost
INFO:requests.packages.urllib3.connectionpool:Starting new HTTP connection (1): localhost
INFO:root:Delete product from order
INFO:requests.packages.urllib3.connectionpool:Starting new HTTP connection (1): localhost
INFO:requests.packages.urllib3.connectionpool:Starting new HTTP connection (1): localhost
INFO:requests.packages.urllib3.connectionpool:Starting new HTTP connection (1): localhost
INFO:requests.packages.urllib3.connectionpool:Starting new HTTP connection (1): localhost
INFO:requests.packages.urllib3.connectionpool:Starting new HTTP connection (1): localhost
INFO:requests.packages.urllib3.connectionpool:Starting new HTTP connection (1): localhost
INFO:root:Show order details
INFO:requests.packages.urllib3.connectionpool:Starting new HTTP connection (1): localhost
INFO:requests.packages.urllib3.connectionpool:Starting new HTTP connection (1): localhost
INFO:requests.packages.urllib3.connectionpool:Starting new HTTP connection (1): localhost
INFO:root:Patch products done
INFO:requests.packages.urllib3.connectionpool:Starting new HTTP connection (1): localhost
INFO:requests.packages.urllib3.connectionpool:Starting new HTTP connection (1): localhost
INFO:root:Edit order details
INFO:requests.packages.urllib3.connectionpool:Starting new HTTP connection (1): localhost
INFO:requests.packages.urllib3.connectionpool:Starting new HTTP connection (1): localhost
INFO:requests.packages.urllib3.connectionpool:Starting new HTTP connection (1): localhost
INFO:requests.packages.urllib3.connectionpool:Starting new HTTP connection (1): localhost
INFO:requests.packages.urllib3.connectionpool:Starting new HTTP connection (1): localhost
INFO:requests.packages.urllib3.connectionpool:Starting new HTTP connection (1): localhost
INFO:requests.packages.urllib3.connectionpool:Starting new HTTP connection (1): localhost
INFO:root:Show order details
INFO:requests.packages.urllib3.connectionpool:Starting new HTTP connection (1): localhost
INFO:root:Show orders
INFO:requests.packages.urllib3.connectionpool:Starting new HTTP connection (1): localhost
INFO:requests.packages.urllib3.connectionpool:Starting new HTTP connection (1): localhost
INFO:requests.packages.urllib3.connectionpool:Starting new HTTP connection (1): localhost
INFO:requests.packages.urllib3.connectionpool:Starting new HTTP connection (1): localhost
INFO:requests.packages.urllib3.connectionpool:Starting new HTTP connection (1): localhost
INFO:requests.packages.urllib3.connectionpool:Starting new HTTP connection (1): localhost
INFO:requests.packages.urllib3.connectionpool:Starting new HTTP connection (1): localhost
INFO:root:Show order details
INFO:requests.packages.urllib3.connectionpool:Starting new HTTP connection (1): localhost
INFO:requests.packages.urllib3.connectionpool:Starting new HTTP connection (1): localhost
INFO:root:Show order details
INFO:requests.packages.urllib3.connectionpool:Starting new HTTP connection (1): localhost
INFO:root:Show orders
INFO:requests.packages.urllib3.connectionpool:Starting new HTTP connection (1): localhost
INFO:requests.packages.urllib3.connectionpool:Starting new HTTP connection (1): localhost
INFO:root:Show order details
INFO:requests.packages.urllib3.connectionpool:Starting new HTTP connection (1): localhost
INFO:root:Show orders
INFO:requests.packages.urllib3.connectionpool:Starting new HTTP connection (1): localhost
INFO:requests.packages.urllib3.connectionpool:Starting new HTTP connection (1): localhost
INFO:requests.packages.urllib3.connectionpool:Starting new HTTP connection (1): localhost
INFO:requests.packages.urllib3.connectionpool:Starting new HTTP connection (1): localhost
INFO:requests.packages.urllib3.connectionpool:Starting new HTTP connection (1): localhost
INFO:root:Show order details
INFO:requests.packages.urllib3.connectionpool:Starting new HTTP connection (1): localhost
INFO:requests.packages.urllib3.connectionpool:Starting new HTTP connection (1): localhost
WARNING:django.request:Not Found: /user/3/order/5/
INFO:requests.packages.urllib3.connectionpool:Starting new HTTP connection (1): localhost
INFO:root:Show orders
INFO:requests.packages.urllib3.connectionpool:Starting new HTTP connection (1): localhost
INFO:requests.packages.urllib3.connectionpool:Starting new HTTP connection (1): localhost
INFO:requests.packages.urllib3.connectionpool:Starting new HTTP connection (1): localhost
INFO:requests.packages.urllib3.connectionpool:Starting new HTTP connection (1): localhost
INFO:requests.packages.urllib3.connectionpool:Starting new HTTP connection (1): localhost
INFO:root:Show order details
INFO:requests.packages.urllib3.connectionpool:Starting new HTTP connection (1): localhost
INFO:requests.packages.urllib3.connectionpool:Starting new HTTP connection (1): localhost
INFO:requests.packages.urllib3.connectionpool:Starting new HTTP connection (1): localhost
INFO:root:Patch products done
INFO:requests.packages.urllib3.connectionpool:Starting new HTTP connection (1): localhost
INFO:requests.packages.urllib3.connectionpool:Starting new HTTP connection (1): localhost
INFO:root:Edit order details
INFO:requests.packages.urllib3.connectionpool:Starting new HTTP connection (1): localhost
INFO:requests.packages.urllib3.connectionpool:Starting new HTTP connection (1): localhost
INFO:requests.packages.urllib3.connectionpool:Starting new HTTP connection (1): localhost
INFO:requests.packages.urllib3.connectionpool:Starting new HTTP connection (1): localhost
INFO:requests.packages.urllib3.connectionpool:Starting new HTTP connection (1): localhost
INFO:requests.packages.urllib3.connectionpool:Starting new HTTP connection (1): localhost
INFO:root:Show order details
INFO:requests.packages.urllib3.connectionpool:Starting new HTTP connection (1): localhost
INFO:requests.packages.urllib3.connectionpool:Starting new HTTP connection (1): localhost
INFO:root:Delete product from order
INFO:requests.packages.urllib3.connectionpool:Starting new HTTP connection (1): localhost
INFO:requests.packages.urllib3.connectionpool:Starting new HTTP connection (1): localhost
INFO:requests.packages.urllib3.connectionpool:Starting new HTTP connection (1): localhost
INFO:requests.packages.urllib3.connectionpool:Starting new HTTP connection (1): localhost
INFO:requests.packages.urllib3.connectionpool:Starting new HTTP connection (1): localhost
INFO:root:Show order details
INFO:requests.packages.urllib3.connectionpool:Starting new HTTP connection (1): localhost
INFO:root:Show orders
INFO:requests.packages.urllib3.connectionpool:Starting new HTTP connection (1): localhost
ERROR:django.request:Internal Server Error: /
Traceback (most recent call last):
  File "/usr/local/lib/python3.5/dist-packages/django/core/handlers/exception.py", line 35, in inner
    response = get_response(request)
  File "/usr/local/lib/python3.5/dist-packages/django/core/handlers/base.py", line 139, in _get_response
    "returned None instead." % (callback.__module__, view_name)
ValueError: The view aggregator.views.index didn't return an HttpResponse object. It returned None instead.
ERROR:django.request:Internal Server Error: /
Traceback (most recent call last):
  File "/usr/local/lib/python3.5/dist-packages/django/core/handlers/exception.py", line 35, in inner
    response = get_response(request)
  File "/usr/local/lib/python3.5/dist-packages/django/core/handlers/base.py", line 128, in _get_response
    response = self.process_exception_by_middleware(e, request)
  File "/usr/local/lib/python3.5/dist-packages/django/core/handlers/base.py", line 126, in _get_response
    response = wrapped_callback(request, *callback_args, **callback_kwargs)
  File "/usr/local/lib/python3.5/dist-packages/django/views/decorators/csrf.py", line 54, in wrapped_view
    return view_func(*args, **kwargs)
  File "/usr/local/lib/python3.5/dist-packages/django/views/generic/base.py", line 69, in view
    return self.dispatch(request, *args, **kwargs)
  File "/usr/local/lib/python3.5/dist-packages/rest_framework/views.py", line 494, in dispatch
    response = self.handle_exception(exc)
  File "/usr/local/lib/python3.5/dist-packages/rest_framework/views.py", line 454, in handle_exception
    self.raise_uncaught_exception(exc)
  File "/usr/local/lib/python3.5/dist-packages/rest_framework/views.py", line 491, in dispatch
    response = handler(request, *args, **kwargs)
TypeError: get() takes 1 positional argument but 2 were given
WARNING:django.request:Not Found: /
WARNING:django.request:Not Found: /
WARNING:django.request:Not Found: /
WARNING:django.request:Not Found: /
ERROR:django.request:Internal Server Error: /
Traceback (most recent call last):
  File "/usr/local/lib/python3.5/dist-packages/django/core/handlers/exception.py", line 35, in inner
    response = get_response(request)
  File "/usr/local/lib/python3.5/dist-packages/django/core/handlers/base.py", line 128, in _get_response
    response = self.process_exception_by_middleware(e, request)
  File "/usr/local/lib/python3.5/dist-packages/django/core/handlers/base.py", line 126, in _get_response
    response = wrapped_callback(request, *callback_args, **callback_kwargs)
  File "/usr/local/lib/python3.5/dist-packages/django/views/decorators/csrf.py", line 54, in wrapped_view
    return view_func(*args, **kwargs)
  File "/usr/local/lib/python3.5/dist-packages/django/views/generic/base.py", line 69, in view
    return self.dispatch(request, *args, **kwargs)
  File "/usr/local/lib/python3.5/dist-packages/rest_framework/views.py", line 496, in dispatch
    self.response = self.finalize_response(request, response, *args, **kwargs)
  File "/usr/local/lib/python3.5/dist-packages/rest_framework/views.py", line 411, in finalize_response
    % type(response)
AssertionError: Expected a `Response`, `HttpResponse` or `HttpStreamingResponse` to be returned from the view, but received a `<class 'NoneType'>`
ERROR:django.request:Internal Server Error: /
Traceback (most recent call last):
  File "/usr/local/lib/python3.5/dist-packages/django/core/handlers/exception.py", line 35, in inner
    response = get_response(request)
  File "/usr/local/lib/python3.5/dist-packages/django/core/handlers/base.py", line 128, in _get_response
    response = self.process_exception_by_middleware(e, request)
  File "/usr/local/lib/python3.5/dist-packages/django/core/handlers/base.py", line 126, in _get_response
    response = wrapped_callback(request, *callback_args, **callback_kwargs)
  File "/usr/local/lib/python3.5/dist-packages/django/views/decorators/csrf.py", line 54, in wrapped_view
    return view_func(*args, **kwargs)
  File "/usr/local/lib/python3.5/dist-packages/django/views/generic/base.py", line 69, in view
    return self.dispatch(request, *args, **kwargs)
  File "/usr/local/lib/python3.5/dist-packages/rest_framework/views.py", line 496, in dispatch
    self.response = self.finalize_response(request, response, *args, **kwargs)
  File "/usr/local/lib/python3.5/dist-packages/rest_framework/views.py", line 411, in finalize_response
    % type(response)
AssertionError: Expected a `Response`, `HttpResponse` or `HttpStreamingResponse` to be returned from the view, but received a `<class 'NoneType'>`
ERROR:django.request:Internal Server Error: /
Traceback (most recent call last):
  File "/usr/local/lib/python3.5/dist-packages/django/core/handlers/exception.py", line 35, in inner
    response = get_response(request)
  File "/usr/local/lib/python3.5/dist-packages/django/core/handlers/base.py", line 128, in _get_response
    response = self.process_exception_by_middleware(e, request)
  File "/usr/local/lib/python3.5/dist-packages/django/core/handlers/base.py", line 126, in _get_response
    response = wrapped_callback(request, *callback_args, **callback_kwargs)
  File "/usr/local/lib/python3.5/dist-packages/django/views/decorators/csrf.py", line 54, in wrapped_view
    return view_func(*args, **kwargs)
  File "/usr/local/lib/python3.5/dist-packages/django/views/generic/base.py", line 69, in view
    return self.dispatch(request, *args, **kwargs)
  File "/usr/local/lib/python3.5/dist-packages/rest_framework/views.py", line 496, in dispatch
    self.response = self.finalize_response(request, response, *args, **kwargs)
  File "/usr/local/lib/python3.5/dist-packages/rest_framework/views.py", line 411, in finalize_response
    % type(response)
AssertionError: Expected a `Response`, `HttpResponse` or `HttpStreamingResponse` to be returned from the view, but received a `<class 'NoneType'>`
ERROR:django.request:Internal Server Error: /
Traceback (most recent call last):
  File "/home/sanya/Documents/Git/rsoi_2lab/rsoi_2lab/ag_service/aggregator/views.py", line 32, in post
    r.raise_for_status()
  File "/usr/local/lib/python3.5/dist-packages/requests/models.py", line 935, in raise_for_status
    raise HTTPError(http_error_msg, response=self)
requests.exceptions.HTTPError: 500 Server Error: Internal Server Error for url: http://localhost:8002/user/auth/

During handling of the above exception, another exception occurred:

Traceback (most recent call last):
  File "/usr/local/lib/python3.5/dist-packages/django/core/handlers/exception.py", line 35, in inner
    response = get_response(request)
  File "/usr/local/lib/python3.5/dist-packages/django/core/handlers/base.py", line 128, in _get_response
    response = self.process_exception_by_middleware(e, request)
  File "/usr/local/lib/python3.5/dist-packages/django/core/handlers/base.py", line 126, in _get_response
    response = wrapped_callback(request, *callback_args, **callback_kwargs)
  File "/usr/local/lib/python3.5/dist-packages/django/views/decorators/csrf.py", line 54, in wrapped_view
    return view_func(*args, **kwargs)
  File "/usr/local/lib/python3.5/dist-packages/django/views/generic/base.py", line 69, in view
    return self.dispatch(request, *args, **kwargs)
  File "/usr/local/lib/python3.5/dist-packages/rest_framework/views.py", line 494, in dispatch
    response = self.handle_exception(exc)
  File "/usr/local/lib/python3.5/dist-packages/rest_framework/views.py", line 454, in handle_exception
    self.raise_uncaught_exception(exc)
  File "/usr/local/lib/python3.5/dist-packages/rest_framework/views.py", line 491, in dispatch
    response = handler(request, *args, **kwargs)
  File "/home/sanya/Documents/Git/rsoi_2lab/rsoi_2lab/ag_service/aggregator/views.py", line 35, in post
    return HttpResponse(loader.render_to_string( str(status_code)+'.html'), status=status_code)
  File "/usr/local/lib/python3.5/dist-packages/django/template/loader.py", line 61, in render_to_string
    template = get_template(template_name, using=using)
  File "/usr/local/lib/python3.5/dist-packages/django/template/loader.py", line 19, in get_template
    raise TemplateDoesNotExist(template_name, chain=chain)
django.template.exceptions.TemplateDoesNotExist: 500.html
ERROR:django.request:Internal Server Error: /
Traceback (most recent call last):
  File "/usr/local/lib/python3.5/dist-packages/django/core/handlers/exception.py", line 35, in inner
    response = get_response(request)
  File "/usr/local/lib/python3.5/dist-packages/django/core/handlers/base.py", line 128, in _get_response
    response = self.process_exception_by_middleware(e, request)
  File "/usr/local/lib/python3.5/dist-packages/django/core/handlers/base.py", line 126, in _get_response
    response = wrapped_callback(request, *callback_args, **callback_kwargs)
  File "/usr/local/lib/python3.5/dist-packages/django/views/decorators/csrf.py", line 54, in wrapped_view
    return view_func(*args, **kwargs)
  File "/usr/local/lib/python3.5/dist-packages/django/views/generic/base.py", line 69, in view
    return self.dispatch(request, *args, **kwargs)
  File "/usr/local/lib/python3.5/dist-packages/rest_framework/views.py", line 494, in dispatch
    response = self.handle_exception(exc)
  File "/usr/local/lib/python3.5/dist-packages/rest_framework/views.py", line 454, in handle_exception
    self.raise_uncaught_exception(exc)
  File "/usr/local/lib/python3.5/dist-packages/rest_framework/views.py", line 491, in dispatch
    response = handler(request, *args, **kwargs)
  File "/home/sanya/Documents/Git/rsoi_2lab/rsoi_2lab/ag_service/aggregator/views.py", line 39, in post
    return render('index.html', r.json())
  File "/usr/local/lib/python3.5/dist-packages/django/shortcuts.py", line 36, in render
    content = loader.render_to_string(template_name, context, request, using=using)
  File "/usr/local/lib/python3.5/dist-packages/django/template/loader.py", line 61, in render_to_string
    template = get_template(template_name, using=using)
  File "/usr/local/lib/python3.5/dist-packages/django/template/loader.py", line 19, in get_template
    raise TemplateDoesNotExist(template_name, chain=chain)
django.template.exceptions.TemplateDoesNotExist: {'error': 'hello'}
ERROR:django.request:Internal Server Error: /
Traceback (most recent call last):
  File "/usr/local/lib/python3.5/dist-packages/django/core/handlers/exception.py", line 35, in inner
    response = get_response(request)
  File "/usr/local/lib/python3.5/dist-packages/django/core/handlers/base.py", line 158, in _get_response
    response = self.process_exception_by_middleware(e, request)
  File "/usr/local/lib/python3.5/dist-packages/django/core/handlers/base.py", line 156, in _get_response
    response = response.render()
  File "/usr/local/lib/python3.5/dist-packages/django/template/response.py", line 106, in render
    self.content = self.rendered_content
  File "/usr/local/lib/python3.5/dist-packages/rest_framework/response.py", line 72, in rendered_content
    ret = renderer.render(self.data, accepted_media_type, context)
  File "/usr/local/lib/python3.5/dist-packages/rest_framework/renderers.py", line 719, in render
    ret = template.render(context, request=renderer_context['request'])
  File "/usr/local/lib/python3.5/dist-packages/django/template/backends/django.py", line 61, in render
    return self.template.render(context)
  File "/usr/local/lib/python3.5/dist-packages/django/template/base.py", line 173, in render
    with context.bind_template(self):
  File "/usr/lib/python3.5/contextlib.py", line 59, in __enter__
    return next(self.gen)
  File "/usr/local/lib/python3.5/dist-packages/django/template/context.py", line 246, in bind_template
    processors = (template.engine.template_context_processors +
  File "/usr/local/lib/python3.5/dist-packages/django/utils/functional.py", line 36, in __get__
    res = instance.__dict__[self.name] = self.func(instance)
  File "/usr/local/lib/python3.5/dist-packages/django/template/engine.py", line 85, in template_context_processors
    return tuple(import_string(path) for path in context_processors)
  File "/usr/local/lib/python3.5/dist-packages/django/template/engine.py", line 85, in <genexpr>
    return tuple(import_string(path) for path in context_processors)
  File "/usr/local/lib/python3.5/dist-packages/django/utils/module_loading.py", line 17, in import_string
    module = import_module(module_path)
  File "/usr/lib/python3.5/importlib/__init__.py", line 126, in import_module
    return _bootstrap._gcd_import(name[level:], package, level)
  File "<frozen importlib._bootstrap>", line 986, in _gcd_import
  File "<frozen importlib._bootstrap>", line 969, in _find_and_load
  File "<frozen importlib._bootstrap>", line 956, in _find_and_load_unlocked
ImportError: No module named 'django.core.context_processors'
ERROR:django.request:Internal Server Error: /
Traceback (most recent call last):
  File "/usr/local/lib/python3.5/dist-packages/django/core/handlers/exception.py", line 35, in inner
    response = get_response(request)
  File "/usr/local/lib/python3.5/dist-packages/django/core/handlers/base.py", line 128, in _get_response
    response = self.process_exception_by_middleware(e, request)
  File "/usr/local/lib/python3.5/dist-packages/django/core/handlers/base.py", line 126, in _get_response
    response = wrapped_callback(request, *callback_args, **callback_kwargs)
  File "/usr/local/lib/python3.5/dist-packages/django/views/decorators/csrf.py", line 54, in wrapped_view
    return view_func(*args, **kwargs)
  File "/usr/local/lib/python3.5/dist-packages/django/views/generic/base.py", line 69, in view
    return self.dispatch(request, *args, **kwargs)
  File "/usr/local/lib/python3.5/dist-packages/django/utils/decorators.py", line 62, in _wrapper
    return bound_func(*args, **kwargs)
  File "/usr/local/lib/python3.5/dist-packages/django/views/decorators/csrf.py", line 54, in wrapped_view
    return view_func(*args, **kwargs)
  File "/usr/local/lib/python3.5/dist-packages/django/utils/decorators.py", line 58, in bound_func
    return func.__get__(self, type(self))(*args2, **kwargs2)
  File "/usr/local/lib/python3.5/dist-packages/braces/views/_forms.py", line 24, in dispatch
    return super(CsrfExemptMixin, self).dispatch(*args, **kwargs)
  File "/usr/local/lib/python3.5/dist-packages/rest_framework/views.py", line 494, in dispatch
    response = self.handle_exception(exc)
  File "/usr/local/lib/python3.5/dist-packages/rest_framework/views.py", line 454, in handle_exception
    self.raise_uncaught_exception(exc)
  File "/usr/local/lib/python3.5/dist-packages/rest_framework/views.py", line 491, in dispatch
    response = handler(request, *args, **kwargs)
  File "/home/sanya/Documents/Git/rsoi_2lab/rsoi_2lab/ag_service/aggregator/views.py", line 42, in post
    return render(request, 'index.html', r.json())
  File "/usr/local/lib/python3.5/dist-packages/django/shortcuts.py", line 36, in render
    content = loader.render_to_string(template_name, context, request, using=using)
  File "/usr/local/lib/python3.5/dist-packages/django/template/loader.py", line 62, in render_to_string
    return template.render(context, request)
  File "/usr/local/lib/python3.5/dist-packages/django/template/backends/django.py", line 59, in render
    context = make_context(context, request, autoescape=self.backend.engine.autoescape)
  File "/usr/local/lib/python3.5/dist-packages/django/template/context.py", line 274, in make_context
    raise TypeError('context must be a dict rather than %s.' % context.__class__.__name__)
TypeError: context must be a dict rather than str.
ERROR:django.request:Internal Server Error: /
Traceback (most recent call last):
  File "/usr/local/lib/python3.5/dist-packages/django/core/handlers/exception.py", line 35, in inner
    response = get_response(request)
  File "/usr/local/lib/python3.5/dist-packages/django/core/handlers/base.py", line 128, in _get_response
    response = self.process_exception_by_middleware(e, request)
  File "/usr/local/lib/python3.5/dist-packages/django/core/handlers/base.py", line 126, in _get_response
    response = wrapped_callback(request, *callback_args, **callback_kwargs)
  File "/usr/local/lib/python3.5/dist-packages/django/views/decorators/csrf.py", line 54, in wrapped_view
    return view_func(*args, **kwargs)
  File "/usr/local/lib/python3.5/dist-packages/django/views/generic/base.py", line 69, in view
    return self.dispatch(request, *args, **kwargs)
  File "/usr/local/lib/python3.5/dist-packages/django/utils/decorators.py", line 62, in _wrapper
    return bound_func(*args, **kwargs)
  File "/usr/local/lib/python3.5/dist-packages/django/views/decorators/csrf.py", line 54, in wrapped_view
    return view_func(*args, **kwargs)
  File "/usr/local/lib/python3.5/dist-packages/django/utils/decorators.py", line 58, in bound_func
    return func.__get__(self, type(self))(*args2, **kwargs2)
  File "/usr/local/lib/python3.5/dist-packages/braces/views/_forms.py", line 24, in dispatch
    return super(CsrfExemptMixin, self).dispatch(*args, **kwargs)
  File "/usr/local/lib/python3.5/dist-packages/rest_framework/views.py", line 494, in dispatch
    response = self.handle_exception(exc)
  File "/usr/local/lib/python3.5/dist-packages/rest_framework/views.py", line 454, in handle_exception
    self.raise_uncaught_exception(exc)
  File "/usr/local/lib/python3.5/dist-packages/rest_framework/views.py", line 491, in dispatch
    response = handler(request, *args, **kwargs)
  File "/home/sanya/Documents/Git/rsoi_2lab/rsoi_2lab/ag_service/aggregator/views.py", line 42, in post
    return render(request, 'index.html', r.json())
  File "/usr/local/lib/python3.5/dist-packages/requests/models.py", line 892, in json
    return complexjson.loads(self.text, **kwargs)
  File "/usr/lib/python3.5/json/__init__.py", line 319, in loads
    return _default_decoder.decode(s)
  File "/usr/lib/python3.5/json/decoder.py", line 339, in decode
    obj, end = self.raw_decode(s, idx=_w(s, 0).end())
  File "/usr/lib/python3.5/json/decoder.py", line 357, in raw_decode
    raise JSONDecodeError("Expecting value", s, err.value) from None
json.decoder.JSONDecodeError: Expecting value: line 1 column 1 (char 0)
ERROR:django.request:Internal Server Error: /
Traceback (most recent call last):
  File "/usr/local/lib/python3.5/dist-packages/django/core/handlers/exception.py", line 35, in inner
    response = get_response(request)
  File "/usr/local/lib/python3.5/dist-packages/django/core/handlers/base.py", line 128, in _get_response
    response = self.process_exception_by_middleware(e, request)
  File "/usr/local/lib/python3.5/dist-packages/django/core/handlers/base.py", line 126, in _get_response
    response = wrapped_callback(request, *callback_args, **callback_kwargs)
  File "/usr/local/lib/python3.5/dist-packages/django/views/decorators/csrf.py", line 54, in wrapped_view
    return view_func(*args, **kwargs)
  File "/usr/local/lib/python3.5/dist-packages/django/views/generic/base.py", line 69, in view
    return self.dispatch(request, *args, **kwargs)
  File "/usr/local/lib/python3.5/dist-packages/django/utils/decorators.py", line 62, in _wrapper
    return bound_func(*args, **kwargs)
  File "/usr/local/lib/python3.5/dist-packages/django/views/decorators/csrf.py", line 54, in wrapped_view
    return view_func(*args, **kwargs)
  File "/usr/local/lib/python3.5/dist-packages/django/utils/decorators.py", line 58, in bound_func
    return func.__get__(self, type(self))(*args2, **kwargs2)
  File "/usr/local/lib/python3.5/dist-packages/braces/views/_forms.py", line 24, in dispatch
    return super(CsrfExemptMixin, self).dispatch(*args, **kwargs)
  File "/usr/local/lib/python3.5/dist-packages/rest_framework/views.py", line 496, in dispatch
    self.response = self.finalize_response(request, response, *args, **kwargs)
  File "/usr/local/lib/python3.5/dist-packages/rest_framework/views.py", line 411, in finalize_response
    % type(response)
AssertionError: Expected a `Response`, `HttpResponse` or `HttpStreamingResponse` to be returned from the view, but received a `<class 'NoneType'>`
ERROR:django.request:Internal Server Error: /
Traceback (most recent call last):
  File "/usr/local/lib/python3.5/dist-packages/django/core/handlers/exception.py", line 35, in inner
    response = get_response(request)
  File "/usr/local/lib/python3.5/dist-packages/django/core/handlers/base.py", line 128, in _get_response
    response = self.process_exception_by_middleware(e, request)
  File "/usr/local/lib/python3.5/dist-packages/django/core/handlers/base.py", line 126, in _get_response
    response = wrapped_callback(request, *callback_args, **callback_kwargs)
  File "/usr/local/lib/python3.5/dist-packages/django/views/decorators/csrf.py", line 54, in wrapped_view
    return view_func(*args, **kwargs)
  File "/usr/local/lib/python3.5/dist-packages/django/views/generic/base.py", line 69, in view
    return self.dispatch(request, *args, **kwargs)
  File "/usr/local/lib/python3.5/dist-packages/django/utils/decorators.py", line 62, in _wrapper
    return bound_func(*args, **kwargs)
  File "/usr/local/lib/python3.5/dist-packages/django/views/decorators/csrf.py", line 54, in wrapped_view
    return view_func(*args, **kwargs)
  File "/usr/local/lib/python3.5/dist-packages/django/utils/decorators.py", line 58, in bound_func
    return func.__get__(self, type(self))(*args2, **kwargs2)
  File "/usr/local/lib/python3.5/dist-packages/braces/views/_forms.py", line 24, in dispatch
    return super(CsrfExemptMixin, self).dispatch(*args, **kwargs)
  File "/usr/local/lib/python3.5/dist-packages/rest_framework/views.py", line 496, in dispatch
    self.response = self.finalize_response(request, response, *args, **kwargs)
  File "/usr/local/lib/python3.5/dist-packages/rest_framework/views.py", line 411, in finalize_response
    % type(response)
AssertionError: Expected a `Response`, `HttpResponse` or `HttpStreamingResponse` to be returned from the view, but received a `<class 'NoneType'>`
ERROR:django.request:Internal Server Error: /
Traceback (most recent call last):
  File "/usr/local/lib/python3.5/dist-packages/django/core/handlers/exception.py", line 35, in inner
    response = get_response(request)
  File "/usr/local/lib/python3.5/dist-packages/django/core/handlers/base.py", line 128, in _get_response
    response = self.process_exception_by_middleware(e, request)
  File "/usr/local/lib/python3.5/dist-packages/django/core/handlers/base.py", line 126, in _get_response
    response = wrapped_callback(request, *callback_args, **callback_kwargs)
  File "/usr/local/lib/python3.5/dist-packages/django/views/decorators/csrf.py", line 54, in wrapped_view
    return view_func(*args, **kwargs)
  File "/usr/local/lib/python3.5/dist-packages/django/views/generic/base.py", line 69, in view
    return self.dispatch(request, *args, **kwargs)
  File "/usr/local/lib/python3.5/dist-packages/django/utils/decorators.py", line 62, in _wrapper
    return bound_func(*args, **kwargs)
  File "/usr/local/lib/python3.5/dist-packages/django/views/decorators/csrf.py", line 54, in wrapped_view
    return view_func(*args, **kwargs)
  File "/usr/local/lib/python3.5/dist-packages/django/utils/decorators.py", line 58, in bound_func
    return func.__get__(self, type(self))(*args2, **kwargs2)
  File "/usr/local/lib/python3.5/dist-packages/braces/views/_forms.py", line 24, in dispatch
    return super(CsrfExemptMixin, self).dispatch(*args, **kwargs)
  File "/usr/local/lib/python3.5/dist-packages/rest_framework/views.py", line 496, in dispatch
    self.response = self.finalize_response(request, response, *args, **kwargs)
  File "/usr/local/lib/python3.5/dist-packages/rest_framework/views.py", line 411, in finalize_response
    % type(response)
AssertionError: Expected a `Response`, `HttpResponse` or `HttpStreamingResponse` to be returned from the view, but received a `<class 'NoneType'>`
ERROR:django.request:Internal Server Error: /
Traceback (most recent call last):
  File "/usr/local/lib/python3.5/dist-packages/django/core/handlers/exception.py", line 35, in inner
    response = get_response(request)
  File "/usr/local/lib/python3.5/dist-packages/django/core/handlers/base.py", line 128, in _get_response
    response = self.process_exception_by_middleware(e, request)
  File "/usr/local/lib/python3.5/dist-packages/django/core/handlers/base.py", line 126, in _get_response
    response = wrapped_callback(request, *callback_args, **callback_kwargs)
  File "/usr/local/lib/python3.5/dist-packages/django/views/decorators/csrf.py", line 54, in wrapped_view
    return view_func(*args, **kwargs)
  File "/usr/local/lib/python3.5/dist-packages/django/views/generic/base.py", line 69, in view
    return self.dispatch(request, *args, **kwargs)
  File "/usr/local/lib/python3.5/dist-packages/django/utils/decorators.py", line 62, in _wrapper
    return bound_func(*args, **kwargs)
  File "/usr/local/lib/python3.5/dist-packages/django/views/decorators/csrf.py", line 54, in wrapped_view
    return view_func(*args, **kwargs)
  File "/usr/local/lib/python3.5/dist-packages/django/utils/decorators.py", line 58, in bound_func
    return func.__get__(self, type(self))(*args2, **kwargs2)
  File "/usr/local/lib/python3.5/dist-packages/braces/views/_forms.py", line 24, in dispatch
    return super(CsrfExemptMixin, self).dispatch(*args, **kwargs)
  File "/usr/local/lib/python3.5/dist-packages/rest_framework/views.py", line 496, in dispatch
    self.response = self.finalize_response(request, response, *args, **kwargs)
  File "/usr/local/lib/python3.5/dist-packages/rest_framework/views.py", line 411, in finalize_response
    % type(response)
AssertionError: Expected a `Response`, `HttpResponse` or `HttpStreamingResponse` to be returned from the view, but received a `<class 'NoneType'>`
ERROR:django.request:Internal Server Error: /
Traceback (most recent call last):
  File "/usr/local/lib/python3.5/dist-packages/django/core/handlers/exception.py", line 35, in inner
    response = get_response(request)
  File "/usr/local/lib/python3.5/dist-packages/django/core/handlers/base.py", line 128, in _get_response
    response = self.process_exception_by_middleware(e, request)
  File "/usr/local/lib/python3.5/dist-packages/django/core/handlers/base.py", line 126, in _get_response
    response = wrapped_callback(request, *callback_args, **callback_kwargs)
  File "/usr/local/lib/python3.5/dist-packages/django/views/decorators/csrf.py", line 54, in wrapped_view
    return view_func(*args, **kwargs)
  File "/usr/local/lib/python3.5/dist-packages/django/views/generic/base.py", line 69, in view
    return self.dispatch(request, *args, **kwargs)
  File "/usr/local/lib/python3.5/dist-packages/django/utils/decorators.py", line 62, in _wrapper
    return bound_func(*args, **kwargs)
  File "/usr/local/lib/python3.5/dist-packages/django/views/decorators/csrf.py", line 54, in wrapped_view
    return view_func(*args, **kwargs)
  File "/usr/local/lib/python3.5/dist-packages/django/utils/decorators.py", line 58, in bound_func
    return func.__get__(self, type(self))(*args2, **kwargs2)
  File "/usr/local/lib/python3.5/dist-packages/braces/views/_forms.py", line 24, in dispatch
    return super(CsrfExemptMixin, self).dispatch(*args, **kwargs)
  File "/usr/local/lib/python3.5/dist-packages/rest_framework/views.py", line 496, in dispatch
    self.response = self.finalize_response(request, response, *args, **kwargs)
  File "/usr/local/lib/python3.5/dist-packages/rest_framework/views.py", line 411, in finalize_response
    % type(response)
AssertionError: Expected a `Response`, `HttpResponse` or `HttpStreamingResponse` to be returned from the view, but received a `<class 'NoneType'>`
ERROR:django.request:Internal Server Error: /
Traceback (most recent call last):
  File "/usr/local/lib/python3.5/dist-packages/django/core/handlers/exception.py", line 35, in inner
    response = get_response(request)
  File "/usr/local/lib/python3.5/dist-packages/django/core/handlers/base.py", line 128, in _get_response
    response = self.process_exception_by_middleware(e, request)
  File "/usr/local/lib/python3.5/dist-packages/django/core/handlers/base.py", line 126, in _get_response
    response = wrapped_callback(request, *callback_args, **callback_kwargs)
  File "/usr/local/lib/python3.5/dist-packages/django/views/decorators/csrf.py", line 54, in wrapped_view
    return view_func(*args, **kwargs)
  File "/usr/local/lib/python3.5/dist-packages/django/views/generic/base.py", line 69, in view
    return self.dispatch(request, *args, **kwargs)
  File "/usr/local/lib/python3.5/dist-packages/django/utils/decorators.py", line 62, in _wrapper
    return bound_func(*args, **kwargs)
  File "/usr/local/lib/python3.5/dist-packages/django/views/decorators/csrf.py", line 54, in wrapped_view
    return view_func(*args, **kwargs)
  File "/usr/local/lib/python3.5/dist-packages/django/utils/decorators.py", line 58, in bound_func
    return func.__get__(self, type(self))(*args2, **kwargs2)
  File "/usr/local/lib/python3.5/dist-packages/braces/views/_forms.py", line 24, in dispatch
    return super(CsrfExemptMixin, self).dispatch(*args, **kwargs)
  File "/usr/local/lib/python3.5/dist-packages/rest_framework/views.py", line 496, in dispatch
    self.response = self.finalize_response(request, response, *args, **kwargs)
  File "/usr/local/lib/python3.5/dist-packages/rest_framework/views.py", line 411, in finalize_response
    % type(response)
AssertionError: Expected a `Response`, `HttpResponse` or `HttpStreamingResponse` to be returned from the view, but received a `<class 'NoneType'>`
ERROR:django.request:Internal Server Error: /
Traceback (most recent call last):
  File "/usr/local/lib/python3.5/dist-packages/django/core/handlers/exception.py", line 35, in inner
    response = get_response(request)
  File "/usr/local/lib/python3.5/dist-packages/django/core/handlers/base.py", line 128, in _get_response
    response = self.process_exception_by_middleware(e, request)
  File "/usr/local/lib/python3.5/dist-packages/django/core/handlers/base.py", line 126, in _get_response
    response = wrapped_callback(request, *callback_args, **callback_kwargs)
  File "/usr/local/lib/python3.5/dist-packages/django/views/decorators/csrf.py", line 54, in wrapped_view
    return view_func(*args, **kwargs)
  File "/usr/local/lib/python3.5/dist-packages/django/views/generic/base.py", line 69, in view
    return self.dispatch(request, *args, **kwargs)
  File "/usr/local/lib/python3.5/dist-packages/django/utils/decorators.py", line 62, in _wrapper
    return bound_func(*args, **kwargs)
  File "/usr/local/lib/python3.5/dist-packages/django/views/decorators/csrf.py", line 54, in wrapped_view
    return view_func(*args, **kwargs)
  File "/usr/local/lib/python3.5/dist-packages/django/utils/decorators.py", line 58, in bound_func
    return func.__get__(self, type(self))(*args2, **kwargs2)
  File "/usr/local/lib/python3.5/dist-packages/braces/views/_forms.py", line 24, in dispatch
    return super(CsrfExemptMixin, self).dispatch(*args, **kwargs)
  File "/usr/local/lib/python3.5/dist-packages/rest_framework/views.py", line 496, in dispatch
    self.response = self.finalize_response(request, response, *args, **kwargs)
  File "/usr/local/lib/python3.5/dist-packages/rest_framework/views.py", line 411, in finalize_response
    % type(response)
AssertionError: Expected a `Response`, `HttpResponse` or `HttpStreamingResponse` to be returned from the view, but received a `<class 'NoneType'>`
ERROR:django.request:Internal Server Error: /
Traceback (most recent call last):
  File "/usr/local/lib/python3.5/dist-packages/django/core/handlers/exception.py", line 35, in inner
    response = get_response(request)
  File "/usr/local/lib/python3.5/dist-packages/django/core/handlers/base.py", line 128, in _get_response
    response = self.process_exception_by_middleware(e, request)
  File "/usr/local/lib/python3.5/dist-packages/django/core/handlers/base.py", line 126, in _get_response
    response = wrapped_callback(request, *callback_args, **callback_kwargs)
  File "/usr/local/lib/python3.5/dist-packages/django/views/decorators/csrf.py", line 54, in wrapped_view
    return view_func(*args, **kwargs)
  File "/usr/local/lib/python3.5/dist-packages/django/views/generic/base.py", line 69, in view
    return self.dispatch(request, *args, **kwargs)
  File "/usr/local/lib/python3.5/dist-packages/django/utils/decorators.py", line 62, in _wrapper
    return bound_func(*args, **kwargs)
  File "/usr/local/lib/python3.5/dist-packages/django/views/decorators/csrf.py", line 54, in wrapped_view
    return view_func(*args, **kwargs)
  File "/usr/local/lib/python3.5/dist-packages/django/utils/decorators.py", line 58, in bound_func
    return func.__get__(self, type(self))(*args2, **kwargs2)
  File "/usr/local/lib/python3.5/dist-packages/braces/views/_forms.py", line 24, in dispatch
    return super(CsrfExemptMixin, self).dispatch(*args, **kwargs)
  File "/usr/local/lib/python3.5/dist-packages/rest_framework/views.py", line 496, in dispatch
    self.response = self.finalize_response(request, response, *args, **kwargs)
  File "/usr/local/lib/python3.5/dist-packages/rest_framework/views.py", line 411, in finalize_response
    % type(response)
AssertionError: Expected a `Response`, `HttpResponse` or `HttpStreamingResponse` to be returned from the view, but received a `<class 'NoneType'>`
ERROR:django.request:Internal Server Error: /
Traceback (most recent call last):
  File "/usr/local/lib/python3.5/dist-packages/django/core/handlers/exception.py", line 35, in inner
    response = get_response(request)
  File "/usr/local/lib/python3.5/dist-packages/django/core/handlers/base.py", line 128, in _get_response
    response = self.process_exception_by_middleware(e, request)
  File "/usr/local/lib/python3.5/dist-packages/django/core/handlers/base.py", line 126, in _get_response
    response = wrapped_callback(request, *callback_args, **callback_kwargs)
  File "/usr/local/lib/python3.5/dist-packages/django/views/decorators/csrf.py", line 54, in wrapped_view
    return view_func(*args, **kwargs)
  File "/usr/local/lib/python3.5/dist-packages/django/views/generic/base.py", line 69, in view
    return self.dispatch(request, *args, **kwargs)
  File "/usr/local/lib/python3.5/dist-packages/django/utils/decorators.py", line 62, in _wrapper
    return bound_func(*args, **kwargs)
  File "/usr/local/lib/python3.5/dist-packages/django/views/decorators/csrf.py", line 54, in wrapped_view
    return view_func(*args, **kwargs)
  File "/usr/local/lib/python3.5/dist-packages/django/utils/decorators.py", line 58, in bound_func
    return func.__get__(self, type(self))(*args2, **kwargs2)
  File "/usr/local/lib/python3.5/dist-packages/braces/views/_forms.py", line 24, in dispatch
    return super(CsrfExemptMixin, self).dispatch(*args, **kwargs)
  File "/usr/local/lib/python3.5/dist-packages/rest_framework/views.py", line 496, in dispatch
    self.response = self.finalize_response(request, response, *args, **kwargs)
  File "/usr/local/lib/python3.5/dist-packages/rest_framework/views.py", line 411, in finalize_response
    % type(response)
AssertionError: Expected a `Response`, `HttpResponse` or `HttpStreamingResponse` to be returned from the view, but received a `<class 'NoneType'>`
WARNING:django.security.csrf:Forbidden (CSRF token missing or incorrect.): /auth/
ERROR:django.request:Internal Server Error: /
Traceback (most recent call last):
  File "/usr/local/lib/python3.5/dist-packages/django/core/handlers/exception.py", line 35, in inner
    response = get_response(request)
  File "/usr/local/lib/python3.5/dist-packages/django/core/handlers/base.py", line 128, in _get_response
    response = self.process_exception_by_middleware(e, request)
  File "/usr/local/lib/python3.5/dist-packages/django/core/handlers/base.py", line 126, in _get_response
    response = wrapped_callback(request, *callback_args, **callback_kwargs)
  File "/usr/local/lib/python3.5/dist-packages/django/views/decorators/csrf.py", line 54, in wrapped_view
    return view_func(*args, **kwargs)
  File "/usr/local/lib/python3.5/dist-packages/django/views/generic/base.py", line 69, in view
    return self.dispatch(request, *args, **kwargs)
  File "/usr/local/lib/python3.5/dist-packages/django/utils/decorators.py", line 62, in _wrapper
    return bound_func(*args, **kwargs)
  File "/usr/local/lib/python3.5/dist-packages/django/views/decorators/csrf.py", line 54, in wrapped_view
    return view_func(*args, **kwargs)
  File "/usr/local/lib/python3.5/dist-packages/django/utils/decorators.py", line 58, in bound_func
    return func.__get__(self, type(self))(*args2, **kwargs2)
  File "/usr/local/lib/python3.5/dist-packages/braces/views/_forms.py", line 24, in dispatch
    return super(CsrfExemptMixin, self).dispatch(*args, **kwargs)
  File "/usr/local/lib/python3.5/dist-packages/rest_framework/views.py", line 496, in dispatch
    self.response = self.finalize_response(request, response, *args, **kwargs)
  File "/usr/local/lib/python3.5/dist-packages/rest_framework/views.py", line 411, in finalize_response
    % type(response)
AssertionError: Expected a `Response`, `HttpResponse` or `HttpStreamingResponse` to be returned from the view, but received a `<class 'NoneType'>`
ERROR:django.request:Internal Server Error: /
Traceback (most recent call last):
  File "/usr/local/lib/python3.5/dist-packages/django/core/handlers/exception.py", line 35, in inner
    response = get_response(request)
  File "/usr/local/lib/python3.5/dist-packages/django/core/handlers/base.py", line 128, in _get_response
    response = self.process_exception_by_middleware(e, request)
  File "/usr/local/lib/python3.5/dist-packages/django/core/handlers/base.py", line 126, in _get_response
    response = wrapped_callback(request, *callback_args, **callback_kwargs)
  File "/usr/local/lib/python3.5/dist-packages/django/views/decorators/csrf.py", line 54, in wrapped_view
    return view_func(*args, **kwargs)
  File "/usr/local/lib/python3.5/dist-packages/django/views/generic/base.py", line 69, in view
    return self.dispatch(request, *args, **kwargs)
  File "/usr/local/lib/python3.5/dist-packages/django/utils/decorators.py", line 62, in _wrapper
    return bound_func(*args, **kwargs)
  File "/usr/local/lib/python3.5/dist-packages/django/views/decorators/csrf.py", line 54, in wrapped_view
    return view_func(*args, **kwargs)
  File "/usr/local/lib/python3.5/dist-packages/django/utils/decorators.py", line 58, in bound_func
    return func.__get__(self, type(self))(*args2, **kwargs2)
  File "/usr/local/lib/python3.5/dist-packages/braces/views/_forms.py", line 24, in dispatch
    return super(CsrfExemptMixin, self).dispatch(*args, **kwargs)
  File "/usr/local/lib/python3.5/dist-packages/rest_framework/views.py", line 494, in dispatch
    response = self.handle_exception(exc)
  File "/usr/local/lib/python3.5/dist-packages/rest_framework/views.py", line 454, in handle_exception
    self.raise_uncaught_exception(exc)
  File "/usr/local/lib/python3.5/dist-packages/rest_framework/views.py", line 491, in dispatch
    response = handler(request, *args, **kwargs)
  File "/home/sanya/Documents/Git/rsoi_2lab/rsoi_2lab/ag_service/aggregator/views.py", line 42, in post
    return render(request, 'index.html', r.json())
  File "/usr/local/lib/python3.5/dist-packages/django/shortcuts.py", line 36, in render
    content = loader.render_to_string(template_name, context, request, using=using)
  File "/usr/local/lib/python3.5/dist-packages/django/template/loader.py", line 62, in render_to_string
    return template.render(context, request)
  File "/usr/local/lib/python3.5/dist-packages/django/template/backends/django.py", line 59, in render
    context = make_context(context, request, autoescape=self.backend.engine.autoescape)
  File "/usr/local/lib/python3.5/dist-packages/django/template/context.py", line 274, in make_context
    raise TypeError('context must be a dict rather than %s.' % context.__class__.__name__)
TypeError: context must be a dict rather than list.
ERROR:django.request:Internal Server Error: /
Traceback (most recent call last):
  File "/usr/local/lib/python3.5/dist-packages/django/core/handlers/exception.py", line 35, in inner
    response = get_response(request)
  File "/usr/local/lib/python3.5/dist-packages/django/core/handlers/base.py", line 128, in _get_response
    response = self.process_exception_by_middleware(e, request)
  File "/usr/local/lib/python3.5/dist-packages/django/core/handlers/base.py", line 126, in _get_response
    response = wrapped_callback(request, *callback_args, **callback_kwargs)
  File "/usr/local/lib/python3.5/dist-packages/django/views/decorators/csrf.py", line 54, in wrapped_view
    return view_func(*args, **kwargs)
  File "/usr/local/lib/python3.5/dist-packages/django/views/generic/base.py", line 69, in view
    return self.dispatch(request, *args, **kwargs)
  File "/usr/local/lib/python3.5/dist-packages/django/utils/decorators.py", line 62, in _wrapper
    return bound_func(*args, **kwargs)
  File "/usr/local/lib/python3.5/dist-packages/django/views/decorators/csrf.py", line 54, in wrapped_view
    return view_func(*args, **kwargs)
  File "/usr/local/lib/python3.5/dist-packages/django/utils/decorators.py", line 58, in bound_func
    return func.__get__(self, type(self))(*args2, **kwargs2)
  File "/usr/local/lib/python3.5/dist-packages/braces/views/_forms.py", line 24, in dispatch
    return super(CsrfExemptMixin, self).dispatch(*args, **kwargs)
  File "/usr/local/lib/python3.5/dist-packages/rest_framework/views.py", line 494, in dispatch
    response = self.handle_exception(exc)
  File "/usr/local/lib/python3.5/dist-packages/rest_framework/views.py", line 454, in handle_exception
    self.raise_uncaught_exception(exc)
  File "/usr/local/lib/python3.5/dist-packages/rest_framework/views.py", line 491, in dispatch
    response = handler(request, *args, **kwargs)
  File "/home/sanya/Documents/Git/rsoi_2lab/rsoi_2lab/ag_service/aggregator/views.py", line 43, in post
    return render(request, 'index.html', r.json())
  File "/usr/local/lib/python3.5/dist-packages/django/shortcuts.py", line 36, in render
    content = loader.render_to_string(template_name, context, request, using=using)
  File "/usr/local/lib/python3.5/dist-packages/django/template/loader.py", line 62, in render_to_string
    return template.render(context, request)
  File "/usr/local/lib/python3.5/dist-packages/django/template/backends/django.py", line 59, in render
    context = make_context(context, request, autoescape=self.backend.engine.autoescape)
  File "/usr/local/lib/python3.5/dist-packages/django/template/context.py", line 274, in make_context
    raise TypeError('context must be a dict rather than %s.' % context.__class__.__name__)
TypeError: context must be a dict rather than list.
WARNING:django.security.SuspiciousSession:Session data corrupted
WARNING:django.security.SuspiciousSession:Session data corrupted
WARNING:django.security.SuspiciousSession:Session data corrupted
WARNING:django.request:Not Found: /favicon.ico
WARNING:django.request:Not Found: /user/1/orders/
INFO:root:Show orders
INFO:root:Show orders
INFO:root:Show order details
ERROR:django.request:Internal Server Error: /login/
Traceback (most recent call last):
  File "/usr/local/lib/python3.5/dist-packages/django/core/handlers/exception.py", line 35, in inner
    response = get_response(request)
  File "/usr/local/lib/python3.5/dist-packages/django/core/handlers/base.py", line 158, in _get_response
    response = self.process_exception_by_middleware(e, request)
  File "/usr/local/lib/python3.5/dist-packages/django/core/handlers/base.py", line 156, in _get_response
    response = response.render()
  File "/usr/local/lib/python3.5/dist-packages/django/template/response.py", line 106, in render
    self.content = self.rendered_content
  File "/usr/local/lib/python3.5/dist-packages/django/template/response.py", line 81, in rendered_content
    template = self.resolve_template(self.template_name)
  File "/usr/local/lib/python3.5/dist-packages/django/template/response.py", line 63, in resolve_template
    return select_template(template, using=self.using)
  File "/usr/local/lib/python3.5/dist-packages/django/template/loader.py", line 47, in select_template
    raise TemplateDoesNotExist(', '.join(template_name_list), chain=chain)
django.template.exceptions.TemplateDoesNotExist: registration/login.html
ERROR:django.request:Internal Server Error: /login/
Traceback (most recent call last):
  File "/usr/local/lib/python3.5/dist-packages/django/core/handlers/exception.py", line 35, in inner
    response = get_response(request)
  File "/usr/local/lib/python3.5/dist-packages/django/core/handlers/base.py", line 158, in _get_response
    response = self.process_exception_by_middleware(e, request)
  File "/usr/local/lib/python3.5/dist-packages/django/core/handlers/base.py", line 156, in _get_response
    response = response.render()
  File "/usr/local/lib/python3.5/dist-packages/django/template/response.py", line 106, in render
    self.content = self.rendered_content
  File "/usr/local/lib/python3.5/dist-packages/django/template/response.py", line 81, in rendered_content
    template = self.resolve_template(self.template_name)
  File "/usr/local/lib/python3.5/dist-packages/django/template/response.py", line 63, in resolve_template
    return select_template(template, using=self.using)
  File "/usr/local/lib/python3.5/dist-packages/django/template/loader.py", line 47, in select_template
    raise TemplateDoesNotExist(', '.join(template_name_list), chain=chain)
django.template.exceptions.TemplateDoesNotExist: registration/login.html
ERROR:django.request:Internal Server Error: /login/
Traceback (most recent call last):
  File "/usr/local/lib/python3.5/dist-packages/django/template/backends/django.py", line 61, in render
    return self.template.render(context)
  File "/usr/local/lib/python3.5/dist-packages/django/template/base.py", line 175, in render
    return self._render(context)
  File "/usr/local/lib/python3.5/dist-packages/django/template/base.py", line 167, in _render
    return self.nodelist.render(context)
  File "/usr/local/lib/python3.5/dist-packages/django/template/base.py", line 943, in render
    bit = node.render_annotated(context)
  File "/usr/local/lib/python3.5/dist-packages/django/template/base.py", line 910, in render_annotated
    return self.render(context)
  File "/usr/local/lib/python3.5/dist-packages/django/template/loader_tags.py", line 132, in render
    compiled_parent = self.get_parent(context)
  File "/usr/local/lib/python3.5/dist-packages/django/template/loader_tags.py", line 129, in get_parent
    return self.find_template(parent, context)
  File "/usr/local/lib/python3.5/dist-packages/django/template/loader_tags.py", line 109, in find_template
    template_name, skip=history,
  File "/usr/local/lib/python3.5/dist-packages/django/template/engine.py", line 130, in find_template
    raise TemplateDoesNotExist(name, tried=tried)
django.template.exceptions.TemplateDoesNotExist: base.html

The above exception was the direct cause of the following exception:

Traceback (most recent call last):
  File "/usr/local/lib/python3.5/dist-packages/django/core/handlers/exception.py", line 35, in inner
    response = get_response(request)
  File "/usr/local/lib/python3.5/dist-packages/django/core/handlers/base.py", line 158, in _get_response
    response = self.process_exception_by_middleware(e, request)
  File "/usr/local/lib/python3.5/dist-packages/django/core/handlers/base.py", line 156, in _get_response
    response = response.render()
  File "/usr/local/lib/python3.5/dist-packages/django/template/response.py", line 106, in render
    self.content = self.rendered_content
  File "/usr/local/lib/python3.5/dist-packages/django/template/response.py", line 83, in rendered_content
    content = template.render(context, self._request)
  File "/usr/local/lib/python3.5/dist-packages/django/template/backends/django.py", line 63, in render
    reraise(exc, self.backend)
  File "/usr/local/lib/python3.5/dist-packages/django/template/backends/django.py", line 84, in reraise
    raise new from exc
django.template.exceptions.TemplateDoesNotExist: base.html
WARNING:django.request:Not Found: /accounts/profile/
ERROR:django.request:Internal Server Error: /
Traceback (most recent call last):
  File "/usr/local/lib/python3.5/dist-packages/django/core/handlers/exception.py", line 35, in inner
    response = get_response(request)
  File "/usr/local/lib/python3.5/dist-packages/django/core/handlers/base.py", line 128, in _get_response
    response = self.process_exception_by_middleware(e, request)
  File "/usr/local/lib/python3.5/dist-packages/django/core/handlers/base.py", line 126, in _get_response
    response = wrapped_callback(request, *callback_args, **callback_kwargs)
  File "/usr/local/lib/python3.5/dist-packages/django/views/decorators/csrf.py", line 54, in wrapped_view
    return view_func(*args, **kwargs)
  File "/usr/local/lib/python3.5/dist-packages/django/views/generic/base.py", line 69, in view
    return self.dispatch(request, *args, **kwargs)
  File "/usr/local/lib/python3.5/dist-packages/django/utils/decorators.py", line 62, in _wrapper
    return bound_func(*args, **kwargs)
  File "/usr/local/lib/python3.5/dist-packages/django/views/decorators/csrf.py", line 54, in wrapped_view
    return view_func(*args, **kwargs)
  File "/usr/local/lib/python3.5/dist-packages/django/utils/decorators.py", line 58, in bound_func
    return func.__get__(self, type(self))(*args2, **kwargs2)
  File "/usr/local/lib/python3.5/dist-packages/braces/views/_forms.py", line 24, in dispatch
    return super(CsrfExemptMixin, self).dispatch(*args, **kwargs)
  File "/usr/local/lib/python3.5/dist-packages/rest_framework/views.py", line 494, in dispatch
    response = self.handle_exception(exc)
  File "/usr/local/lib/python3.5/dist-packages/rest_framework/views.py", line 454, in handle_exception
    self.raise_uncaught_exception(exc)
  File "/usr/local/lib/python3.5/dist-packages/rest_framework/views.py", line 491, in dispatch
    response = handler(request, *args, **kwargs)
  File "/home/sanya/Documents/Git/rsoi_2lab/rsoi_2lab/ag_service/aggregator/views.py", line 42, in post
    return render(request, 'index.html', {'error':r.json()})
  File "/usr/local/lib/python3.5/dist-packages/requests/models.py", line 892, in json
    return complexjson.loads(self.text, **kwargs)
  File "/usr/lib/python3.5/json/__init__.py", line 319, in loads
    return _default_decoder.decode(s)
  File "/usr/lib/python3.5/json/decoder.py", line 339, in decode
    obj, end = self.raw_decode(s, idx=_w(s, 0).end())
  File "/usr/lib/python3.5/json/decoder.py", line 357, in raw_decode
    raise JSONDecodeError("Expecting value", s, err.value) from None
json.decoder.JSONDecodeError: Expecting value: line 1 column 1 (char 0)
ERROR:django.request:Internal Server Error: /
Traceback (most recent call last):
  File "/usr/local/lib/python3.5/dist-packages/django/core/handlers/exception.py", line 35, in inner
    response = get_response(request)
  File "/usr/local/lib/python3.5/dist-packages/django/core/handlers/base.py", line 128, in _get_response
    response = self.process_exception_by_middleware(e, request)
  File "/usr/local/lib/python3.5/dist-packages/django/core/handlers/base.py", line 126, in _get_response
    response = wrapped_callback(request, *callback_args, **callback_kwargs)
  File "/usr/local/lib/python3.5/dist-packages/django/views/decorators/csrf.py", line 54, in wrapped_view
    return view_func(*args, **kwargs)
  File "/usr/local/lib/python3.5/dist-packages/django/views/generic/base.py", line 69, in view
    return self.dispatch(request, *args, **kwargs)
  File "/usr/local/lib/python3.5/dist-packages/django/utils/decorators.py", line 62, in _wrapper
    return bound_func(*args, **kwargs)
  File "/usr/local/lib/python3.5/dist-packages/django/views/decorators/csrf.py", line 54, in wrapped_view
    return view_func(*args, **kwargs)
  File "/usr/local/lib/python3.5/dist-packages/django/utils/decorators.py", line 58, in bound_func
    return func.__get__(self, type(self))(*args2, **kwargs2)
  File "/usr/local/lib/python3.5/dist-packages/braces/views/_forms.py", line 24, in dispatch
    return super(CsrfExemptMixin, self).dispatch(*args, **kwargs)
  File "/usr/local/lib/python3.5/dist-packages/rest_framework/views.py", line 494, in dispatch
    response = self.handle_exception(exc)
  File "/usr/local/lib/python3.5/dist-packages/rest_framework/views.py", line 454, in handle_exception
    self.raise_uncaught_exception(exc)
  File "/usr/local/lib/python3.5/dist-packages/rest_framework/views.py", line 491, in dispatch
    response = handler(request, *args, **kwargs)
  File "/home/sanya/Documents/Git/rsoi_2lab/rsoi_2lab/ag_service/aggregator/views.py", line 42, in post
    return render(request, 'index.html', {'error':r.json()})
  File "/usr/local/lib/python3.5/dist-packages/requests/models.py", line 892, in json
    return complexjson.loads(self.text, **kwargs)
  File "/usr/lib/python3.5/json/__init__.py", line 319, in loads
    return _default_decoder.decode(s)
  File "/usr/lib/python3.5/json/decoder.py", line 339, in decode
    obj, end = self.raw_decode(s, idx=_w(s, 0).end())
  File "/usr/lib/python3.5/json/decoder.py", line 357, in raw_decode
    raise JSONDecodeError("Expecting value", s, err.value) from None
json.decoder.JSONDecodeError: Expecting value: line 1 column 1 (char 0)
WARNING:django.request:Not Found: /accounts/profile/
ERROR:django.request:Internal Server Error: /
Traceback (most recent call last):
  File "/usr/local/lib/python3.5/dist-packages/django/core/handlers/exception.py", line 35, in inner
    response = get_response(request)
  File "/usr/local/lib/python3.5/dist-packages/django/core/handlers/base.py", line 128, in _get_response
    response = self.process_exception_by_middleware(e, request)
  File "/usr/local/lib/python3.5/dist-packages/django/core/handlers/base.py", line 126, in _get_response
    response = wrapped_callback(request, *callback_args, **callback_kwargs)
  File "/usr/local/lib/python3.5/dist-packages/django/views/decorators/csrf.py", line 54, in wrapped_view
    return view_func(*args, **kwargs)
  File "/usr/local/lib/python3.5/dist-packages/django/views/generic/base.py", line 69, in view
    return self.dispatch(request, *args, **kwargs)
  File "/usr/local/lib/python3.5/dist-packages/django/utils/decorators.py", line 62, in _wrapper
    return bound_func(*args, **kwargs)
  File "/usr/local/lib/python3.5/dist-packages/django/views/decorators/csrf.py", line 54, in wrapped_view
    return view_func(*args, **kwargs)
  File "/usr/local/lib/python3.5/dist-packages/django/utils/decorators.py", line 58, in bound_func
    return func.__get__(self, type(self))(*args2, **kwargs2)
  File "/usr/local/lib/python3.5/dist-packages/braces/views/_forms.py", line 24, in dispatch
    return super(CsrfExemptMixin, self).dispatch(*args, **kwargs)
  File "/usr/local/lib/python3.5/dist-packages/rest_framework/views.py", line 494, in dispatch
    response = self.handle_exception(exc)
  File "/usr/local/lib/python3.5/dist-packages/rest_framework/views.py", line 454, in handle_exception
    self.raise_uncaught_exception(exc)
  File "/usr/local/lib/python3.5/dist-packages/rest_framework/views.py", line 491, in dispatch
    response = handler(request, *args, **kwargs)
  File "/home/sanya/Documents/Git/rsoi_2lab/rsoi_2lab/ag_service/aggregator/views.py", line 42, in post
    return render(request, 'index.html', {'error':r.json()})
  File "/usr/local/lib/python3.5/dist-packages/requests/models.py", line 892, in json
    return complexjson.loads(self.text, **kwargs)
  File "/usr/lib/python3.5/json/__init__.py", line 319, in loads
    return _default_decoder.decode(s)
  File "/usr/lib/python3.5/json/decoder.py", line 339, in decode
    obj, end = self.raw_decode(s, idx=_w(s, 0).end())
  File "/usr/lib/python3.5/json/decoder.py", line 357, in raw_decode
    raise JSONDecodeError("Expecting value", s, err.value) from None
json.decoder.JSONDecodeError: Expecting value: line 1 column 1 (char 0)
ERROR:django.request:Internal Server Error: /
Traceback (most recent call last):
  File "/usr/local/lib/python3.5/dist-packages/django/core/handlers/exception.py", line 35, in inner
    response = get_response(request)
  File "/usr/local/lib/python3.5/dist-packages/django/core/handlers/base.py", line 128, in _get_response
    response = self.process_exception_by_middleware(e, request)
  File "/usr/local/lib/python3.5/dist-packages/django/core/handlers/base.py", line 126, in _get_response
    response = wrapped_callback(request, *callback_args, **callback_kwargs)
  File "/usr/local/lib/python3.5/dist-packages/django/views/decorators/csrf.py", line 54, in wrapped_view
    return view_func(*args, **kwargs)
  File "/usr/local/lib/python3.5/dist-packages/django/views/generic/base.py", line 69, in view
    return self.dispatch(request, *args, **kwargs)
  File "/usr/local/lib/python3.5/dist-packages/django/utils/decorators.py", line 62, in _wrapper
    return bound_func(*args, **kwargs)
  File "/usr/local/lib/python3.5/dist-packages/django/views/decorators/csrf.py", line 54, in wrapped_view
    return view_func(*args, **kwargs)
  File "/usr/local/lib/python3.5/dist-packages/django/utils/decorators.py", line 58, in bound_func
    return func.__get__(self, type(self))(*args2, **kwargs2)
  File "/usr/local/lib/python3.5/dist-packages/braces/views/_forms.py", line 24, in dispatch
    return super(CsrfExemptMixin, self).dispatch(*args, **kwargs)
  File "/usr/local/lib/python3.5/dist-packages/rest_framework/views.py", line 496, in dispatch
    self.response = self.finalize_response(request, response, *args, **kwargs)
  File "/usr/local/lib/python3.5/dist-packages/rest_framework/views.py", line 411, in finalize_response
    % type(response)
AssertionError: Expected a `Response`, `HttpResponse` or `HttpStreamingResponse` to be returned from the view, but received a `<class 'NoneType'>`
WARNING:django.request:Not Found: /login/
WARNING:django.request:Not Found: /accounts/profile/
ERROR:django.request:Internal Server Error: /
Traceback (most recent call last):
  File "/usr/local/lib/python3.5/dist-packages/django/core/handlers/exception.py", line 35, in inner
    response = get_response(request)
  File "/usr/local/lib/python3.5/dist-packages/django/core/handlers/base.py", line 128, in _get_response
    response = self.process_exception_by_middleware(e, request)
  File "/usr/local/lib/python3.5/dist-packages/django/core/handlers/base.py", line 126, in _get_response
    response = wrapped_callback(request, *callback_args, **callback_kwargs)
  File "/usr/local/lib/python3.5/dist-packages/django/views/decorators/csrf.py", line 54, in wrapped_view
    return view_func(*args, **kwargs)
  File "/usr/local/lib/python3.5/dist-packages/django/views/generic/base.py", line 69, in view
    return self.dispatch(request, *args, **kwargs)
  File "/usr/local/lib/python3.5/dist-packages/django/utils/decorators.py", line 62, in _wrapper
    return bound_func(*args, **kwargs)
  File "/usr/local/lib/python3.5/dist-packages/django/views/decorators/csrf.py", line 54, in wrapped_view
    return view_func(*args, **kwargs)
  File "/usr/local/lib/python3.5/dist-packages/django/utils/decorators.py", line 58, in bound_func
    return func.__get__(self, type(self))(*args2, **kwargs2)
  File "/usr/local/lib/python3.5/dist-packages/braces/views/_forms.py", line 24, in dispatch
    return super(CsrfExemptMixin, self).dispatch(*args, **kwargs)
  File "/usr/local/lib/python3.5/dist-packages/rest_framework/views.py", line 496, in dispatch
    self.response = self.finalize_response(request, response, *args, **kwargs)
  File "/usr/local/lib/python3.5/dist-packages/rest_framework/views.py", line 411, in finalize_response
    % type(response)
AssertionError: Expected a `Response`, `HttpResponse` or `HttpStreamingResponse` to be returned from the view, but received a `<class 'NoneType'>`
ERROR:django.request:Internal Server Error: /
Traceback (most recent call last):
  File "/usr/local/lib/python3.5/dist-packages/django/core/handlers/exception.py", line 35, in inner
    response = get_response(request)
  File "/usr/local/lib/python3.5/dist-packages/django/core/handlers/base.py", line 128, in _get_response
    response = self.process_exception_by_middleware(e, request)
  File "/usr/local/lib/python3.5/dist-packages/django/core/handlers/base.py", line 126, in _get_response
    response = wrapped_callback(request, *callback_args, **callback_kwargs)
  File "/usr/local/lib/python3.5/dist-packages/django/views/decorators/csrf.py", line 54, in wrapped_view
    return view_func(*args, **kwargs)
  File "/usr/local/lib/python3.5/dist-packages/django/views/generic/base.py", line 69, in view
    return self.dispatch(request, *args, **kwargs)
  File "/usr/local/lib/python3.5/dist-packages/django/utils/decorators.py", line 62, in _wrapper
    return bound_func(*args, **kwargs)
  File "/usr/local/lib/python3.5/dist-packages/django/views/decorators/csrf.py", line 54, in wrapped_view
    return view_func(*args, **kwargs)
  File "/usr/local/lib/python3.5/dist-packages/django/utils/decorators.py", line 58, in bound_func
    return func.__get__(self, type(self))(*args2, **kwargs2)
  File "/usr/local/lib/python3.5/dist-packages/braces/views/_forms.py", line 24, in dispatch
    return super(CsrfExemptMixin, self).dispatch(*args, **kwargs)
  File "/usr/local/lib/python3.5/dist-packages/rest_framework/views.py", line 496, in dispatch
    self.response = self.finalize_response(request, response, *args, **kwargs)
  File "/usr/local/lib/python3.5/dist-packages/rest_framework/views.py", line 411, in finalize_response
    % type(response)
AssertionError: Expected a `Response`, `HttpResponse` or `HttpStreamingResponse` to be returned from the view, but received a `<class 'NoneType'>`
ERROR:django.request:Internal Server Error: /
Traceback (most recent call last):
  File "/usr/local/lib/python3.5/dist-packages/django/core/handlers/exception.py", line 35, in inner
    response = get_response(request)
  File "/usr/local/lib/python3.5/dist-packages/django/core/handlers/base.py", line 128, in _get_response
    response = self.process_exception_by_middleware(e, request)
  File "/usr/local/lib/python3.5/dist-packages/django/core/handlers/base.py", line 126, in _get_response
    response = wrapped_callback(request, *callback_args, **callback_kwargs)
  File "/usr/local/lib/python3.5/dist-packages/django/views/decorators/csrf.py", line 54, in wrapped_view
    return view_func(*args, **kwargs)
  File "/usr/local/lib/python3.5/dist-packages/django/views/generic/base.py", line 69, in view
    return self.dispatch(request, *args, **kwargs)
  File "/usr/local/lib/python3.5/dist-packages/django/utils/decorators.py", line 62, in _wrapper
    return bound_func(*args, **kwargs)
  File "/usr/local/lib/python3.5/dist-packages/django/views/decorators/csrf.py", line 54, in wrapped_view
    return view_func(*args, **kwargs)
  File "/usr/local/lib/python3.5/dist-packages/django/utils/decorators.py", line 58, in bound_func
    return func.__get__(self, type(self))(*args2, **kwargs2)
  File "/usr/local/lib/python3.5/dist-packages/braces/views/_forms.py", line 24, in dispatch
    return super(CsrfExemptMixin, self).dispatch(*args, **kwargs)
  File "/usr/local/lib/python3.5/dist-packages/rest_framework/views.py", line 494, in dispatch
    response = self.handle_exception(exc)
  File "/usr/local/lib/python3.5/dist-packages/rest_framework/views.py", line 454, in handle_exception
    self.raise_uncaught_exception(exc)
  File "/usr/local/lib/python3.5/dist-packages/rest_framework/views.py", line 491, in dispatch
    response = handler(request, *args, **kwargs)
  File "/home/sanya/Documents/Git/rsoi_2lab/rsoi_2lab/ag_service/aggregator/views.py", line 42, in post
    return HttpResponse(r.json())
  File "/usr/local/lib/python3.5/dist-packages/requests/models.py", line 892, in json
    return complexjson.loads(self.text, **kwargs)
  File "/usr/lib/python3.5/json/__init__.py", line 319, in loads
    return _default_decoder.decode(s)
  File "/usr/lib/python3.5/json/decoder.py", line 339, in decode
    obj, end = self.raw_decode(s, idx=_w(s, 0).end())
  File "/usr/lib/python3.5/json/decoder.py", line 357, in raw_decode
    raise JSONDecodeError("Expecting value", s, err.value) from None
json.decoder.JSONDecodeError: Expecting value: line 1 column 1 (char 0)
WARNING:django.security.csrf:Forbidden (CSRF token missing or incorrect.): /auth/
ERROR:django.request:Internal Server Error: /auth/
Traceback (most recent call last):
  File "/usr/local/lib/python3.5/dist-packages/rest_framework/request.py", line 410, in __getattr__
    return getattr(self._request, attr)
AttributeError: 'WSGIRequest' object has no attribute 'text'

During handling of the above exception, another exception occurred:

Traceback (most recent call last):
  File "/usr/local/lib/python3.5/dist-packages/django/core/handlers/exception.py", line 35, in inner
    response = get_response(request)
  File "/usr/local/lib/python3.5/dist-packages/django/core/handlers/base.py", line 128, in _get_response
    response = self.process_exception_by_middleware(e, request)
  File "/usr/local/lib/python3.5/dist-packages/django/core/handlers/base.py", line 126, in _get_response
    response = wrapped_callback(request, *callback_args, **callback_kwargs)
  File "/usr/local/lib/python3.5/dist-packages/django/views/decorators/csrf.py", line 54, in wrapped_view
    return view_func(*args, **kwargs)
  File "/usr/local/lib/python3.5/dist-packages/django/views/generic/base.py", line 69, in view
    return self.dispatch(request, *args, **kwargs)
  File "/usr/local/lib/python3.5/dist-packages/django/utils/decorators.py", line 62, in _wrapper
    return bound_func(*args, **kwargs)
  File "/usr/local/lib/python3.5/dist-packages/django/views/decorators/csrf.py", line 54, in wrapped_view
    return view_func(*args, **kwargs)
  File "/usr/local/lib/python3.5/dist-packages/django/utils/decorators.py", line 58, in bound_func
    return func.__get__(self, type(self))(*args2, **kwargs2)
  File "/usr/local/lib/python3.5/dist-packages/braces/views/_forms.py", line 24, in dispatch
    return super(CsrfExemptMixin, self).dispatch(*args, **kwargs)
  File "/usr/local/lib/python3.5/dist-packages/rest_framework/views.py", line 494, in dispatch
    response = self.handle_exception(exc)
  File "/usr/local/lib/python3.5/dist-packages/rest_framework/views.py", line 454, in handle_exception
    self.raise_uncaught_exception(exc)
  File "/usr/local/lib/python3.5/dist-packages/rest_framework/views.py", line 491, in dispatch
    response = handler(request, *args, **kwargs)
  File "/home/sanya/Documents/Git/rsoi_2lab/rsoi_2lab/ag_service/aggregator/views.py", line 48, in post
    print(request.text)
  File "/usr/local/lib/python3.5/dist-packages/rest_framework/request.py", line 412, in __getattr__
    return self.__getattribute__(attr)
AttributeError: 'Request' object has no attribute 'text'
ERROR:django.request:Internal Server Error: /auth/
Traceback (most recent call last):
  File "/usr/local/lib/python3.5/dist-packages/rest_framework/request.py", line 410, in __getattr__
    return getattr(self._request, attr)
AttributeError: 'WSGIRequest' object has no attribute 'json'

During handling of the above exception, another exception occurred:

Traceback (most recent call last):
  File "/usr/local/lib/python3.5/dist-packages/django/core/handlers/exception.py", line 35, in inner
    response = get_response(request)
  File "/usr/local/lib/python3.5/dist-packages/django/core/handlers/base.py", line 128, in _get_response
    response = self.process_exception_by_middleware(e, request)
  File "/usr/local/lib/python3.5/dist-packages/django/core/handlers/base.py", line 126, in _get_response
    response = wrapped_callback(request, *callback_args, **callback_kwargs)
  File "/usr/local/lib/python3.5/dist-packages/django/views/decorators/csrf.py", line 54, in wrapped_view
    return view_func(*args, **kwargs)
  File "/usr/local/lib/python3.5/dist-packages/django/views/generic/base.py", line 69, in view
    return self.dispatch(request, *args, **kwargs)
  File "/usr/local/lib/python3.5/dist-packages/django/utils/decorators.py", line 62, in _wrapper
    return bound_func(*args, **kwargs)
  File "/usr/local/lib/python3.5/dist-packages/django/views/decorators/csrf.py", line 54, in wrapped_view
    return view_func(*args, **kwargs)
  File "/usr/local/lib/python3.5/dist-packages/django/utils/decorators.py", line 58, in bound_func
    return func.__get__(self, type(self))(*args2, **kwargs2)
  File "/usr/local/lib/python3.5/dist-packages/braces/views/_forms.py", line 24, in dispatch
    return super(CsrfExemptMixin, self).dispatch(*args, **kwargs)
  File "/usr/local/lib/python3.5/dist-packages/rest_framework/views.py", line 494, in dispatch
    response = self.handle_exception(exc)
  File "/usr/local/lib/python3.5/dist-packages/rest_framework/views.py", line 454, in handle_exception
    self.raise_uncaught_exception(exc)
  File "/usr/local/lib/python3.5/dist-packages/rest_framework/views.py", line 491, in dispatch
    response = handler(request, *args, **kwargs)
  File "/home/sanya/Documents/Git/rsoi_2lab/rsoi_2lab/ag_service/aggregator/views.py", line 48, in post
    print(request.json())
  File "/usr/local/lib/python3.5/dist-packages/rest_framework/request.py", line 412, in __getattr__
    return self.__getattribute__(attr)
AttributeError: 'Request' object has no attribute 'json'
ERROR:django.request:Internal Server Error: /
Traceback (most recent call last):
  File "/usr/local/lib/python3.5/dist-packages/django/core/handlers/exception.py", line 35, in inner
    response = get_response(request)
  File "/usr/local/lib/python3.5/dist-packages/django/core/handlers/base.py", line 128, in _get_response
    response = self.process_exception_by_middleware(e, request)
  File "/usr/local/lib/python3.5/dist-packages/django/core/handlers/base.py", line 126, in _get_response
    response = wrapped_callback(request, *callback_args, **callback_kwargs)
  File "/usr/local/lib/python3.5/dist-packages/django/views/decorators/csrf.py", line 54, in wrapped_view
    return view_func(*args, **kwargs)
  File "/usr/local/lib/python3.5/dist-packages/django/views/generic/base.py", line 69, in view
    return self.dispatch(request, *args, **kwargs)
  File "/usr/local/lib/python3.5/dist-packages/django/utils/decorators.py", line 62, in _wrapper
    return bound_func(*args, **kwargs)
  File "/usr/local/lib/python3.5/dist-packages/django/views/decorators/csrf.py", line 54, in wrapped_view
    return view_func(*args, **kwargs)
  File "/usr/local/lib/python3.5/dist-packages/django/utils/decorators.py", line 58, in bound_func
    return func.__get__(self, type(self))(*args2, **kwargs2)
  File "/usr/local/lib/python3.5/dist-packages/braces/views/_forms.py", line 24, in dispatch
    return super(CsrfExemptMixin, self).dispatch(*args, **kwargs)
  File "/usr/local/lib/python3.5/dist-packages/rest_framework/views.py", line 494, in dispatch
    response = self.handle_exception(exc)
  File "/usr/local/lib/python3.5/dist-packages/rest_framework/views.py", line 454, in handle_exception
    self.raise_uncaught_exception(exc)
  File "/usr/local/lib/python3.5/dist-packages/rest_framework/views.py", line 491, in dispatch
    response = handler(request, *args, **kwargs)
  File "/home/sanya/Documents/Git/rsoi_2lab/rsoi_2lab/ag_service/aggregator/views.py", line 43, in post
    return redirect(r)
  File "/usr/local/lib/python3.5/dist-packages/django/shortcuts.py", line 58, in redirect
    return redirect_class(resolve_url(to, *args, **kwargs))
  File "/usr/local/lib/python3.5/dist-packages/django/shortcuts.py", line 149, in resolve_url
    return reverse(to, args=args, kwargs=kwargs)
  File "/usr/local/lib/python3.5/dist-packages/django/urls/base.py", line 88, in reverse
    return iri_to_uri(resolver._reverse_with_prefix(view, prefix, *args, **kwargs))
  File "/usr/local/lib/python3.5/dist-packages/django/urls/resolvers.py", line 632, in _reverse_with_prefix
    raise NoReverseMatch(msg)
django.urls.exceptions.NoReverseMatch: Reverse for '<Response [200]>' not found. '<Response [200]>' is not a valid view function or pattern name.
ERROR:django.request:Internal Server Error: /auth/
Traceback (most recent call last):
  File "/usr/local/lib/python3.5/dist-packages/django/core/handlers/exception.py", line 35, in inner
    response = get_response(request)
  File "/usr/local/lib/python3.5/dist-packages/django/core/handlers/base.py", line 128, in _get_response
    response = self.process_exception_by_middleware(e, request)
  File "/usr/local/lib/python3.5/dist-packages/django/core/handlers/base.py", line 126, in _get_response
    response = wrapped_callback(request, *callback_args, **callback_kwargs)
  File "/usr/local/lib/python3.5/dist-packages/django/views/decorators/csrf.py", line 54, in wrapped_view
    return view_func(*args, **kwargs)
  File "/usr/local/lib/python3.5/dist-packages/django/views/generic/base.py", line 69, in view
    return self.dispatch(request, *args, **kwargs)
  File "/usr/local/lib/python3.5/dist-packages/django/utils/decorators.py", line 62, in _wrapper
    return bound_func(*args, **kwargs)
  File "/usr/local/lib/python3.5/dist-packages/django/views/decorators/csrf.py", line 54, in wrapped_view
    return view_func(*args, **kwargs)
  File "/usr/local/lib/python3.5/dist-packages/django/utils/decorators.py", line 58, in bound_func
    return func.__get__(self, type(self))(*args2, **kwargs2)
  File "/usr/local/lib/python3.5/dist-packages/braces/views/_forms.py", line 24, in dispatch
    return super(CsrfExemptMixin, self).dispatch(*args, **kwargs)
  File "/usr/local/lib/python3.5/dist-packages/rest_framework/views.py", line 494, in dispatch
    response = self.handle_exception(exc)
  File "/usr/local/lib/python3.5/dist-packages/rest_framework/views.py", line 454, in handle_exception
    self.raise_uncaught_exception(exc)
  File "/usr/local/lib/python3.5/dist-packages/rest_framework/views.py", line 491, in dispatch
    response = handler(request, *args, **kwargs)
  File "/home/sanya/Documents/Git/rsoi_2lab/rsoi_2lab/ag_service/aggregator/views.py", line 51, in get
    print(requests.Get.get('code'))
AttributeError: module 'requests' has no attribute 'Get'
ERROR:django.request:Internal Server Error: /auth/
Traceback (most recent call last):
  File "/usr/local/lib/python3.5/dist-packages/rest_framework/request.py", line 410, in __getattr__
    return getattr(self._request, attr)
AttributeError: 'WSGIRequest' object has no attribute 'Get'

During handling of the above exception, another exception occurred:

Traceback (most recent call last):
  File "/usr/local/lib/python3.5/dist-packages/django/core/handlers/exception.py", line 35, in inner
    response = get_response(request)
  File "/usr/local/lib/python3.5/dist-packages/django/core/handlers/base.py", line 128, in _get_response
    response = self.process_exception_by_middleware(e, request)
  File "/usr/local/lib/python3.5/dist-packages/django/core/handlers/base.py", line 126, in _get_response
    response = wrapped_callback(request, *callback_args, **callback_kwargs)
  File "/usr/local/lib/python3.5/dist-packages/django/views/decorators/csrf.py", line 54, in wrapped_view
    return view_func(*args, **kwargs)
  File "/usr/local/lib/python3.5/dist-packages/django/views/generic/base.py", line 69, in view
    return self.dispatch(request, *args, **kwargs)
  File "/usr/local/lib/python3.5/dist-packages/django/utils/decorators.py", line 62, in _wrapper
    return bound_func(*args, **kwargs)
  File "/usr/local/lib/python3.5/dist-packages/django/views/decorators/csrf.py", line 54, in wrapped_view
    return view_func(*args, **kwargs)
  File "/usr/local/lib/python3.5/dist-packages/django/utils/decorators.py", line 58, in bound_func
    return func.__get__(self, type(self))(*args2, **kwargs2)
  File "/usr/local/lib/python3.5/dist-packages/braces/views/_forms.py", line 24, in dispatch
    return super(CsrfExemptMixin, self).dispatch(*args, **kwargs)
  File "/usr/local/lib/python3.5/dist-packages/rest_framework/views.py", line 494, in dispatch
    response = self.handle_exception(exc)
  File "/usr/local/lib/python3.5/dist-packages/rest_framework/views.py", line 454, in handle_exception
    self.raise_uncaught_exception(exc)
  File "/usr/local/lib/python3.5/dist-packages/rest_framework/views.py", line 491, in dispatch
    response = handler(request, *args, **kwargs)
  File "/home/sanya/Documents/Git/rsoi_2lab/rsoi_2lab/ag_service/aggregator/views.py", line 51, in get
    print(request.Get.get('code'))
  File "/usr/local/lib/python3.5/dist-packages/rest_framework/request.py", line 412, in __getattr__
    return self.__getattribute__(attr)
AttributeError: 'Request' object has no attribute 'Get'
ERROR:django.request:Internal Server Error: /auth/
Traceback (most recent call last):
  File "/usr/local/lib/python3.5/dist-packages/rest_framework/request.py", line 410, in __getattr__
    return getattr(self._request, attr)
AttributeError: 'WSGIRequest' object has no attribute 'Get'

During handling of the above exception, another exception occurred:

Traceback (most recent call last):
  File "/usr/local/lib/python3.5/dist-packages/django/core/handlers/exception.py", line 35, in inner
    response = get_response(request)
  File "/usr/local/lib/python3.5/dist-packages/django/core/handlers/base.py", line 128, in _get_response
    response = self.process_exception_by_middleware(e, request)
  File "/usr/local/lib/python3.5/dist-packages/django/core/handlers/base.py", line 126, in _get_response
    response = wrapped_callback(request, *callback_args, **callback_kwargs)
  File "/usr/local/lib/python3.5/dist-packages/django/views/decorators/csrf.py", line 54, in wrapped_view
    return view_func(*args, **kwargs)
  File "/usr/local/lib/python3.5/dist-packages/django/views/generic/base.py", line 69, in view
    return self.dispatch(request, *args, **kwargs)
  File "/usr/local/lib/python3.5/dist-packages/django/utils/decorators.py", line 62, in _wrapper
    return bound_func(*args, **kwargs)
  File "/usr/local/lib/python3.5/dist-packages/django/views/decorators/csrf.py", line 54, in wrapped_view
    return view_func(*args, **kwargs)
  File "/usr/local/lib/python3.5/dist-packages/django/utils/decorators.py", line 58, in bound_func
    return func.__get__(self, type(self))(*args2, **kwargs2)
  File "/usr/local/lib/python3.5/dist-packages/braces/views/_forms.py", line 24, in dispatch
    return super(CsrfExemptMixin, self).dispatch(*args, **kwargs)
  File "/usr/local/lib/python3.5/dist-packages/rest_framework/views.py", line 494, in dispatch
    response = self.handle_exception(exc)
  File "/usr/local/lib/python3.5/dist-packages/rest_framework/views.py", line 454, in handle_exception
    self.raise_uncaught_exception(exc)
  File "/usr/local/lib/python3.5/dist-packages/rest_framework/views.py", line 491, in dispatch
    response = handler(request, *args, **kwargs)
  File "/home/sanya/Documents/Git/rsoi_2lab/rsoi_2lab/ag_service/aggregator/views.py", line 52, in get
    return HttpResponse("Success" + request.Get.get('code'))
  File "/usr/local/lib/python3.5/dist-packages/rest_framework/request.py", line 412, in __getattr__
    return self.__getattribute__(attr)
AttributeError: 'Request' object has no attribute 'Get'
WARNING:django.request:Not Found: /auth/url_userauth2/
ERROR:django.request:Internal Server Error: /auth/
Traceback (most recent call last):
  File "/usr/local/lib/python3.5/dist-packages/django/core/handlers/exception.py", line 35, in inner
    response = get_response(request)
  File "/usr/local/lib/python3.5/dist-packages/django/core/handlers/base.py", line 128, in _get_response
    response = self.process_exception_by_middleware(e, request)
  File "/usr/local/lib/python3.5/dist-packages/django/core/handlers/base.py", line 126, in _get_response
    response = wrapped_callback(request, *callback_args, **callback_kwargs)
  File "/usr/local/lib/python3.5/dist-packages/django/views/decorators/csrf.py", line 54, in wrapped_view
    return view_func(*args, **kwargs)
  File "/usr/local/lib/python3.5/dist-packages/django/views/generic/base.py", line 69, in view
    return self.dispatch(request, *args, **kwargs)
  File "/usr/local/lib/python3.5/dist-packages/django/utils/decorators.py", line 62, in _wrapper
    return bound_func(*args, **kwargs)
  File "/usr/local/lib/python3.5/dist-packages/django/views/decorators/csrf.py", line 54, in wrapped_view
    return view_func(*args, **kwargs)
  File "/usr/local/lib/python3.5/dist-packages/django/utils/decorators.py", line 58, in bound_func
    return func.__get__(self, type(self))(*args2, **kwargs2)
  File "/usr/local/lib/python3.5/dist-packages/braces/views/_forms.py", line 24, in dispatch
    return super(CsrfExemptMixin, self).dispatch(*args, **kwargs)
  File "/usr/local/lib/python3.5/dist-packages/rest_framework/views.py", line 494, in dispatch
    response = self.handle_exception(exc)
  File "/usr/local/lib/python3.5/dist-packages/rest_framework/views.py", line 454, in handle_exception
    self.raise_uncaught_exception(exc)
  File "/usr/local/lib/python3.5/dist-packages/rest_framework/views.py", line 491, in dispatch
    response = handler(request, *args, **kwargs)
  File "/home/sanya/Documents/Git/rsoi_2lab/rsoi_2lab/ag_service/aggregator/views.py", line 41, in get
    print(r['access_token'])
TypeError: 'Response' object is not subscriptable
ERROR:django.request:Internal Server Error: /auth/
Traceback (most recent call last):
  File "/usr/local/lib/python3.5/dist-packages/django/core/handlers/exception.py", line 35, in inner
    response = get_response(request)
  File "/usr/local/lib/python3.5/dist-packages/django/core/handlers/base.py", line 128, in _get_response
    response = self.process_exception_by_middleware(e, request)
  File "/usr/local/lib/python3.5/dist-packages/django/core/handlers/base.py", line 126, in _get_response
    response = wrapped_callback(request, *callback_args, **callback_kwargs)
  File "/usr/local/lib/python3.5/dist-packages/django/views/decorators/csrf.py", line 54, in wrapped_view
    return view_func(*args, **kwargs)
  File "/usr/local/lib/python3.5/dist-packages/django/views/generic/base.py", line 69, in view
    return self.dispatch(request, *args, **kwargs)
  File "/usr/local/lib/python3.5/dist-packages/django/utils/decorators.py", line 62, in _wrapper
    return bound_func(*args, **kwargs)
  File "/usr/local/lib/python3.5/dist-packages/django/views/decorators/csrf.py", line 54, in wrapped_view
    return view_func(*args, **kwargs)
  File "/usr/local/lib/python3.5/dist-packages/django/utils/decorators.py", line 58, in bound_func
    return func.__get__(self, type(self))(*args2, **kwargs2)
  File "/usr/local/lib/python3.5/dist-packages/braces/views/_forms.py", line 24, in dispatch
    return super(CsrfExemptMixin, self).dispatch(*args, **kwargs)
  File "/usr/local/lib/python3.5/dist-packages/rest_framework/views.py", line 494, in dispatch
    response = self.handle_exception(exc)
  File "/usr/local/lib/python3.5/dist-packages/rest_framework/views.py", line 454, in handle_exception
    self.raise_uncaught_exception(exc)
  File "/usr/local/lib/python3.5/dist-packages/rest_framework/views.py", line 491, in dispatch
    response = handler(request, *args, **kwargs)
  File "/home/sanya/Documents/Git/rsoi_2lab/rsoi_2lab/ag_service/aggregator/views.py", line 44, in get
    r.set_cookie('access',r.json().get('access_token'))
AttributeError: 'Response' object has no attribute 'set_cookie'
ERROR:django.request:Internal Server Error: /auth/
Traceback (most recent call last):
  File "/usr/local/lib/python3.5/dist-packages/django/core/handlers/exception.py", line 35, in inner
    response = get_response(request)
  File "/usr/local/lib/python3.5/dist-packages/django/core/handlers/base.py", line 128, in _get_response
    response = self.process_exception_by_middleware(e, request)
  File "/usr/local/lib/python3.5/dist-packages/django/core/handlers/base.py", line 126, in _get_response
    response = wrapped_callback(request, *callback_args, **callback_kwargs)
  File "/usr/local/lib/python3.5/dist-packages/django/views/decorators/csrf.py", line 54, in wrapped_view
    return view_func(*args, **kwargs)
  File "/usr/local/lib/python3.5/dist-packages/django/views/generic/base.py", line 69, in view
    return self.dispatch(request, *args, **kwargs)
  File "/usr/local/lib/python3.5/dist-packages/django/utils/decorators.py", line 62, in _wrapper
    return bound_func(*args, **kwargs)
  File "/usr/local/lib/python3.5/dist-packages/django/views/decorators/csrf.py", line 54, in wrapped_view
    return view_func(*args, **kwargs)
  File "/usr/local/lib/python3.5/dist-packages/django/utils/decorators.py", line 58, in bound_func
    return func.__get__(self, type(self))(*args2, **kwargs2)
  File "/usr/local/lib/python3.5/dist-packages/braces/views/_forms.py", line 24, in dispatch
    return super(CsrfExemptMixin, self).dispatch(*args, **kwargs)
  File "/usr/local/lib/python3.5/dist-packages/rest_framework/views.py", line 494, in dispatch
    response = self.handle_exception(exc)
  File "/usr/local/lib/python3.5/dist-packages/rest_framework/views.py", line 454, in handle_exception
    self.raise_uncaught_exception(exc)
  File "/usr/local/lib/python3.5/dist-packages/rest_framework/views.py", line 491, in dispatch
    response = handler(request, *args, **kwargs)
  File "/home/sanya/Documents/Git/rsoi_2lab/rsoi_2lab/ag_service/aggregator/views.py", line 45, in get
    r1 = HttpResponseRedirect()
TypeError: __init__() missing 1 required positional argument: 'redirect_to'
ERROR:django.request:Internal Server Error: /auth/
Traceback (most recent call last):
  File "/home/sanya/Documents/Git/rsoi_2lab/rsoi_2lab/ag_service/aggregator/views.py", line 40, in get
    r.raise_for_status()
  File "/usr/local/lib/python3.5/dist-packages/requests/models.py", line 935, in raise_for_status
    raise HTTPError(http_error_msg, response=self)
requests.exceptions.HTTPError: 401 Client Error: Unauthorized for url: http://localhost:8002/o/token/?grant_type=authorization_code&client_id=OdDr0vDribM42njMOQwmakhGC1vXaTogVyipMHjK&client_secret=0RoojuHswkIMfhPLt38yo2jIyjZzf9NZunMR8hcVm0e6h2nJrTDDM607ZNpRjZud5hjuMEo5NOR80ZG6e4dVkVDkJdLLZblf5B8mKBCBQVNfuZqi92CGzeibqofvQh3v&code=iB0uiHoqXrqmgGSwXq9Dgxa0l42lnc&redirect_uri=http://localhost:8003/auth/

During handling of the above exception, another exception occurred:

Traceback (most recent call last):
  File "/usr/local/lib/python3.5/dist-packages/django/core/handlers/exception.py", line 35, in inner
    response = get_response(request)
  File "/usr/local/lib/python3.5/dist-packages/django/core/handlers/base.py", line 128, in _get_response
    response = self.process_exception_by_middleware(e, request)
  File "/usr/local/lib/python3.5/dist-packages/django/core/handlers/base.py", line 126, in _get_response
    response = wrapped_callback(request, *callback_args, **callback_kwargs)
  File "/usr/local/lib/python3.5/dist-packages/django/views/decorators/csrf.py", line 54, in wrapped_view
    return view_func(*args, **kwargs)
  File "/usr/local/lib/python3.5/dist-packages/django/views/generic/base.py", line 69, in view
    return self.dispatch(request, *args, **kwargs)
  File "/usr/local/lib/python3.5/dist-packages/django/utils/decorators.py", line 62, in _wrapper
    return bound_func(*args, **kwargs)
  File "/usr/local/lib/python3.5/dist-packages/django/views/decorators/csrf.py", line 54, in wrapped_view
    return view_func(*args, **kwargs)
  File "/usr/local/lib/python3.5/dist-packages/django/utils/decorators.py", line 58, in bound_func
    return func.__get__(self, type(self))(*args2, **kwargs2)
  File "/usr/local/lib/python3.5/dist-packages/braces/views/_forms.py", line 24, in dispatch
    return super(CsrfExemptMixin, self).dispatch(*args, **kwargs)
  File "/usr/local/lib/python3.5/dist-packages/rest_framework/views.py", line 494, in dispatch
    response = self.handle_exception(exc)
  File "/usr/local/lib/python3.5/dist-packages/rest_framework/views.py", line 454, in handle_exception
    self.raise_uncaught_exception(exc)
  File "/usr/local/lib/python3.5/dist-packages/rest_framework/views.py", line 491, in dispatch
    response = handler(request, *args, **kwargs)
  File "/home/sanya/Documents/Git/rsoi_2lab/rsoi_2lab/ag_service/aggregator/views.py", line 43, in get
    return HttpResponse(loader.render_to_string( str(status_code)+'.html'), status=status_code)
  File "/usr/local/lib/python3.5/dist-packages/django/template/loader.py", line 61, in render_to_string
    template = get_template(template_name, using=using)
  File "/usr/local/lib/python3.5/dist-packages/django/template/loader.py", line 19, in get_template
    raise TemplateDoesNotExist(template_name, chain=chain)
django.template.exceptions.TemplateDoesNotExist: 401.html
ERROR:django.request:Internal Server Error: /auth/
Traceback (most recent call last):
  File "/usr/local/lib/python3.5/dist-packages/django/core/handlers/exception.py", line 35, in inner
    response = get_response(request)
  File "/usr/local/lib/python3.5/dist-packages/django/core/handlers/base.py", line 128, in _get_response
    response = self.process_exception_by_middleware(e, request)
  File "/usr/local/lib/python3.5/dist-packages/django/core/handlers/base.py", line 126, in _get_response
    response = wrapped_callback(request, *callback_args, **callback_kwargs)
  File "/usr/local/lib/python3.5/dist-packages/django/views/decorators/csrf.py", line 54, in wrapped_view
    return view_func(*args, **kwargs)
  File "/usr/local/lib/python3.5/dist-packages/django/views/generic/base.py", line 69, in view
    return self.dispatch(request, *args, **kwargs)
  File "/usr/local/lib/python3.5/dist-packages/django/utils/decorators.py", line 62, in _wrapper
    return bound_func(*args, **kwargs)
  File "/usr/local/lib/python3.5/dist-packages/django/views/decorators/csrf.py", line 54, in wrapped_view
    return view_func(*args, **kwargs)
  File "/usr/local/lib/python3.5/dist-packages/django/utils/decorators.py", line 58, in bound_func
    return func.__get__(self, type(self))(*args2, **kwargs2)
  File "/usr/local/lib/python3.5/dist-packages/braces/views/_forms.py", line 24, in dispatch
    return super(CsrfExemptMixin, self).dispatch(*args, **kwargs)
  File "/usr/local/lib/python3.5/dist-packages/rest_framework/views.py", line 494, in dispatch
    response = self.handle_exception(exc)
  File "/usr/local/lib/python3.5/dist-packages/rest_framework/views.py", line 454, in handle_exception
    self.raise_uncaught_exception(exc)
  File "/usr/local/lib/python3.5/dist-packages/rest_framework/views.py", line 491, in dispatch
    response = handler(request, *args, **kwargs)
  File "/home/sanya/Documents/Git/rsoi_2lab/rsoi_2lab/ag_service/aggregator/views.py", line 45, in get
    user_id = response.cookie.get('id')
NameError: name 'response' is not defined
ERROR:django.request:Internal Server Error: /auth/
Traceback (most recent call last):
  File "/usr/local/lib/python3.5/dist-packages/django/core/handlers/exception.py", line 35, in inner
    response = get_response(request)
  File "/usr/local/lib/python3.5/dist-packages/django/core/handlers/base.py", line 128, in _get_response
    response = self.process_exception_by_middleware(e, request)
  File "/usr/local/lib/python3.5/dist-packages/django/core/handlers/base.py", line 126, in _get_response
    response = wrapped_callback(request, *callback_args, **callback_kwargs)
  File "/usr/local/lib/python3.5/dist-packages/django/views/decorators/csrf.py", line 54, in wrapped_view
    return view_func(*args, **kwargs)
  File "/usr/local/lib/python3.5/dist-packages/django/views/generic/base.py", line 69, in view
    return self.dispatch(request, *args, **kwargs)
  File "/usr/local/lib/python3.5/dist-packages/django/utils/decorators.py", line 62, in _wrapper
    return bound_func(*args, **kwargs)
  File "/usr/local/lib/python3.5/dist-packages/django/views/decorators/csrf.py", line 54, in wrapped_view
    return view_func(*args, **kwargs)
  File "/usr/local/lib/python3.5/dist-packages/django/utils/decorators.py", line 58, in bound_func
    return func.__get__(self, type(self))(*args2, **kwargs2)
  File "/usr/local/lib/python3.5/dist-packages/braces/views/_forms.py", line 24, in dispatch
    return super(CsrfExemptMixin, self).dispatch(*args, **kwargs)
  File "/usr/local/lib/python3.5/dist-packages/rest_framework/views.py", line 494, in dispatch
    response = self.handle_exception(exc)
  File "/usr/local/lib/python3.5/dist-packages/rest_framework/views.py", line 454, in handle_exception
    self.raise_uncaught_exception(exc)
  File "/usr/local/lib/python3.5/dist-packages/rest_framework/views.py", line 491, in dispatch
    response = handler(request, *args, **kwargs)
  File "/home/sanya/Documents/Git/rsoi_2lab/rsoi_2lab/ag_service/aggregator/views.py", line 45, in get
    user_id = r.cookie.get('id')
AttributeError: 'Response' object has no attribute 'cookie'
ERROR:django.request:Internal Server Error: /auth/
Traceback (most recent call last):
  File "/usr/local/lib/python3.5/dist-packages/django/core/handlers/exception.py", line 35, in inner
    response = get_response(request)
  File "/usr/local/lib/python3.5/dist-packages/django/core/handlers/base.py", line 128, in _get_response
    response = self.process_exception_by_middleware(e, request)
  File "/usr/local/lib/python3.5/dist-packages/django/core/handlers/base.py", line 126, in _get_response
    response = wrapped_callback(request, *callback_args, **callback_kwargs)
  File "/usr/local/lib/python3.5/dist-packages/django/views/decorators/csrf.py", line 54, in wrapped_view
    return view_func(*args, **kwargs)
  File "/usr/local/lib/python3.5/dist-packages/django/views/generic/base.py", line 69, in view
    return self.dispatch(request, *args, **kwargs)
  File "/usr/local/lib/python3.5/dist-packages/django/utils/decorators.py", line 62, in _wrapper
    return bound_func(*args, **kwargs)
  File "/usr/local/lib/python3.5/dist-packages/django/views/decorators/csrf.py", line 54, in wrapped_view
    return view_func(*args, **kwargs)
  File "/usr/local/lib/python3.5/dist-packages/django/utils/decorators.py", line 58, in bound_func
    return func.__get__(self, type(self))(*args2, **kwargs2)
  File "/usr/local/lib/python3.5/dist-packages/braces/views/_forms.py", line 24, in dispatch
    return super(CsrfExemptMixin, self).dispatch(*args, **kwargs)
  File "/usr/local/lib/python3.5/dist-packages/rest_framework/views.py", line 494, in dispatch
    response = self.handle_exception(exc)
  File "/usr/local/lib/python3.5/dist-packages/rest_framework/views.py", line 454, in handle_exception
    self.raise_uncaught_exception(exc)
  File "/usr/local/lib/python3.5/dist-packages/rest_framework/views.py", line 491, in dispatch
    response = handler(request, *args, **kwargs)
  File "/home/sanya/Documents/Git/rsoi_2lab/rsoi_2lab/ag_service/aggregator/views.py", line 46, in get
    r1 = HttpResponseRedirect(reverse('agg2',args=[user_id]))
NameError: name 'reverse' is not defined
WARNING:django.security.SuspiciousSession:Session data corrupted
WARNING:django.security.SuspiciousSession:Session data corrupted
WARNING:django.security.SuspiciousSession:Session data corrupted
WARNING:django.security.SuspiciousSession:Session data corrupted
INFO:root:Show orders
WARNING:django.security.SuspiciousSession:Session data corrupted
WARNING:django.security.SuspiciousSession:Session data corrupted
ERROR:django.request:Internal Server Error: /user/2/order/2/
Traceback (most recent call last):
  File "/usr/local/lib/python3.5/dist-packages/django/core/handlers/exception.py", line 35, in inner
    response = get_response(request)
  File "/usr/local/lib/python3.5/dist-packages/django/core/handlers/base.py", line 128, in _get_response
    response = self.process_exception_by_middleware(e, request)
  File "/usr/local/lib/python3.5/dist-packages/django/core/handlers/base.py", line 126, in _get_response
    response = wrapped_callback(request, *callback_args, **callback_kwargs)
  File "/usr/local/lib/python3.5/dist-packages/django/views/decorators/csrf.py", line 54, in wrapped_view
    return view_func(*args, **kwargs)
  File "/usr/local/lib/python3.5/dist-packages/django/views/generic/base.py", line 69, in view
    return self.dispatch(request, *args, **kwargs)
  File "/usr/local/lib/python3.5/dist-packages/rest_framework/views.py", line 494, in dispatch
    response = self.handle_exception(exc)
  File "/usr/local/lib/python3.5/dist-packages/rest_framework/views.py", line 454, in handle_exception
    self.raise_uncaught_exception(exc)
  File "/usr/local/lib/python3.5/dist-packages/rest_framework/views.py", line 491, in dispatch
    response = handler(request, *args, **kwargs)
  File "/home/sanya/Documents/Git/rsoi_2lab/rsoi_2lab/ag_service/aggregator/views.py", line 84, in get
    if not has_access(request):
  File "/home/sanya/Documents/Git/rsoi_2lab/rsoi_2lab/ag_service/aggregator/views.py", line 33, in has_access
    'Authorization': 'Bearer '+ token,
TypeError: Can't convert 'NoneType' object to str implicitly
WARNING:django.security.SuspiciousSession:Session data corrupted
WARNING:django.security.SuspiciousSession:Session data corrupted
WARNING:django.security.SuspiciousSession:Session data corrupted
WARNING:django.security.SuspiciousSession:Session data corrupted
WARNING:django.security.SuspiciousSession:Session data corrupted
INFO:root:Show order details
WARNING:django.security.SuspiciousSession:Session data corrupted
WARNING:django.security.SuspiciousSession:Session data corrupted
WARNING:django.security.SuspiciousSession:Session data corrupted
INFO:root:Show orders
WARNING:django.security.SuspiciousSession:Session data corrupted
WARNING:django.security.SuspiciousSession:Session data corrupted
INFO:root:Show orders
WARNING:django.security.SuspiciousSession:Session data corrupted
WARNING:django.security.SuspiciousSession:Session data corrupted
INFO:root:Show orders
WARNING:django.security.SuspiciousSession:Session data corrupted
WARNING:django.security.SuspiciousSession:Session data corrupted
WARNING:django.request:Not Found: /user/1/orders/
WARNING:django.security.SuspiciousSession:Session data corrupted
INFO:root:Show orders
WARNING:django.security.SuspiciousSession:Session data corrupted
WARNING:django.security.SuspiciousSession:Session data corrupted
INFO:root:Show orders
WARNING:django.security.SuspiciousSession:Session data corrupted
INFO:root:Show orders
WARNING:django.security.SuspiciousSession:Session data corrupted
INFO:root:Show order details
WARNING:django.security.SuspiciousSession:Session data corrupted
INFO:root:Show order details
WARNING:django.security.SuspiciousSession:Session data corrupted
INFO:root:Show orders
WARNING:django.security.SuspiciousSession:Session data corrupted
INFO:root:Show order details
WARNING:django.security.SuspiciousSession:Session data corrupted
INFO:root:Show orders
WARNING:django.security.SuspiciousSession:Session data corrupted
INFO:root:Show order details
WARNING:django.security.SuspiciousSession:Session data corrupted
INFO:root:Show orders
WARNING:django.security.SuspiciousSession:Session data corrupted
INFO:root:Show order details
INFO:root:Show orders
INFO:root:Show order details
WARNING:django.request:Not Found: /favicon.ico
WARNING:django.security.SuspiciousSession:Session data corrupted
INFO:root:Show orders
WARNING:django.security.SuspiciousSession:Session data corrupted
INFO:root:Show order details
WARNING:django.security.SuspiciousSession:Session data corrupted
INFO:root:Show order details
WARNING:django.security.SuspiciousSession:Session data corrupted
INFO:root:Show orders
WARNING:django.security.SuspiciousSession:Session data corrupted
INFO:root:Show order details
WARNING:django.security.SuspiciousSession:Session data corrupted
INFO:root:Show order details
WARNING:django.security.SuspiciousSession:Session data corrupted
INFO:root:Show orders
WARNING:django.security.SuspiciousSession:Session data corrupted
INFO:root:Show order details
WARNING:django.security.SuspiciousSession:Session data corrupted
WARNING:django.security.SuspiciousSession:Session data corrupted
INFO:root:Show orders
WARNING:django.security.SuspiciousSession:Session data corrupted
INFO:root:Show order details
WARNING:django.security.SuspiciousSession:Session data corrupted
INFO:root:Patch products done
INFO:root:Edit order details
WARNING:django.security.SuspiciousSession:Session data corrupted
INFO:root:Show order details
WARNING:django.security.SuspiciousSession:Session data corrupted
INFO:root:Delete product from order
WARNING:django.security.SuspiciousSession:Session data corrupted
INFO:root:Show order details
WARNING:django.security.SuspiciousSession:Session data corrupted
INFO:root:Show orders
